2024-09-03T04:48:04 (36) created PID file '/data/zeoserver/zeoserver.pid'
2024-09-03T04:48:04 (36) opening storage u'1' using FileStorage
2024-09-03T04:48:06 (36) Blob directory `/data/blobstorage` is unused and has no layout marker set. Selected `bushy` layout. 
2024-09-03T04:48:06 (36) Blob temporary directory '/data/blobstorage/tmp' does not exist. Created new directory.
2024-09-03T04:48:06 StorageServer created RW with storages: 1:RW:/data/filestorage/Data.fs
2024-09-03T04:48:06 listening on ('', 8080)
2024-09-03T05:03:25 (37) created PID file '/data/zeoserver/zeoserver.pid'
2024-09-03T05:03:25 (37) opening storage u'1' using FileStorage
2024-09-03T05:03:26 StorageServer created RW with storages: 1:RW:/data/filestorage/Data.fs
2024-09-03T05:03:26 listening on ('', 8080)
2024-09-03T05:03:35 Connected server protocol
2024-09-03T05:03:35 received handshake 'Z5'
2024-09-03T05:03:35 Connected server protocol
2024-09-03T05:03:35 received handshake 'Z5'
2024-09-03T05:16:01 (:8080) disconnected
2024-09-03T05:16:14 Connected server protocol
2024-09-03T05:16:14 received handshake 'Z5'
2024-09-03T06:00:41 Unexpected error while trying to resolve conflict on <type 'BTrees.OIBTree.OIBucket'>
Traceback (most recent call last):
  File "/home/senaite/senaitelims/eggs/cp27mu/ZODB-5.8.0-py2.7.egg/ZODB/ConflictResolution.py", line 286, in tryToResolveConflict
    newstate = unpickler.load()
UnpicklingError: NEWOBJ class argument isn't a type object
2024-09-03T06:00:41 Bad request, 'vote'
Traceback (most recent call last):
  File "/home/senaite/senaitelims/eggs/cp27mu/ZEO-5.3.0-py2.7.egg/ZEO/asyncio/server.py", line 103, in message_received
    result = getattr(self.zeo_storage, name)(*args)
  File "/home/senaite/senaitelims/eggs/cp27mu/ZEO-5.3.0-py2.7.egg/ZEO/StorageServer.py", line 374, in vote
    return self.lock_manager.lock(self, self._vote)
  File "/home/senaite/senaitelims/eggs/cp27mu/ZEO-5.3.0-py2.7.egg/ZEO/StorageServer.py", line 1168, in lock
    result = func()
  File "/home/senaite/senaitelims/eggs/cp27mu/ZEO-5.3.0-py2.7.egg/ZEO/StorageServer.py", line 395, in _vote
    getattr(self, op)(*args)
  File "/home/senaite/senaitelims/eggs/cp27mu/ZEO-5.3.0-py2.7.egg/ZEO/StorageServer.py", line 529, in _store
    self.storage.store(oid, serial, data, '', self.transaction)
  File "/home/senaite/senaitelims/eggs/cp27mu/ZODB-5.8.0-py2.7.egg/ZODB/FileStorage/FileStorage.py", line 616, in store
    oldserial, data)
  File "/home/senaite/senaitelims/eggs/cp27mu/ZODB-5.8.0-py2.7.egg/ZODB/ConflictResolution.py", line 311, in tryToResolveConflict
    data=newpickle)
ConflictError: database conflict error (oid 0x0127d0bd, class BTrees.OIBTree.OIBucket, serial this txn started with 0x03fb0da8ad73d766 2024-09-03 06:00:40.652931, serial currently committed 0x03fb0da8b0b13355 2024-09-03 06:00:41.412232)
2024-09-03T06:00:41 (:8080) no current transaction: tpc_abort()
2024-09-03T06:01:02 Unexpected error while trying to resolve conflict on <type 'BTrees.OIBTree.OIBucket'>
Traceback (most recent call last):
  File "/home/senaite/senaitelims/eggs/cp27mu/ZODB-5.8.0-py2.7.egg/ZODB/ConflictResolution.py", line 286, in tryToResolveConflict
    newstate = unpickler.load()
UnpicklingError: NEWOBJ class argument isn't a type object
2024-09-03T06:01:02 Bad request, 'vote'
Traceback (most recent call last):
  File "/home/senaite/senaitelims/eggs/cp27mu/ZEO-5.3.0-py2.7.egg/ZEO/asyncio/server.py", line 103, in message_received
    result = getattr(self.zeo_storage, name)(*args)
  File "/home/senaite/senaitelims/eggs/cp27mu/ZEO-5.3.0-py2.7.egg/ZEO/StorageServer.py", line 374, in vote
    return self.lock_manager.lock(self, self._vote)
  File "/home/senaite/senaitelims/eggs/cp27mu/ZEO-5.3.0-py2.7.egg/ZEO/StorageServer.py", line 1168, in lock
    result = func()
  File "/home/senaite/senaitelims/eggs/cp27mu/ZEO-5.3.0-py2.7.egg/ZEO/StorageServer.py", line 395, in _vote
    getattr(self, op)(*args)
  File "/home/senaite/senaitelims/eggs/cp27mu/ZEO-5.3.0-py2.7.egg/ZEO/StorageServer.py", line 529, in _store
    self.storage.store(oid, serial, data, '', self.transaction)
  File "/home/senaite/senaitelims/eggs/cp27mu/ZODB-5.8.0-py2.7.egg/ZODB/FileStorage/FileStorage.py", line 616, in store
    oldserial, data)
  File "/home/senaite/senaitelims/eggs/cp27mu/ZODB-5.8.0-py2.7.egg/ZODB/ConflictResolution.py", line 311, in tryToResolveConflict
    data=newpickle)
ConflictError: database conflict error (oid 0x0127d0bd, class BTrees.OIBTree.OIBucket, serial this txn started with 0x03fb0da9093d07cc 2024-09-03 06:01:02.165250, serial currently committed 0x03fb0da90b8c2655 2024-09-03 06:01:02.706436)
2024-09-03T06:01:02 (:8080) no current transaction: tpc_abort()
2024-09-03T06:06:52 Unexpected error while trying to resolve conflict on <ZODB.ConflictResolution.BadClass object at 0x7f9cc00aad90>
Traceback (most recent call last):
  File "/home/senaite/senaitelims/eggs/cp27mu/ZODB-5.8.0-py2.7.egg/ZODB/ConflictResolution.py", line 274, in tryToResolveConflict
    inst = klass.__new__(klass, *newargs)
TypeError: object.__new__(X): X is not a type object (BadClass)
2024-09-03T06:06:52 Bad request, 'vote'
Traceback (most recent call last):
  File "/home/senaite/senaitelims/eggs/cp27mu/ZEO-5.3.0-py2.7.egg/ZEO/asyncio/server.py", line 103, in message_received
    result = getattr(self.zeo_storage, name)(*args)
  File "/home/senaite/senaitelims/eggs/cp27mu/ZEO-5.3.0-py2.7.egg/ZEO/StorageServer.py", line 374, in vote
    return self.lock_manager.lock(self, self._vote)
  File "/home/senaite/senaitelims/eggs/cp27mu/ZEO-5.3.0-py2.7.egg/ZEO/StorageServer.py", line 1168, in lock
    result = func()
  File "/home/senaite/senaitelims/eggs/cp27mu/ZEO-5.3.0-py2.7.egg/ZEO/StorageServer.py", line 395, in _vote
    getattr(self, op)(*args)
  File "/home/senaite/senaitelims/eggs/cp27mu/ZEO-5.3.0-py2.7.egg/ZEO/StorageServer.py", line 529, in _store
    self.storage.store(oid, serial, data, '', self.transaction)
  File "/home/senaite/senaitelims/eggs/cp27mu/ZODB-5.8.0-py2.7.egg/ZODB/FileStorage/FileStorage.py", line 616, in store
    oldserial, data)
  File "/home/senaite/senaitelims/eggs/cp27mu/ZODB-5.8.0-py2.7.egg/ZODB/ConflictResolution.py", line 311, in tryToResolveConflict
    data=newpickle)
ConflictError: database conflict error (oid 0x3236, class Persistence.mapping.PersistentMapping, serial this txn started with 0x03f9e3a57a58c744 2024-07-12 06:29:28.675029, serial currently committed 0x03fb0daee1870c44 2024-09-03 06:06:52.858015)
2024-09-03T06:06:52 (:8080) no current transaction: tpc_abort()
2024-09-03T06:29:59 (:8080) disconnected
2024-09-03T06:30:16 Connected server protocol
2024-09-03T06:30:16 received handshake 'Z5'
2024-09-03T06:41:22 (:8080) disconnected
2024-09-03T06:41:36 Connected server protocol
2024-09-03T06:41:36 received handshake 'Z5'
2024-09-03T06:48:36 (:8080) disconnected
2024-09-03T06:48:52 Connected server protocol
2024-09-03T06:48:52 received handshake 'Z5'
2024-09-03T09:23:01 (:8080) disconnected
2024-09-03T09:23:18 Connected server protocol
2024-09-03T09:23:18 received handshake 'Z5'
2024-09-03T09:24:02 (:8080) disconnected
2024-09-03T09:24:10 Connected server protocol
2024-09-03T09:24:10 received handshake 'Z5'
2024-09-03T09:35:03 (:8080) disconnected
2024-09-03T09:35:16 Connected server protocol
2024-09-03T09:35:16 received handshake 'Z5'
2024-09-03T09:35:52 (:8080) disconnected
2024-09-03T09:36:00 Connected server protocol
2024-09-03T09:36:00 received handshake 'Z5'
2024-09-03T09:42:41 Unexpected error while trying to resolve conflict on <type 'BTrees.OIBTree.OIBucket'>
Traceback (most recent call last):
  File "/home/senaite/senaitelims/eggs/cp27mu/ZODB-5.8.0-py2.7.egg/ZODB/ConflictResolution.py", line 286, in tryToResolveConflict
    newstate = unpickler.load()
UnpicklingError: NEWOBJ class argument isn't a type object
2024-09-03T09:42:41 Bad request, 'vote'
Traceback (most recent call last):
  File "/home/senaite/senaitelims/eggs/cp27mu/ZEO-5.3.0-py2.7.egg/ZEO/asyncio/server.py", line 103, in message_received
    result = getattr(self.zeo_storage, name)(*args)
  File "/home/senaite/senaitelims/eggs/cp27mu/ZEO-5.3.0-py2.7.egg/ZEO/StorageServer.py", line 374, in vote
    return self.lock_manager.lock(self, self._vote)
  File "/home/senaite/senaitelims/eggs/cp27mu/ZEO-5.3.0-py2.7.egg/ZEO/StorageServer.py", line 1168, in lock
    result = func()
  File "/home/senaite/senaitelims/eggs/cp27mu/ZEO-5.3.0-py2.7.egg/ZEO/StorageServer.py", line 395, in _vote
    getattr(self, op)(*args)
  File "/home/senaite/senaitelims/eggs/cp27mu/ZEO-5.3.0-py2.7.egg/ZEO/StorageServer.py", line 529, in _store
    self.storage.store(oid, serial, data, '', self.transaction)
  File "/home/senaite/senaitelims/eggs/cp27mu/ZODB-5.8.0-py2.7.egg/ZODB/FileStorage/FileStorage.py", line 616, in store
    oldserial, data)
  File "/home/senaite/senaitelims/eggs/cp27mu/ZODB-5.8.0-py2.7.egg/ZODB/ConflictResolution.py", line 311, in tryToResolveConflict
    data=newpickle)
ConflictError: database conflict error (oid 0x0127d0bd, class BTrees.OIBTree.OIBucket, serial this txn started with 0x03fb0e86abd45866 2024-09-03 09:42:40.272533, serial currently committed 0x03fb0e86af0c1688 2024-09-03 09:42:41.026692)
2024-09-03T09:42:41 (:8080) no current transaction: tpc_abort()
2024-09-03T10:19:49 (:8080) disconnected
2024-09-03T10:20:02 Connected server protocol
2024-09-03T10:20:02 received handshake 'Z5'
2024-09-03T10:23:41 (:8080) disconnected
2024-09-03T10:23:51 Connected server protocol
2024-09-03T10:23:51 received handshake 'Z5'
2024-09-03T10:49:59 (:8080) disconnected
2024-09-03T10:50:10 Connected server protocol
2024-09-03T10:50:10 received handshake 'Z5'
2024-09-03T10:52:22 (:8080) disconnected
2024-09-03T10:52:30 Connected server protocol
2024-09-03T10:52:30 received handshake 'Z5'
2024-09-03T10:55:51 (:8080) disconnected
2024-09-03T10:56:03 Connected server protocol
2024-09-03T10:56:03 received handshake 'Z5'
2024-09-03T10:59:55 (:8080) disconnected
2024-09-03T11:00:05 Connected server protocol
2024-09-03T11:00:05 received handshake 'Z5'
2024-09-03T11:01:19 (:8080) disconnected
2024-09-03T11:01:31 Connected server protocol
2024-09-03T11:01:31 received handshake 'Z5'
2024-09-03T11:04:47 (:8080) disconnected
2024-09-03T11:04:56 Connected server protocol
2024-09-03T11:04:56 received handshake 'Z5'
2024-09-03T11:11:26 Unexpected error while trying to resolve conflict on <type 'BTrees.OIBTree.OIBucket'>
Traceback (most recent call last):
  File "/home/senaite/senaitelims/eggs/cp27mu/ZODB-5.8.0-py2.7.egg/ZODB/ConflictResolution.py", line 286, in tryToResolveConflict
    newstate = unpickler.load()
UnpicklingError: NEWOBJ class argument isn't a type object
2024-09-03T11:11:26 Bad request, 'vote'
Traceback (most recent call last):
  File "/home/senaite/senaitelims/eggs/cp27mu/ZEO-5.3.0-py2.7.egg/ZEO/asyncio/server.py", line 103, in message_received
    result = getattr(self.zeo_storage, name)(*args)
  File "/home/senaite/senaitelims/eggs/cp27mu/ZEO-5.3.0-py2.7.egg/ZEO/StorageServer.py", line 374, in vote
    return self.lock_manager.lock(self, self._vote)
  File "/home/senaite/senaitelims/eggs/cp27mu/ZEO-5.3.0-py2.7.egg/ZEO/StorageServer.py", line 1168, in lock
    result = func()
  File "/home/senaite/senaitelims/eggs/cp27mu/ZEO-5.3.0-py2.7.egg/ZEO/StorageServer.py", line 395, in _vote
    getattr(self, op)(*args)
  File "/home/senaite/senaitelims/eggs/cp27mu/ZEO-5.3.0-py2.7.egg/ZEO/StorageServer.py", line 529, in _store
    self.storage.store(oid, serial, data, '', self.transaction)
  File "/home/senaite/senaitelims/eggs/cp27mu/ZODB-5.8.0-py2.7.egg/ZODB/FileStorage/FileStorage.py", line 616, in store
    oldserial, data)
  File "/home/senaite/senaitelims/eggs/cp27mu/ZODB-5.8.0-py2.7.egg/ZODB/ConflictResolution.py", line 311, in tryToResolveConflict
    data=newpickle)
ConflictError: database conflict error (oid 0x0127d53b, class BTrees.OIBTree.OIBucket, serial this txn started with 0x03fb0edf6d657055 2024-09-03 11:11:25.639745, serial currently committed 0x03fb0edf7063cdbb 2024-09-03 11:11:26.341373)
2024-09-03T11:11:26 (:8080) no current transaction: tpc_abort()
2024-09-03T11:19:56 (:8080) disconnected
2024-09-03T11:20:09 Connected server protocol
2024-09-03T11:20:09 received handshake 'Z5'
2024-09-03T11:21:45 (:8080) disconnected
2024-09-03T11:21:54 Connected server protocol
2024-09-03T11:21:54 received handshake 'Z5'
2024-09-03T11:24:21 (:8080) disconnected
2024-09-03T11:24:30 Connected server protocol
2024-09-03T11:24:30 received handshake 'Z5'
2024-09-03T11:25:33 (:8080) disconnected
2024-09-03T11:25:45 Connected server protocol
2024-09-03T11:25:45 received handshake 'Z5'
2024-09-03T11:47:51 (:8080) disconnected
2024-09-03T11:48:04 Connected server protocol
2024-09-03T11:48:04 received handshake 'Z5'
2024-09-03T11:55:09 (:8080) disconnected
2024-09-03T11:55:21 Connected server protocol
2024-09-03T11:55:21 received handshake 'Z5'
2024-09-04T03:45:56 (:8080) disconnected
2024-09-04T03:46:30 Connected server protocol
2024-09-04T03:46:30 received handshake 'Z5'
2024-09-04T03:49:07 (:8080) disconnected
2024-09-04T03:49:22 Connected server protocol
2024-09-04T03:49:22 received handshake 'Z5'
2024-09-04T03:58:26 (:8080) disconnected
2024-09-04T03:58:40 Connected server protocol
2024-09-04T03:58:40 received handshake 'Z5'
2024-09-04T03:59:02 (:8080) disconnected
2024-09-04T03:59:10 Connected server protocol
2024-09-04T03:59:10 received handshake 'Z5'
2024-09-04T04:00:15 (:8080) disconnected
2024-09-04T04:00:24 Connected server protocol
2024-09-04T04:00:24 received handshake 'Z5'
2024-09-04T04:09:06 (:8080) disconnected
2024-09-04T04:09:18 Connected server protocol
2024-09-04T04:09:18 received handshake 'Z5'
2024-09-04T04:10:32 (:8080) disconnected
2024-09-04T04:10:41 Connected server protocol
2024-09-04T04:10:41 received handshake 'Z5'
2024-09-04T04:13:02 (:8080) disconnected
2024-09-04T04:13:12 Connected server protocol
2024-09-04T04:13:12 received handshake 'Z5'
2024-09-04T04:15:09 (:8080) disconnected
2024-09-04T04:15:24 Connected server protocol
2024-09-04T04:15:24 received handshake 'Z5'
2024-09-04T04:16:15 (:8080) disconnected
2024-09-04T04:16:25 Connected server protocol
2024-09-04T04:16:25 received handshake 'Z5'
2024-09-04T04:18:42 (:8080) disconnected
2024-09-04T04:18:52 Connected server protocol
2024-09-04T04:18:52 received handshake 'Z5'
2024-09-04T05:05:13 Unexpected error while trying to resolve conflict on <type 'BTrees.OIBTree.OIBucket'>
Traceback (most recent call last):
  File "/home/senaite/senaitelims/eggs/cp27mu/ZODB-5.8.0-py2.7.egg/ZODB/ConflictResolution.py", line 286, in tryToResolveConflict
    newstate = unpickler.load()
UnpicklingError: NEWOBJ class argument isn't a type object
2024-09-04T05:05:13 Bad request, 'vote'
Traceback (most recent call last):
  File "/home/senaite/senaitelims/eggs/cp27mu/ZEO-5.3.0-py2.7.egg/ZEO/asyncio/server.py", line 103, in message_received
    result = getattr(self.zeo_storage, name)(*args)
  File "/home/senaite/senaitelims/eggs/cp27mu/ZEO-5.3.0-py2.7.egg/ZEO/StorageServer.py", line 374, in vote
    return self.lock_manager.lock(self, self._vote)
  File "/home/senaite/senaitelims/eggs/cp27mu/ZEO-5.3.0-py2.7.egg/ZEO/StorageServer.py", line 1168, in lock
    result = func()
  File "/home/senaite/senaitelims/eggs/cp27mu/ZEO-5.3.0-py2.7.egg/ZEO/StorageServer.py", line 395, in _vote
    getattr(self, op)(*args)
  File "/home/senaite/senaitelims/eggs/cp27mu/ZEO-5.3.0-py2.7.egg/ZEO/StorageServer.py", line 529, in _store
    self.storage.store(oid, serial, data, '', self.transaction)
  File "/home/senaite/senaitelims/eggs/cp27mu/ZODB-5.8.0-py2.7.egg/ZODB/FileStorage/FileStorage.py", line 616, in store
    oldserial, data)
  File "/home/senaite/senaitelims/eggs/cp27mu/ZODB-5.8.0-py2.7.egg/ZODB/ConflictResolution.py", line 311, in tryToResolveConflict
    data=newpickle)
ConflictError: database conflict error (oid 0x0127d53b, class BTrees.OIBTree.OIBucket, serial this txn started with 0x03fb131134588544 2024-09-04 05:05:12.268543, serial currently committed 0x03fb131137a3fdee 2024-09-04 05:05:13.040764)
2024-09-04T05:05:13 (:8080) no current transaction: tpc_abort()
2024-09-04T05:09:18 (:8080) disconnected
2024-09-04T05:09:34 Connected server protocol
2024-09-04T05:09:34 received handshake 'Z5'
2024-09-04T05:10:09 Unexpected error while trying to resolve conflict on <type 'BTrees.IOBTree.IOBucket'>
Traceback (most recent call last):
  File "/home/senaite/senaitelims/eggs/cp27mu/ZODB-5.8.0-py2.7.egg/ZODB/ConflictResolution.py", line 286, in tryToResolveConflict
    newstate = unpickler.load()
UnpicklingError: NEWOBJ class argument isn't a type object
2024-09-04T05:10:09 Bad request, 'vote'
Traceback (most recent call last):
  File "/home/senaite/senaitelims/eggs/cp27mu/ZEO-5.3.0-py2.7.egg/ZEO/asyncio/server.py", line 103, in message_received
    result = getattr(self.zeo_storage, name)(*args)
  File "/home/senaite/senaitelims/eggs/cp27mu/ZEO-5.3.0-py2.7.egg/ZEO/StorageServer.py", line 374, in vote
    return self.lock_manager.lock(self, self._vote)
  File "/home/senaite/senaitelims/eggs/cp27mu/ZEO-5.3.0-py2.7.egg/ZEO/StorageServer.py", line 1168, in lock
    result = func()
  File "/home/senaite/senaitelims/eggs/cp27mu/ZEO-5.3.0-py2.7.egg/ZEO/StorageServer.py", line 395, in _vote
    getattr(self, op)(*args)
  File "/home/senaite/senaitelims/eggs/cp27mu/ZEO-5.3.0-py2.7.egg/ZEO/StorageServer.py", line 529, in _store
    self.storage.store(oid, serial, data, '', self.transaction)
  File "/home/senaite/senaitelims/eggs/cp27mu/ZODB-5.8.0-py2.7.egg/ZODB/FileStorage/FileStorage.py", line 616, in store
    oldserial, data)
  File "/home/senaite/senaitelims/eggs/cp27mu/ZODB-5.8.0-py2.7.egg/ZODB/ConflictResolution.py", line 311, in tryToResolveConflict
    data=newpickle)
ConflictError: database conflict error (oid 0x0127d1bc, class BTrees.IOBTree.IOBucket, serial this txn started with 0x03fb0db5414ce4bb 2024-09-03 06:13:15.304773, serial currently committed 0x03fb131628b2a866 2024-09-04 05:10:09.538566)
2024-09-04T05:10:09 (:8080) no current transaction: tpc_abort()
2024-09-04T05:10:09 Unexpected error while trying to resolve conflict on <type 'BTrees.OIBTree.OIBucket'>
Traceback (most recent call last):
  File "/home/senaite/senaitelims/eggs/cp27mu/ZODB-5.8.0-py2.7.egg/ZODB/ConflictResolution.py", line 286, in tryToResolveConflict
    newstate = unpickler.load()
UnpicklingError: NEWOBJ class argument isn't a type object
2024-09-04T05:10:09 Bad request, 'vote'
Traceback (most recent call last):
  File "/home/senaite/senaitelims/eggs/cp27mu/ZEO-5.3.0-py2.7.egg/ZEO/asyncio/server.py", line 103, in message_received
    result = getattr(self.zeo_storage, name)(*args)
  File "/home/senaite/senaitelims/eggs/cp27mu/ZEO-5.3.0-py2.7.egg/ZEO/StorageServer.py", line 374, in vote
    return self.lock_manager.lock(self, self._vote)
  File "/home/senaite/senaitelims/eggs/cp27mu/ZEO-5.3.0-py2.7.egg/ZEO/StorageServer.py", line 1168, in lock
    result = func()
  File "/home/senaite/senaitelims/eggs/cp27mu/ZEO-5.3.0-py2.7.egg/ZEO/StorageServer.py", line 395, in _vote
    getattr(self, op)(*args)
  File "/home/senaite/senaitelims/eggs/cp27mu/ZEO-5.3.0-py2.7.egg/ZEO/StorageServer.py", line 529, in _store
    self.storage.store(oid, serial, data, '', self.transaction)
  File "/home/senaite/senaitelims/eggs/cp27mu/ZODB-5.8.0-py2.7.egg/ZODB/FileStorage/FileStorage.py", line 616, in store
    oldserial, data)
  File "/home/senaite/senaitelims/eggs/cp27mu/ZODB-5.8.0-py2.7.egg/ZODB/ConflictResolution.py", line 311, in tryToResolveConflict
    data=newpickle)
ConflictError: database conflict error (oid 0x0127d53b, class BTrees.OIBTree.OIBucket, serial this txn started with 0x03fb13113d2018ee 2024-09-04 05:05:14.326261, serial currently committed 0x03fb131628b2a866 2024-09-04 05:10:09.538566)
2024-09-04T05:10:09 (:8080) no current transaction: tpc_abort()
2024-09-04T05:10:09 Unexpected error while trying to resolve conflict on <type 'BTrees.OIBTree.OIBucket'>
Traceback (most recent call last):
  File "/home/senaite/senaitelims/eggs/cp27mu/ZODB-5.8.0-py2.7.egg/ZODB/ConflictResolution.py", line 286, in tryToResolveConflict
    newstate = unpickler.load()
UnpicklingError: NEWOBJ class argument isn't a type object
2024-09-04T05:10:09 Bad request, 'vote'
Traceback (most recent call last):
  File "/home/senaite/senaitelims/eggs/cp27mu/ZEO-5.3.0-py2.7.egg/ZEO/asyncio/server.py", line 103, in message_received
    result = getattr(self.zeo_storage, name)(*args)
  File "/home/senaite/senaitelims/eggs/cp27mu/ZEO-5.3.0-py2.7.egg/ZEO/StorageServer.py", line 374, in vote
    return self.lock_manager.lock(self, self._vote)
  File "/home/senaite/senaitelims/eggs/cp27mu/ZEO-5.3.0-py2.7.egg/ZEO/StorageServer.py", line 1168, in lock
    result = func()
  File "/home/senaite/senaitelims/eggs/cp27mu/ZEO-5.3.0-py2.7.egg/ZEO/StorageServer.py", line 395, in _vote
    getattr(self, op)(*args)
  File "/home/senaite/senaitelims/eggs/cp27mu/ZEO-5.3.0-py2.7.egg/ZEO/StorageServer.py", line 529, in _store
    self.storage.store(oid, serial, data, '', self.transaction)
  File "/home/senaite/senaitelims/eggs/cp27mu/ZODB-5.8.0-py2.7.egg/ZODB/FileStorage/FileStorage.py", line 616, in store
    oldserial, data)
  File "/home/senaite/senaitelims/eggs/cp27mu/ZODB-5.8.0-py2.7.egg/ZODB/ConflictResolution.py", line 311, in tryToResolveConflict
    data=newpickle)
ConflictError: database conflict error (oid 0x0127d53b, class BTrees.OIBTree.OIBucket, serial this txn started with 0x03fb13113d2018ee 2024-09-04 05:05:14.326261, serial currently committed 0x03fb131628b2a866 2024-09-04 05:10:09.538566)
2024-09-04T05:10:09 (:8080) no current transaction: tpc_abort()
2024-09-04T05:10:14 Unexpected error while trying to resolve conflict on <type 'BTrees.IOBTree.IOBucket'>
Traceback (most recent call last):
  File "/home/senaite/senaitelims/eggs/cp27mu/ZODB-5.8.0-py2.7.egg/ZODB/ConflictResolution.py", line 286, in tryToResolveConflict
    newstate = unpickler.load()
UnpicklingError: NEWOBJ class argument isn't a type object
2024-09-04T05:10:14 Bad request, 'vote'
Traceback (most recent call last):
  File "/home/senaite/senaitelims/eggs/cp27mu/ZEO-5.3.0-py2.7.egg/ZEO/asyncio/server.py", line 103, in message_received
    result = getattr(self.zeo_storage, name)(*args)
  File "/home/senaite/senaitelims/eggs/cp27mu/ZEO-5.3.0-py2.7.egg/ZEO/StorageServer.py", line 374, in vote
    return self.lock_manager.lock(self, self._vote)
  File "/home/senaite/senaitelims/eggs/cp27mu/ZEO-5.3.0-py2.7.egg/ZEO/StorageServer.py", line 1168, in lock
    result = func()
  File "/home/senaite/senaitelims/eggs/cp27mu/ZEO-5.3.0-py2.7.egg/ZEO/StorageServer.py", line 395, in _vote
    getattr(self, op)(*args)
  File "/home/senaite/senaitelims/eggs/cp27mu/ZEO-5.3.0-py2.7.egg/ZEO/StorageServer.py", line 529, in _store
    self.storage.store(oid, serial, data, '', self.transaction)
  File "/home/senaite/senaitelims/eggs/cp27mu/ZODB-5.8.0-py2.7.egg/ZODB/FileStorage/FileStorage.py", line 616, in store
    oldserial, data)
  File "/home/senaite/senaitelims/eggs/cp27mu/ZODB-5.8.0-py2.7.egg/ZODB/ConflictResolution.py", line 311, in tryToResolveConflict
    data=newpickle)
ConflictError: database conflict error (oid 0x0127d1bc, class BTrees.IOBTree.IOBucket, serial this txn started with 0x03fb13162be639cc 2024-09-04 05:10:10.288903, serial currently committed 0x03fb131637407f99 2024-09-04 05:10:12.949675)
2024-09-04T05:10:14 (:8080) no current transaction: tpc_abort()
2024-09-04T05:10:14 Unexpected error while trying to resolve conflict on <type 'BTrees.OIBTree.OIBucket'>
Traceback (most recent call last):
  File "/home/senaite/senaitelims/eggs/cp27mu/ZODB-5.8.0-py2.7.egg/ZODB/ConflictResolution.py", line 286, in tryToResolveConflict
    newstate = unpickler.load()
UnpicklingError: NEWOBJ class argument isn't a type object
2024-09-04T05:10:14 Bad request, 'vote'
Traceback (most recent call last):
  File "/home/senaite/senaitelims/eggs/cp27mu/ZEO-5.3.0-py2.7.egg/ZEO/asyncio/server.py", line 103, in message_received
    result = getattr(self.zeo_storage, name)(*args)
  File "/home/senaite/senaitelims/eggs/cp27mu/ZEO-5.3.0-py2.7.egg/ZEO/StorageServer.py", line 374, in vote
    return self.lock_manager.lock(self, self._vote)
  File "/home/senaite/senaitelims/eggs/cp27mu/ZEO-5.3.0-py2.7.egg/ZEO/StorageServer.py", line 1168, in lock
    result = func()
  File "/home/senaite/senaitelims/eggs/cp27mu/ZEO-5.3.0-py2.7.egg/ZEO/StorageServer.py", line 395, in _vote
    getattr(self, op)(*args)
  File "/home/senaite/senaitelims/eggs/cp27mu/ZEO-5.3.0-py2.7.egg/ZEO/StorageServer.py", line 529, in _store
    self.storage.store(oid, serial, data, '', self.transaction)
  File "/home/senaite/senaitelims/eggs/cp27mu/ZODB-5.8.0-py2.7.egg/ZODB/FileStorage/FileStorage.py", line 616, in store
    oldserial, data)
  File "/home/senaite/senaitelims/eggs/cp27mu/ZODB-5.8.0-py2.7.egg/ZODB/ConflictResolution.py", line 311, in tryToResolveConflict
    data=newpickle)
ConflictError: database conflict error (oid 0x0127d53b, class BTrees.OIBTree.OIBucket, serial this txn started with 0x03fb13162be639cc 2024-09-04 05:10:10.288903, serial currently committed 0x03fb131637407f99 2024-09-04 05:10:12.949675)
2024-09-04T05:10:14 (:8080) no current transaction: tpc_abort()
2024-09-04T05:10:20 Unexpected error while trying to resolve conflict on <type 'BTrees.OIBTree.OIBucket'>
Traceback (most recent call last):
  File "/home/senaite/senaitelims/eggs/cp27mu/ZODB-5.8.0-py2.7.egg/ZODB/ConflictResolution.py", line 286, in tryToResolveConflict
    newstate = unpickler.load()
UnpicklingError: NEWOBJ class argument isn't a type object
2024-09-04T05:10:20 Bad request, 'vote'
Traceback (most recent call last):
  File "/home/senaite/senaitelims/eggs/cp27mu/ZEO-5.3.0-py2.7.egg/ZEO/asyncio/server.py", line 103, in message_received
    result = getattr(self.zeo_storage, name)(*args)
  File "/home/senaite/senaitelims/eggs/cp27mu/ZEO-5.3.0-py2.7.egg/ZEO/StorageServer.py", line 374, in vote
    return self.lock_manager.lock(self, self._vote)
  File "/home/senaite/senaitelims/eggs/cp27mu/ZEO-5.3.0-py2.7.egg/ZEO/StorageServer.py", line 1168, in lock
    result = func()
  File "/home/senaite/senaitelims/eggs/cp27mu/ZEO-5.3.0-py2.7.egg/ZEO/StorageServer.py", line 395, in _vote
    getattr(self, op)(*args)
  File "/home/senaite/senaitelims/eggs/cp27mu/ZEO-5.3.0-py2.7.egg/ZEO/StorageServer.py", line 529, in _store
    self.storage.store(oid, serial, data, '', self.transaction)
  File "/home/senaite/senaitelims/eggs/cp27mu/ZODB-5.8.0-py2.7.egg/ZODB/FileStorage/FileStorage.py", line 616, in store
    oldserial, data)
  File "/home/senaite/senaitelims/eggs/cp27mu/ZODB-5.8.0-py2.7.egg/ZODB/ConflictResolution.py", line 311, in tryToResolveConflict
    data=newpickle)
ConflictError: database conflict error (oid 0x0127d53b, class BTrees.OIBTree.OIBucket, serial this txn started with 0x03fb131637407f99 2024-09-04 05:10:12.949675, serial currently committed 0x03fb131655be4a99 2024-09-04 05:10:20.096092)
2024-09-04T05:10:20 (:8080) no current transaction: tpc_abort()
2024-09-04T05:11:52 (:8080) disconnected
2024-09-04T05:12:00 Connected server protocol
2024-09-04T05:12:00 received handshake 'Z5'
2024-09-04T05:12:26 Unexpected error while trying to resolve conflict on <type 'BTrees.OIBTree.OIBucket'>
Traceback (most recent call last):
  File "/home/senaite/senaitelims/eggs/cp27mu/ZODB-5.8.0-py2.7.egg/ZODB/ConflictResolution.py", line 286, in tryToResolveConflict
    newstate = unpickler.load()
UnpicklingError: NEWOBJ class argument isn't a type object
2024-09-04T05:12:26 Bad request, 'vote'
Traceback (most recent call last):
  File "/home/senaite/senaitelims/eggs/cp27mu/ZEO-5.3.0-py2.7.egg/ZEO/asyncio/server.py", line 103, in message_received
    result = getattr(self.zeo_storage, name)(*args)
  File "/home/senaite/senaitelims/eggs/cp27mu/ZEO-5.3.0-py2.7.egg/ZEO/StorageServer.py", line 374, in vote
    return self.lock_manager.lock(self, self._vote)
  File "/home/senaite/senaitelims/eggs/cp27mu/ZEO-5.3.0-py2.7.egg/ZEO/StorageServer.py", line 1168, in lock
    result = func()
  File "/home/senaite/senaitelims/eggs/cp27mu/ZEO-5.3.0-py2.7.egg/ZEO/StorageServer.py", line 395, in _vote
    getattr(self, op)(*args)
  File "/home/senaite/senaitelims/eggs/cp27mu/ZEO-5.3.0-py2.7.egg/ZEO/StorageServer.py", line 529, in _store
    self.storage.store(oid, serial, data, '', self.transaction)
  File "/home/senaite/senaitelims/eggs/cp27mu/ZODB-5.8.0-py2.7.egg/ZODB/FileStorage/FileStorage.py", line 616, in store
    oldserial, data)
  File "/home/senaite/senaitelims/eggs/cp27mu/ZODB-5.8.0-py2.7.egg/ZODB/ConflictResolution.py", line 311, in tryToResolveConflict
    data=newpickle)
ConflictError: database conflict error (oid 0x0127d53b, class BTrees.OIBTree.OIBucket, serial this txn started with 0x03fb1316707bed77 2024-09-04 05:10:26.363459, serial currently committed 0x03fb1318721361dd 2024-09-04 05:12:26.736495)
2024-09-04T05:12:26 (:8080) no current transaction: tpc_abort()
2024-09-04T05:12:28 Unexpected error while trying to resolve conflict on <type 'BTrees.OIBTree.OIBucket'>
Traceback (most recent call last):
  File "/home/senaite/senaitelims/eggs/cp27mu/ZODB-5.8.0-py2.7.egg/ZODB/ConflictResolution.py", line 286, in tryToResolveConflict
    newstate = unpickler.load()
UnpicklingError: NEWOBJ class argument isn't a type object
2024-09-04T05:12:28 Bad request, 'vote'
Traceback (most recent call last):
  File "/home/senaite/senaitelims/eggs/cp27mu/ZEO-5.3.0-py2.7.egg/ZEO/asyncio/server.py", line 103, in message_received
    result = getattr(self.zeo_storage, name)(*args)
  File "/home/senaite/senaitelims/eggs/cp27mu/ZEO-5.3.0-py2.7.egg/ZEO/StorageServer.py", line 374, in vote
    return self.lock_manager.lock(self, self._vote)
  File "/home/senaite/senaitelims/eggs/cp27mu/ZEO-5.3.0-py2.7.egg/ZEO/StorageServer.py", line 1168, in lock
    result = func()
  File "/home/senaite/senaitelims/eggs/cp27mu/ZEO-5.3.0-py2.7.egg/ZEO/StorageServer.py", line 395, in _vote
    getattr(self, op)(*args)
  File "/home/senaite/senaitelims/eggs/cp27mu/ZEO-5.3.0-py2.7.egg/ZEO/StorageServer.py", line 529, in _store
    self.storage.store(oid, serial, data, '', self.transaction)
  File "/home/senaite/senaitelims/eggs/cp27mu/ZODB-5.8.0-py2.7.egg/ZODB/FileStorage/FileStorage.py", line 616, in store
    oldserial, data)
  File "/home/senaite/senaitelims/eggs/cp27mu/ZODB-5.8.0-py2.7.egg/ZODB/ConflictResolution.py", line 311, in tryToResolveConflict
    data=newpickle)
ConflictError: database conflict error (oid 0x0127d53b, class BTrees.OIBTree.OIBucket, serial this txn started with 0x03fb1316707bed77 2024-09-04 05:10:26.363459, serial currently committed 0x03fb1318721361dd 2024-09-04 05:12:26.736495)
2024-09-04T05:12:28 (:8080) no current transaction: tpc_abort()
2024-09-04T05:12:31 Unexpected error while trying to resolve conflict on <type 'BTrees.OIBTree.OIBucket'>
Traceback (most recent call last):
  File "/home/senaite/senaitelims/eggs/cp27mu/ZODB-5.8.0-py2.7.egg/ZODB/ConflictResolution.py", line 286, in tryToResolveConflict
    newstate = unpickler.load()
UnpicklingError: NEWOBJ class argument isn't a type object
2024-09-04T05:12:31 Bad request, 'vote'
Traceback (most recent call last):
  File "/home/senaite/senaitelims/eggs/cp27mu/ZEO-5.3.0-py2.7.egg/ZEO/asyncio/server.py", line 103, in message_received
    result = getattr(self.zeo_storage, name)(*args)
  File "/home/senaite/senaitelims/eggs/cp27mu/ZEO-5.3.0-py2.7.egg/ZEO/StorageServer.py", line 374, in vote
    return self.lock_manager.lock(self, self._vote)
  File "/home/senaite/senaitelims/eggs/cp27mu/ZEO-5.3.0-py2.7.egg/ZEO/StorageServer.py", line 1168, in lock
    result = func()
  File "/home/senaite/senaitelims/eggs/cp27mu/ZEO-5.3.0-py2.7.egg/ZEO/StorageServer.py", line 395, in _vote
    getattr(self, op)(*args)
  File "/home/senaite/senaitelims/eggs/cp27mu/ZEO-5.3.0-py2.7.egg/ZEO/StorageServer.py", line 529, in _store
    self.storage.store(oid, serial, data, '', self.transaction)
  File "/home/senaite/senaitelims/eggs/cp27mu/ZODB-5.8.0-py2.7.egg/ZODB/FileStorage/FileStorage.py", line 616, in store
    oldserial, data)
  File "/home/senaite/senaitelims/eggs/cp27mu/ZODB-5.8.0-py2.7.egg/ZODB/ConflictResolution.py", line 311, in tryToResolveConflict
    data=newpickle)
ConflictError: database conflict error (oid 0x0127dab8, class BTrees.OIBTree.OIBucket, serial this txn started with 0x03fb13188208ef00 2024-09-04 05:12:30.476929, serial currently committed 0x03fb1318848f3399 2024-09-04 05:12:31.068605)
2024-09-04T05:12:31 (:8080) no current transaction: tpc_abort()
2024-09-04T05:13:56 (:8080) disconnected
2024-09-04T05:14:05 Connected server protocol
2024-09-04T05:14:05 received handshake 'Z5'
2024-09-04T05:14:21 Unexpected error while trying to resolve conflict on <type 'BTrees.IOBTree.IOBucket'>
Traceback (most recent call last):
  File "/home/senaite/senaitelims/eggs/cp27mu/ZODB-5.8.0-py2.7.egg/ZODB/ConflictResolution.py", line 286, in tryToResolveConflict
    newstate = unpickler.load()
UnpicklingError: NEWOBJ class argument isn't a type object
2024-09-04T05:14:21 Bad request, 'vote'
Traceback (most recent call last):
  File "/home/senaite/senaitelims/eggs/cp27mu/ZEO-5.3.0-py2.7.egg/ZEO/asyncio/server.py", line 103, in message_received
    result = getattr(self.zeo_storage, name)(*args)
  File "/home/senaite/senaitelims/eggs/cp27mu/ZEO-5.3.0-py2.7.egg/ZEO/StorageServer.py", line 374, in vote
    return self.lock_manager.lock(self, self._vote)
  File "/home/senaite/senaitelims/eggs/cp27mu/ZEO-5.3.0-py2.7.egg/ZEO/StorageServer.py", line 1168, in lock
    result = func()
  File "/home/senaite/senaitelims/eggs/cp27mu/ZEO-5.3.0-py2.7.egg/ZEO/StorageServer.py", line 395, in _vote
    getattr(self, op)(*args)
  File "/home/senaite/senaitelims/eggs/cp27mu/ZEO-5.3.0-py2.7.egg/ZEO/StorageServer.py", line 529, in _store
    self.storage.store(oid, serial, data, '', self.transaction)
  File "/home/senaite/senaitelims/eggs/cp27mu/ZODB-5.8.0-py2.7.egg/ZODB/FileStorage/FileStorage.py", line 616, in store
    oldserial, data)
  File "/home/senaite/senaitelims/eggs/cp27mu/ZODB-5.8.0-py2.7.egg/ZODB/ConflictResolution.py", line 311, in tryToResolveConflict
    data=newpickle)
ConflictError: database conflict error (oid 0x0127d1bc, class BTrees.IOBTree.IOBucket, serial this txn started with 0x03fb1318721361dd 2024-09-04 05:12:26.736495, serial currently committed 0x03fb131a5aabc755 2024-09-04 05:14:21.251018)
2024-09-04T05:14:21 (:8080) no current transaction: tpc_abort()
2024-09-04T05:15:08 Unexpected error while trying to resolve conflict on <type 'BTrees.OIBTree.OIBucket'>
Traceback (most recent call last):
  File "/home/senaite/senaitelims/eggs/cp27mu/ZODB-5.8.0-py2.7.egg/ZODB/ConflictResolution.py", line 286, in tryToResolveConflict
    newstate = unpickler.load()
UnpicklingError: NEWOBJ class argument isn't a type object
2024-09-04T05:15:08 Bad request, 'vote'
Traceback (most recent call last):
  File "/home/senaite/senaitelims/eggs/cp27mu/ZEO-5.3.0-py2.7.egg/ZEO/asyncio/server.py", line 103, in message_received
    result = getattr(self.zeo_storage, name)(*args)
  File "/home/senaite/senaitelims/eggs/cp27mu/ZEO-5.3.0-py2.7.egg/ZEO/StorageServer.py", line 374, in vote
    return self.lock_manager.lock(self, self._vote)
  File "/home/senaite/senaitelims/eggs/cp27mu/ZEO-5.3.0-py2.7.egg/ZEO/StorageServer.py", line 1168, in lock
    result = func()
  File "/home/senaite/senaitelims/eggs/cp27mu/ZEO-5.3.0-py2.7.egg/ZEO/StorageServer.py", line 395, in _vote
    getattr(self, op)(*args)
  File "/home/senaite/senaitelims/eggs/cp27mu/ZEO-5.3.0-py2.7.egg/ZEO/StorageServer.py", line 529, in _store
    self.storage.store(oid, serial, data, '', self.transaction)
  File "/home/senaite/senaitelims/eggs/cp27mu/ZODB-5.8.0-py2.7.egg/ZODB/FileStorage/FileStorage.py", line 616, in store
    oldserial, data)
  File "/home/senaite/senaitelims/eggs/cp27mu/ZODB-5.8.0-py2.7.egg/ZODB/ConflictResolution.py", line 311, in tryToResolveConflict
    data=newpickle)
ConflictError: database conflict error (oid 0x0127dab8, class BTrees.OIBTree.OIBucket, serial this txn started with 0x03fb131b219b8888 2024-09-04 05:15:07.876770, serial currently committed 0x03fb131b23bcd3ee 2024-09-04 05:15:08.376002)
2024-09-04T05:15:08 (:8080) no current transaction: tpc_abort()
2024-09-04T05:22:04 Unexpected error while trying to resolve conflict on <type 'BTrees.IOBTree.IOBucket'>
Traceback (most recent call last):
  File "/home/senaite/senaitelims/eggs/cp27mu/ZODB-5.8.0-py2.7.egg/ZODB/ConflictResolution.py", line 286, in tryToResolveConflict
    newstate = unpickler.load()
UnpicklingError: NEWOBJ class argument isn't a type object
2024-09-04T05:22:04 Bad request, 'vote'
Traceback (most recent call last):
  File "/home/senaite/senaitelims/eggs/cp27mu/ZEO-5.3.0-py2.7.egg/ZEO/asyncio/server.py", line 103, in message_received
    result = getattr(self.zeo_storage, name)(*args)
  File "/home/senaite/senaitelims/eggs/cp27mu/ZEO-5.3.0-py2.7.egg/ZEO/StorageServer.py", line 374, in vote
    return self.lock_manager.lock(self, self._vote)
  File "/home/senaite/senaitelims/eggs/cp27mu/ZEO-5.3.0-py2.7.egg/ZEO/StorageServer.py", line 1168, in lock
    result = func()
  File "/home/senaite/senaitelims/eggs/cp27mu/ZEO-5.3.0-py2.7.egg/ZEO/StorageServer.py", line 395, in _vote
    getattr(self, op)(*args)
  File "/home/senaite/senaitelims/eggs/cp27mu/ZEO-5.3.0-py2.7.egg/ZEO/StorageServer.py", line 529, in _store
    self.storage.store(oid, serial, data, '', self.transaction)
  File "/home/senaite/senaitelims/eggs/cp27mu/ZODB-5.8.0-py2.7.egg/ZODB/FileStorage/FileStorage.py", line 616, in store
    oldserial, data)
  File "/home/senaite/senaitelims/eggs/cp27mu/ZODB-5.8.0-py2.7.egg/ZODB/ConflictResolution.py", line 311, in tryToResolveConflict
    data=newpickle)
ConflictError: database conflict error (oid 0x0127d1bc, class BTrees.IOBTree.IOBucket, serial this txn started with 0x03fb131a5aabc755 2024-09-04 05:14:21.251018, serial currently committed 0x03fb132214638e44 2024-09-04 05:22:04.778646)
2024-09-04T05:22:04 (:8080) no current transaction: tpc_abort()
2024-09-04T05:22:38 (:8080) disconnected
2024-09-04T05:22:51 Connected server protocol
2024-09-04T05:22:51 received handshake 'Z5'
2024-09-04T05:23:05 Unexpected error while trying to resolve conflict on <type 'BTrees.OIBTree.OIBucket'>
Traceback (most recent call last):
  File "/home/senaite/senaitelims/eggs/cp27mu/ZODB-5.8.0-py2.7.egg/ZODB/ConflictResolution.py", line 286, in tryToResolveConflict
    newstate = unpickler.load()
UnpicklingError: NEWOBJ class argument isn't a type object
2024-09-04T05:23:05 Bad request, 'vote'
Traceback (most recent call last):
  File "/home/senaite/senaitelims/eggs/cp27mu/ZEO-5.3.0-py2.7.egg/ZEO/asyncio/server.py", line 103, in message_received
    result = getattr(self.zeo_storage, name)(*args)
  File "/home/senaite/senaitelims/eggs/cp27mu/ZEO-5.3.0-py2.7.egg/ZEO/StorageServer.py", line 374, in vote
    return self.lock_manager.lock(self, self._vote)
  File "/home/senaite/senaitelims/eggs/cp27mu/ZEO-5.3.0-py2.7.egg/ZEO/StorageServer.py", line 1168, in lock
    result = func()
  File "/home/senaite/senaitelims/eggs/cp27mu/ZEO-5.3.0-py2.7.egg/ZEO/StorageServer.py", line 395, in _vote
    getattr(self, op)(*args)
  File "/home/senaite/senaitelims/eggs/cp27mu/ZEO-5.3.0-py2.7.egg/ZEO/StorageServer.py", line 529, in _store
    self.storage.store(oid, serial, data, '', self.transaction)
  File "/home/senaite/senaitelims/eggs/cp27mu/ZODB-5.8.0-py2.7.egg/ZODB/FileStorage/FileStorage.py", line 616, in store
    oldserial, data)
  File "/home/senaite/senaitelims/eggs/cp27mu/ZODB-5.8.0-py2.7.egg/ZODB/ConflictResolution.py", line 311, in tryToResolveConflict
    data=newpickle)
ConflictError: database conflict error (oid 0x0127dab8, class BTrees.OIBTree.OIBucket, serial this txn started with 0x03fb1323154d7daa 2024-09-04 05:23:04.992820, serial currently committed 0x03fb1323193a6677 2024-09-04 05:23:05.912842)
2024-09-04T05:23:05 (:8080) no current transaction: tpc_abort()
2024-09-04T06:00:50 (:8080) disconnected
2024-09-04T06:00:50 (:8080) disconnected
2024-09-09T04:29:31 (37) created PID file '/data/zeoserver/zeoserver.pid'
2024-09-09T04:29:31 (37) opening storage u'1' using FileStorage
2024-09-09T04:29:34 StorageServer created RW with storages: 1:RW:/data/filestorage/Data.fs
2024-09-09T04:29:34 listening on ('', 8080)
2024-09-09T04:29:40 Connected server protocol
2024-09-09T04:29:40 received handshake 'Z5'
2024-09-09T04:29:40 Connected server protocol
2024-09-09T04:29:40 received handshake 'Z5'
2024-09-13T04:11:00 (35) created PID file '/data/zeoserver/zeoserver.pid'
2024-09-13T04:11:00 (35) opening storage u'1' using FileStorage
2024-09-13T04:11:03 StorageServer created RW with storages: 1:RW:/data/filestorage/Data.fs
2024-09-13T04:11:03 listening on ('', 8080)
2024-09-13T04:11:09 Connected server protocol
2024-09-13T04:11:09 Connected server protocol
2024-09-13T04:11:09 received handshake 'Z5'
2024-09-13T04:11:09 received handshake 'Z5'
2024-09-13T04:31:50 (:8080) disconnected
2024-09-13T04:32:02 Connected server protocol
2024-09-13T04:32:02 received handshake 'Z5'
2024-09-13T04:34:40 (:8080) disconnected
2024-09-13T04:34:49 Connected server protocol
2024-09-13T04:34:49 received handshake 'Z5'
2024-09-13T04:43:02 (:8080) disconnected
2024-09-13T04:43:17 Connected server protocol
2024-09-13T04:43:17 received handshake 'Z5'
2024-09-13T04:46:33 (:8080) disconnected
2024-09-13T04:46:44 Connected server protocol
2024-09-13T04:46:44 received handshake 'Z5'
2024-09-13T04:57:14 (:8080) disconnected
2024-09-13T04:57:27 Connected server protocol
2024-09-13T04:57:27 received handshake 'Z5'
2024-09-13T04:57:32 (:8080) disconnected
2024-09-13T04:59:12 Connected server protocol
2024-09-13T04:59:12 received handshake 'Z5'
2024-09-13T04:59:17 (:8080) disconnected
2024-09-13T05:00:13 Connected server protocol
2024-09-13T05:00:13 received handshake 'Z5'
2024-09-13T05:03:25 (:8080) disconnected
2024-09-13T05:03:39 Connected server protocol
2024-09-13T05:03:39 received handshake 'Z5'
2024-09-13T05:27:38 (:8080) disconnected
2024-09-13T05:27:52 Connected server protocol
2024-09-13T05:27:52 received handshake 'Z5'
2024-09-13T05:38:00 (:8080) disconnected
2024-09-13T05:38:14 Connected server protocol
2024-09-13T05:38:14 received handshake 'Z5'
2024-09-13T05:48:33 (:8080) disconnected
2024-09-13T05:48:46 Connected server protocol
2024-09-13T05:48:46 received handshake 'Z5'
2024-09-13T06:14:36 Unexpected error while trying to resolve conflict on <type 'BTrees.OIBTree.OIBucket'>
Traceback (most recent call last):
  File "/home/senaite/senaitelims/eggs/cp27mu/ZODB-5.8.0-py2.7.egg/ZODB/ConflictResolution.py", line 286, in tryToResolveConflict
    newstate = unpickler.load()
UnpicklingError: NEWOBJ class argument isn't a type object
2024-09-13T06:14:36 Bad request, 'vote'
Traceback (most recent call last):
  File "/home/senaite/senaitelims/eggs/cp27mu/ZEO-5.3.0-py2.7.egg/ZEO/asyncio/server.py", line 103, in message_received
    result = getattr(self.zeo_storage, name)(*args)
  File "/home/senaite/senaitelims/eggs/cp27mu/ZEO-5.3.0-py2.7.egg/ZEO/StorageServer.py", line 374, in vote
    return self.lock_manager.lock(self, self._vote)
  File "/home/senaite/senaitelims/eggs/cp27mu/ZEO-5.3.0-py2.7.egg/ZEO/StorageServer.py", line 1168, in lock
    result = func()
  File "/home/senaite/senaitelims/eggs/cp27mu/ZEO-5.3.0-py2.7.egg/ZEO/StorageServer.py", line 395, in _vote
    getattr(self, op)(*args)
  File "/home/senaite/senaitelims/eggs/cp27mu/ZEO-5.3.0-py2.7.egg/ZEO/StorageServer.py", line 529, in _store
    self.storage.store(oid, serial, data, '', self.transaction)
  File "/home/senaite/senaitelims/eggs/cp27mu/ZODB-5.8.0-py2.7.egg/ZODB/FileStorage/FileStorage.py", line 616, in store
    oldserial, data)
  File "/home/senaite/senaitelims/eggs/cp27mu/ZODB-5.8.0-py2.7.egg/ZODB/ConflictResolution.py", line 311, in tryToResolveConflict
    data=newpickle)
ConflictError: database conflict error (oid 0x0127dab8, class BTrees.OIBTree.OIBucket, serial this txn started with 0x03fb45f698ddc422 2024-09-13 06:14:35.828033, serial currently committed 0x03fb45f69b2898ee 2024-09-13 06:14:36.365293)
2024-09-13T06:14:36 (:8080) no current transaction: tpc_abort()
2024-09-13T06:15:15 Unexpected error while trying to resolve conflict on <type 'BTrees.OIBTree.OIBucket'>
Traceback (most recent call last):
  File "/home/senaite/senaitelims/eggs/cp27mu/ZODB-5.8.0-py2.7.egg/ZODB/ConflictResolution.py", line 286, in tryToResolveConflict
    newstate = unpickler.load()
UnpicklingError: NEWOBJ class argument isn't a type object
2024-09-13T06:15:15 Bad request, 'vote'
Traceback (most recent call last):
  File "/home/senaite/senaitelims/eggs/cp27mu/ZEO-5.3.0-py2.7.egg/ZEO/asyncio/server.py", line 103, in message_received
    result = getattr(self.zeo_storage, name)(*args)
  File "/home/senaite/senaitelims/eggs/cp27mu/ZEO-5.3.0-py2.7.egg/ZEO/StorageServer.py", line 374, in vote
    return self.lock_manager.lock(self, self._vote)
  File "/home/senaite/senaitelims/eggs/cp27mu/ZEO-5.3.0-py2.7.egg/ZEO/StorageServer.py", line 1168, in lock
    result = func()
  File "/home/senaite/senaitelims/eggs/cp27mu/ZEO-5.3.0-py2.7.egg/ZEO/StorageServer.py", line 395, in _vote
    getattr(self, op)(*args)
  File "/home/senaite/senaitelims/eggs/cp27mu/ZEO-5.3.0-py2.7.egg/ZEO/StorageServer.py", line 529, in _store
    self.storage.store(oid, serial, data, '', self.transaction)
  File "/home/senaite/senaitelims/eggs/cp27mu/ZODB-5.8.0-py2.7.egg/ZODB/FileStorage/FileStorage.py", line 616, in store
    oldserial, data)
  File "/home/senaite/senaitelims/eggs/cp27mu/ZODB-5.8.0-py2.7.egg/ZODB/ConflictResolution.py", line 311, in tryToResolveConflict
    data=newpickle)
ConflictError: database conflict error (oid 0x0127df18, class BTrees.OIBTree.OIBucket, serial this txn started with 0x03fb45f73e1a4566 2024-09-13 06:15:14.555302, serial currently committed 0x03fb45f73fee9100 2024-09-13 06:15:14.984039)
2024-09-13T06:15:15 (:8080) no current transaction: tpc_abort()
2024-09-13T06:15:38 Unexpected error while trying to resolve conflict on <type 'BTrees.OIBTree.OIBucket'>
Traceback (most recent call last):
  File "/home/senaite/senaitelims/eggs/cp27mu/ZODB-5.8.0-py2.7.egg/ZODB/ConflictResolution.py", line 286, in tryToResolveConflict
    newstate = unpickler.load()
UnpicklingError: NEWOBJ class argument isn't a type object
2024-09-13T06:15:38 Bad request, 'vote'
Traceback (most recent call last):
  File "/home/senaite/senaitelims/eggs/cp27mu/ZEO-5.3.0-py2.7.egg/ZEO/asyncio/server.py", line 103, in message_received
    result = getattr(self.zeo_storage, name)(*args)
  File "/home/senaite/senaitelims/eggs/cp27mu/ZEO-5.3.0-py2.7.egg/ZEO/StorageServer.py", line 374, in vote
    return self.lock_manager.lock(self, self._vote)
  File "/home/senaite/senaitelims/eggs/cp27mu/ZEO-5.3.0-py2.7.egg/ZEO/StorageServer.py", line 1168, in lock
    result = func()
  File "/home/senaite/senaitelims/eggs/cp27mu/ZEO-5.3.0-py2.7.egg/ZEO/StorageServer.py", line 395, in _vote
    getattr(self, op)(*args)
  File "/home/senaite/senaitelims/eggs/cp27mu/ZEO-5.3.0-py2.7.egg/ZEO/StorageServer.py", line 529, in _store
    self.storage.store(oid, serial, data, '', self.transaction)
  File "/home/senaite/senaitelims/eggs/cp27mu/ZODB-5.8.0-py2.7.egg/ZODB/FileStorage/FileStorage.py", line 616, in store
    oldserial, data)
  File "/home/senaite/senaitelims/eggs/cp27mu/ZODB-5.8.0-py2.7.egg/ZODB/ConflictResolution.py", line 311, in tryToResolveConflict
    data=newpickle)
ConflictError: database conflict error (oid 0x0127df18, class BTrees.OIBTree.OIBucket, serial this txn started with 0x03fb45f7a051ed33 2024-09-13 06:15:37.575006, serial currently committed 0x03fb45f7a4a1ba00 2024-09-13 06:15:38.585565)
2024-09-13T06:15:38 (:8080) no current transaction: tpc_abort()
2024-09-13T06:15:53 Unexpected error while trying to resolve conflict on <type 'BTrees.OIBTree.OIBucket'>
Traceback (most recent call last):
  File "/home/senaite/senaitelims/eggs/cp27mu/ZODB-5.8.0-py2.7.egg/ZODB/ConflictResolution.py", line 286, in tryToResolveConflict
    newstate = unpickler.load()
UnpicklingError: NEWOBJ class argument isn't a type object
2024-09-13T06:15:53 Bad request, 'vote'
Traceback (most recent call last):
  File "/home/senaite/senaitelims/eggs/cp27mu/ZEO-5.3.0-py2.7.egg/ZEO/asyncio/server.py", line 103, in message_received
    result = getattr(self.zeo_storage, name)(*args)
  File "/home/senaite/senaitelims/eggs/cp27mu/ZEO-5.3.0-py2.7.egg/ZEO/StorageServer.py", line 374, in vote
    return self.lock_manager.lock(self, self._vote)
  File "/home/senaite/senaitelims/eggs/cp27mu/ZEO-5.3.0-py2.7.egg/ZEO/StorageServer.py", line 1168, in lock
    result = func()
  File "/home/senaite/senaitelims/eggs/cp27mu/ZEO-5.3.0-py2.7.egg/ZEO/StorageServer.py", line 395, in _vote
    getattr(self, op)(*args)
  File "/home/senaite/senaitelims/eggs/cp27mu/ZEO-5.3.0-py2.7.egg/ZEO/StorageServer.py", line 529, in _store
    self.storage.store(oid, serial, data, '', self.transaction)
  File "/home/senaite/senaitelims/eggs/cp27mu/ZODB-5.8.0-py2.7.egg/ZODB/FileStorage/FileStorage.py", line 616, in store
    oldserial, data)
  File "/home/senaite/senaitelims/eggs/cp27mu/ZODB-5.8.0-py2.7.egg/ZODB/ConflictResolution.py", line 311, in tryToResolveConflict
    data=newpickle)
ConflictError: database conflict error (oid 0x0127df18, class BTrees.OIBTree.OIBucket, serial this txn started with 0x03fb45f7e1923955 2024-09-13 06:15:52.868247, serial currently committed 0x03fb45f7e3b31877 2024-09-13 06:15:53.367092)
2024-09-13T06:15:53 (:8080) no current transaction: tpc_abort()
2024-09-15T09:10:24 Unexpected error while trying to resolve conflict on <type 'BTrees.IOBTree.IOBucket'>
Traceback (most recent call last):
  File "/home/senaite/senaitelims/eggs/cp27mu/ZODB-5.8.0-py2.7.egg/ZODB/ConflictResolution.py", line 286, in tryToResolveConflict
    newstate = unpickler.load()
UnpicklingError: NEWOBJ class argument isn't a type object
2024-09-15T09:10:24 Bad request, 'vote'
Traceback (most recent call last):
  File "/home/senaite/senaitelims/eggs/cp27mu/ZEO-5.3.0-py2.7.egg/ZEO/asyncio/server.py", line 103, in message_received
    result = getattr(self.zeo_storage, name)(*args)
  File "/home/senaite/senaitelims/eggs/cp27mu/ZEO-5.3.0-py2.7.egg/ZEO/StorageServer.py", line 374, in vote
    return self.lock_manager.lock(self, self._vote)
  File "/home/senaite/senaitelims/eggs/cp27mu/ZEO-5.3.0-py2.7.egg/ZEO/StorageServer.py", line 1168, in lock
    result = func()
  File "/home/senaite/senaitelims/eggs/cp27mu/ZEO-5.3.0-py2.7.egg/ZEO/StorageServer.py", line 395, in _vote
    getattr(self, op)(*args)
  File "/home/senaite/senaitelims/eggs/cp27mu/ZEO-5.3.0-py2.7.egg/ZEO/StorageServer.py", line 529, in _store
    self.storage.store(oid, serial, data, '', self.transaction)
  File "/home/senaite/senaitelims/eggs/cp27mu/ZODB-5.8.0-py2.7.egg/ZODB/FileStorage/FileStorage.py", line 616, in store
    oldserial, data)
  File "/home/senaite/senaitelims/eggs/cp27mu/ZODB-5.8.0-py2.7.egg/ZODB/ConflictResolution.py", line 311, in tryToResolveConflict
    data=newpickle)
ConflictError: database conflict error (oid 0x011d37ff, class BTrees.IOBTree.IOBucket, serial this txn started with 0x03fb45f7e3b31877 2024-09-13 06:15:53.367092, serial currently committed 0x03fb51e6663570bb 2024-09-15 09:10:23.955176)
2024-09-15T09:10:24 (:8080) no current transaction: tpc_abort()
2024-09-15T09:13:36 Unexpected error while trying to resolve conflict on <type 'BTrees.OIBTree.OIBucket'>
Traceback (most recent call last):
  File "/home/senaite/senaitelims/eggs/cp27mu/ZODB-5.8.0-py2.7.egg/ZODB/ConflictResolution.py", line 286, in tryToResolveConflict
    newstate = unpickler.load()
UnpicklingError: NEWOBJ class argument isn't a type object
2024-09-15T09:13:36 Bad request, 'vote'
Traceback (most recent call last):
  File "/home/senaite/senaitelims/eggs/cp27mu/ZEO-5.3.0-py2.7.egg/ZEO/asyncio/server.py", line 103, in message_received
    result = getattr(self.zeo_storage, name)(*args)
  File "/home/senaite/senaitelims/eggs/cp27mu/ZEO-5.3.0-py2.7.egg/ZEO/StorageServer.py", line 374, in vote
    return self.lock_manager.lock(self, self._vote)
  File "/home/senaite/senaitelims/eggs/cp27mu/ZEO-5.3.0-py2.7.egg/ZEO/StorageServer.py", line 1168, in lock
    result = func()
  File "/home/senaite/senaitelims/eggs/cp27mu/ZEO-5.3.0-py2.7.egg/ZEO/StorageServer.py", line 395, in _vote
    getattr(self, op)(*args)
  File "/home/senaite/senaitelims/eggs/cp27mu/ZEO-5.3.0-py2.7.egg/ZEO/StorageServer.py", line 529, in _store
    self.storage.store(oid, serial, data, '', self.transaction)
  File "/home/senaite/senaitelims/eggs/cp27mu/ZODB-5.8.0-py2.7.egg/ZODB/FileStorage/FileStorage.py", line 616, in store
    oldserial, data)
  File "/home/senaite/senaitelims/eggs/cp27mu/ZODB-5.8.0-py2.7.egg/ZODB/ConflictResolution.py", line 311, in tryToResolveConflict
    data=newpickle)
ConflictError: database conflict error (oid 0x0127df18, class BTrees.OIBTree.OIBucket, serial this txn started with 0x03fb51e672b921aa 2024-09-15 09:10:26.888243, serial currently committed 0x03fb51e99a350d22 2024-09-15 09:13:36.142320)
2024-09-15T09:13:36 (:8080) no current transaction: tpc_abort()
2024-09-16T08:47:43 (37) created PID file '/data/zeoserver/zeoserver.pid'
2024-09-16T08:47:43 (37) opening storage u'1' using FileStorage
2024-09-16T08:47:45 StorageServer created RW with storages: 1:RW:/data/filestorage/Data.fs
2024-09-16T08:47:45 listening on ('', 8080)
2024-09-16T08:47:51 Connected server protocol
2024-09-16T08:47:51 Connected server protocol
2024-09-16T08:47:51 received handshake 'Z5'
2024-09-16T08:47:51 received handshake 'Z5'
2024-09-16T08:56:30 Unexpected error while trying to resolve conflict on <type 'BTrees.OIBTree.OIBucket'>
Traceback (most recent call last):
  File "/home/senaite/senaitelims/eggs/cp27mu/ZODB-5.8.0-py2.7.egg/ZODB/ConflictResolution.py", line 286, in tryToResolveConflict
    newstate = unpickler.load()
UnpicklingError: NEWOBJ class argument isn't a type object
2024-09-16T08:56:30 Bad request, 'vote'
Traceback (most recent call last):
  File "/home/senaite/senaitelims/eggs/cp27mu/ZEO-5.3.0-py2.7.egg/ZEO/asyncio/server.py", line 103, in message_received
    result = getattr(self.zeo_storage, name)(*args)
  File "/home/senaite/senaitelims/eggs/cp27mu/ZEO-5.3.0-py2.7.egg/ZEO/StorageServer.py", line 374, in vote
    return self.lock_manager.lock(self, self._vote)
  File "/home/senaite/senaitelims/eggs/cp27mu/ZEO-5.3.0-py2.7.egg/ZEO/StorageServer.py", line 1168, in lock
    result = func()
  File "/home/senaite/senaitelims/eggs/cp27mu/ZEO-5.3.0-py2.7.egg/ZEO/StorageServer.py", line 395, in _vote
    getattr(self, op)(*args)
  File "/home/senaite/senaitelims/eggs/cp27mu/ZEO-5.3.0-py2.7.egg/ZEO/StorageServer.py", line 529, in _store
    self.storage.store(oid, serial, data, '', self.transaction)
  File "/home/senaite/senaitelims/eggs/cp27mu/ZODB-5.8.0-py2.7.egg/ZODB/FileStorage/FileStorage.py", line 616, in store
    oldserial, data)
  File "/home/senaite/senaitelims/eggs/cp27mu/ZODB-5.8.0-py2.7.egg/ZODB/ConflictResolution.py", line 311, in tryToResolveConflict
    data=newpickle)
ConflictError: database conflict error (oid 0x0127df18, class BTrees.OIBTree.OIBucket, serial this txn started with 0x03fb57787e241233 2024-09-16 08:56:29.564274, serial currently committed 0x03fb577880abdc99 2024-09-16 08:56:30.157344)
2024-09-16T08:56:30 (:8080) no current transaction: tpc_abort()
2024-09-16T09:20:04 (:8080) disconnected
2024-09-16T09:20:04 (:8080) disconnected
2024-09-16T09:20:25 (37) created PID file '/data/zeoserver/zeoserver.pid'
2024-09-16T09:20:25 (37) opening storage u'1' using FileStorage
2024-09-16T09:20:25 Ignoring index for /data/filestorage/Data.fs
2024-09-16T09:20:26 StorageServer created RW with storages: 1:RW:/data/filestorage/Data.fs
2024-09-16T09:20:26 listening on ('', 8080)
2024-09-16T09:20:31 Connected server protocol
2024-09-16T09:20:31 received handshake 'Z5'
2024-09-16T09:20:31 Connected server protocol
2024-09-16T09:20:31 received handshake 'Z5'
2024-09-16T09:23:35 (:8080) disconnected
2024-09-16T09:23:35 (:8080) disconnected
2024-09-16T09:30:43 (37) created PID file '/data/zeoserver/zeoserver.pid'
2024-09-16T09:30:43 (37) opening storage u'1' using FileStorage
2024-09-16T09:30:43 Ignoring index for /data/filestorage/Data.fs
2024-09-16T09:30:44 StorageServer created RW with storages: 1:RW:/data/filestorage/Data.fs
2024-09-16T09:30:44 listening on ('', 8080)
2024-09-16T09:30:52 Connected server protocol
2024-09-16T09:30:52 Connected server protocol
2024-09-16T09:30:52 received handshake 'Z5'
2024-09-16T09:30:52 received handshake 'Z5'
2024-09-16T09:32:07 Unexpected error while trying to resolve conflict on <ZODB.ConflictResolution.BadClass object at 0x7f3bbd515610>
Traceback (most recent call last):
  File "/home/senaite/senaitelims/eggs/cp27mu/ZODB-5.8.0-py2.7.egg/ZODB/ConflictResolution.py", line 274, in tryToResolveConflict
    inst = klass.__new__(klass, *newargs)
TypeError: object.__new__(X): X is not a type object (BadClass)
2024-09-16T09:32:07 Bad request, 'vote'
Traceback (most recent call last):
  File "/home/senaite/senaitelims/eggs/cp27mu/ZEO-5.3.0-py2.7.egg/ZEO/asyncio/server.py", line 103, in message_received
    result = getattr(self.zeo_storage, name)(*args)
  File "/home/senaite/senaitelims/eggs/cp27mu/ZEO-5.3.0-py2.7.egg/ZEO/StorageServer.py", line 374, in vote
    return self.lock_manager.lock(self, self._vote)
  File "/home/senaite/senaitelims/eggs/cp27mu/ZEO-5.3.0-py2.7.egg/ZEO/StorageServer.py", line 1168, in lock
    result = func()
  File "/home/senaite/senaitelims/eggs/cp27mu/ZEO-5.3.0-py2.7.egg/ZEO/StorageServer.py", line 395, in _vote
    getattr(self, op)(*args)
  File "/home/senaite/senaitelims/eggs/cp27mu/ZEO-5.3.0-py2.7.egg/ZEO/StorageServer.py", line 529, in _store
    self.storage.store(oid, serial, data, '', self.transaction)
  File "/home/senaite/senaitelims/eggs/cp27mu/ZODB-5.8.0-py2.7.egg/ZODB/FileStorage/FileStorage.py", line 616, in store
    oldserial, data)
  File "/home/senaite/senaitelims/eggs/cp27mu/ZODB-5.8.0-py2.7.egg/ZODB/ConflictResolution.py", line 311, in tryToResolveConflict
    data=newpickle)
ConflictError: database conflict error (oid 0x01fc, class Products.CMFPlone.Portal.PloneSite, serial this txn started with 0x03fb579bea5bb2ee 2024-09-16 09:31:54.927703, serial currently committed 0x03fb579c0597c544 2024-09-16 09:32:01.310825)
2024-09-16T09:32:07 (:8080) no current transaction: tpc_abort()
2024-09-16T09:32:07 Unexpected error while trying to resolve conflict on <ZODB.ConflictResolution.BadClass object at 0x7f3bbd5153d0>
Traceback (most recent call last):
  File "/home/senaite/senaitelims/eggs/cp27mu/ZODB-5.8.0-py2.7.egg/ZODB/ConflictResolution.py", line 274, in tryToResolveConflict
    inst = klass.__new__(klass, *newargs)
TypeError: object.__new__(X): X is not a type object (BadClass)
2024-09-16T09:32:07 Bad request, 'vote'
Traceback (most recent call last):
  File "/home/senaite/senaitelims/eggs/cp27mu/ZEO-5.3.0-py2.7.egg/ZEO/asyncio/server.py", line 103, in message_received
    result = getattr(self.zeo_storage, name)(*args)
  File "/home/senaite/senaitelims/eggs/cp27mu/ZEO-5.3.0-py2.7.egg/ZEO/StorageServer.py", line 374, in vote
    return self.lock_manager.lock(self, self._vote)
  File "/home/senaite/senaitelims/eggs/cp27mu/ZEO-5.3.0-py2.7.egg/ZEO/StorageServer.py", line 1168, in lock
    result = func()
  File "/home/senaite/senaitelims/eggs/cp27mu/ZEO-5.3.0-py2.7.egg/ZEO/StorageServer.py", line 395, in _vote
    getattr(self, op)(*args)
  File "/home/senaite/senaitelims/eggs/cp27mu/ZEO-5.3.0-py2.7.egg/ZEO/StorageServer.py", line 529, in _store
    self.storage.store(oid, serial, data, '', self.transaction)
  File "/home/senaite/senaitelims/eggs/cp27mu/ZODB-5.8.0-py2.7.egg/ZODB/FileStorage/FileStorage.py", line 616, in store
    oldserial, data)
  File "/home/senaite/senaitelims/eggs/cp27mu/ZODB-5.8.0-py2.7.egg/ZODB/ConflictResolution.py", line 311, in tryToResolveConflict
    data=newpickle)
ConflictError: database conflict error (oid 0x01fc, class Products.CMFPlone.Portal.PloneSite, serial this txn started with 0x03fb579bea5bb2ee 2024-09-16 09:31:54.927703, serial currently committed 0x03fb579c0597c544 2024-09-16 09:32:01.310825)
2024-09-16T09:32:07 (:8080) no current transaction: tpc_abort()
2024-09-16T09:32:16 Unexpected error while trying to resolve conflict on <ZODB.ConflictResolution.BadClass object at 0x7f3bbd5155d0>
Traceback (most recent call last):
  File "/home/senaite/senaitelims/eggs/cp27mu/ZODB-5.8.0-py2.7.egg/ZODB/ConflictResolution.py", line 274, in tryToResolveConflict
    inst = klass.__new__(klass, *newargs)
TypeError: object.__new__(X): X is not a type object (BadClass)
2024-09-16T09:32:16 Bad request, 'vote'
Traceback (most recent call last):
  File "/home/senaite/senaitelims/eggs/cp27mu/ZEO-5.3.0-py2.7.egg/ZEO/asyncio/server.py", line 103, in message_received
    result = getattr(self.zeo_storage, name)(*args)
  File "/home/senaite/senaitelims/eggs/cp27mu/ZEO-5.3.0-py2.7.egg/ZEO/StorageServer.py", line 374, in vote
    return self.lock_manager.lock(self, self._vote)
  File "/home/senaite/senaitelims/eggs/cp27mu/ZEO-5.3.0-py2.7.egg/ZEO/StorageServer.py", line 1168, in lock
    result = func()
  File "/home/senaite/senaitelims/eggs/cp27mu/ZEO-5.3.0-py2.7.egg/ZEO/StorageServer.py", line 395, in _vote
    getattr(self, op)(*args)
  File "/home/senaite/senaitelims/eggs/cp27mu/ZEO-5.3.0-py2.7.egg/ZEO/StorageServer.py", line 529, in _store
    self.storage.store(oid, serial, data, '', self.transaction)
  File "/home/senaite/senaitelims/eggs/cp27mu/ZODB-5.8.0-py2.7.egg/ZODB/FileStorage/FileStorage.py", line 616, in store
    oldserial, data)
  File "/home/senaite/senaitelims/eggs/cp27mu/ZODB-5.8.0-py2.7.egg/ZODB/ConflictResolution.py", line 311, in tryToResolveConflict
    data=newpickle)
ConflictError: database conflict error (oid 0x01fc, class Products.CMFPlone.Portal.PloneSite, serial this txn started with 0x03fb579c0597c544 2024-09-16 09:32:01.310825, serial currently committed 0x03fb579c392d1744 2024-09-16 09:32:13.400657)
2024-09-16T09:32:16 (:8080) no current transaction: tpc_abort()
2024-09-16T09:32:18 Unexpected error while trying to resolve conflict on <ZODB.ConflictResolution.BadClass object at 0x7f3bbd515410>
Traceback (most recent call last):
  File "/home/senaite/senaitelims/eggs/cp27mu/ZODB-5.8.0-py2.7.egg/ZODB/ConflictResolution.py", line 274, in tryToResolveConflict
    inst = klass.__new__(klass, *newargs)
TypeError: object.__new__(X): X is not a type object (BadClass)
2024-09-16T09:32:18 Bad request, 'vote'
Traceback (most recent call last):
  File "/home/senaite/senaitelims/eggs/cp27mu/ZEO-5.3.0-py2.7.egg/ZEO/asyncio/server.py", line 103, in message_received
    result = getattr(self.zeo_storage, name)(*args)
  File "/home/senaite/senaitelims/eggs/cp27mu/ZEO-5.3.0-py2.7.egg/ZEO/StorageServer.py", line 374, in vote
    return self.lock_manager.lock(self, self._vote)
  File "/home/senaite/senaitelims/eggs/cp27mu/ZEO-5.3.0-py2.7.egg/ZEO/StorageServer.py", line 1168, in lock
    result = func()
  File "/home/senaite/senaitelims/eggs/cp27mu/ZEO-5.3.0-py2.7.egg/ZEO/StorageServer.py", line 395, in _vote
    getattr(self, op)(*args)
  File "/home/senaite/senaitelims/eggs/cp27mu/ZEO-5.3.0-py2.7.egg/ZEO/StorageServer.py", line 529, in _store
    self.storage.store(oid, serial, data, '', self.transaction)
  File "/home/senaite/senaitelims/eggs/cp27mu/ZODB-5.8.0-py2.7.egg/ZODB/FileStorage/FileStorage.py", line 616, in store
    oldserial, data)
  File "/home/senaite/senaitelims/eggs/cp27mu/ZODB-5.8.0-py2.7.egg/ZODB/ConflictResolution.py", line 311, in tryToResolveConflict
    data=newpickle)
ConflictError: database conflict error (oid 0x01fc, class Products.CMFPlone.Portal.PloneSite, serial this txn started with 0x03fb579c0597c544 2024-09-16 09:32:01.310825, serial currently committed 0x03fb579c392d1744 2024-09-16 09:32:13.400657)
2024-09-16T09:32:18 (:8080) no current transaction: tpc_abort()
2024-09-16T09:32:24 Unexpected error while trying to resolve conflict on <ZODB.ConflictResolution.BadClass object at 0x7f3bbd5155d0>
Traceback (most recent call last):
  File "/home/senaite/senaitelims/eggs/cp27mu/ZODB-5.8.0-py2.7.egg/ZODB/ConflictResolution.py", line 274, in tryToResolveConflict
    inst = klass.__new__(klass, *newargs)
TypeError: object.__new__(X): X is not a type object (BadClass)
2024-09-16T09:32:24 Bad request, 'vote'
Traceback (most recent call last):
  File "/home/senaite/senaitelims/eggs/cp27mu/ZEO-5.3.0-py2.7.egg/ZEO/asyncio/server.py", line 103, in message_received
    result = getattr(self.zeo_storage, name)(*args)
  File "/home/senaite/senaitelims/eggs/cp27mu/ZEO-5.3.0-py2.7.egg/ZEO/StorageServer.py", line 374, in vote
    return self.lock_manager.lock(self, self._vote)
  File "/home/senaite/senaitelims/eggs/cp27mu/ZEO-5.3.0-py2.7.egg/ZEO/StorageServer.py", line 1168, in lock
    result = func()
  File "/home/senaite/senaitelims/eggs/cp27mu/ZEO-5.3.0-py2.7.egg/ZEO/StorageServer.py", line 395, in _vote
    getattr(self, op)(*args)
  File "/home/senaite/senaitelims/eggs/cp27mu/ZEO-5.3.0-py2.7.egg/ZEO/StorageServer.py", line 529, in _store
    self.storage.store(oid, serial, data, '', self.transaction)
  File "/home/senaite/senaitelims/eggs/cp27mu/ZODB-5.8.0-py2.7.egg/ZODB/FileStorage/FileStorage.py", line 616, in store
    oldserial, data)
  File "/home/senaite/senaitelims/eggs/cp27mu/ZODB-5.8.0-py2.7.egg/ZODB/ConflictResolution.py", line 311, in tryToResolveConflict
    data=newpickle)
ConflictError: database conflict error (oid 0x01fc, class Products.CMFPlone.Portal.PloneSite, serial this txn started with 0x03fb579c392d1744 2024-09-16 09:32:13.400657, serial currently committed 0x03fb579c5fa9fb99 2024-09-16 09:32:22.421249)
2024-09-16T09:32:24 (:8080) no current transaction: tpc_abort()
2024-09-16T09:36:26 (:8080) disconnected
2024-09-16T09:36:26 (:8080) disconnected
2024-09-16T09:36:54 (37) created PID file '/data/zeoserver/zeoserver.pid'
2024-09-16T09:36:54 (37) opening storage u'1' using FileStorage
2024-09-16T09:36:54 Ignoring index for /data/filestorage/Data.fs
2024-09-16T09:36:54 StorageServer created RW with storages: 1:RW:/data/filestorage/Data.fs
2024-09-16T09:36:55 listening on ('', 8080)
2024-09-16T09:37:01 Connected server protocol
2024-09-16T09:37:01 received handshake 'Z5'
2024-09-16T09:37:01 Connected server protocol
2024-09-16T09:37:01 received handshake 'Z5'
2024-09-17T03:56:04 (:8080) disconnected
2024-09-17T03:56:04 (:8080) disconnected
2024-09-17T03:56:34 (37) created PID file '/data/zeoserver/zeoserver.pid'
2024-09-17T03:56:34 (37) opening storage u'1' using FileStorage
2024-09-17T03:56:34 Ignoring index for /data/filestorage/Data.fs
2024-09-17T03:57:05 StorageServer created RW with storages: 1:RW:/data/filestorage/Data.fs
2024-09-17T03:57:05 listening on ('', 8080)
2024-09-17T03:57:06 Connected server protocol
2024-09-17T03:57:06 received handshake 'Z5'
2024-09-17T03:57:07 Connected server protocol
2024-09-17T03:57:07 received handshake 'Z5'
2024-09-17T06:22:13 Unexpected error while trying to resolve conflict on <ZODB.ConflictResolution.BadClass object at 0x7f972ce6e850>
Traceback (most recent call last):
  File "/home/senaite/senaitelims/eggs/cp27mu/ZODB-5.8.0-py2.7.egg/ZODB/ConflictResolution.py", line 274, in tryToResolveConflict
    inst = klass.__new__(klass, *newargs)
TypeError: object.__new__(X): X is not a type object (BadClass)
2024-09-17T06:22:13 Bad request, 'vote'
Traceback (most recent call last):
  File "/home/senaite/senaitelims/eggs/cp27mu/ZEO-5.3.0-py2.7.egg/ZEO/asyncio/server.py", line 103, in message_received
    result = getattr(self.zeo_storage, name)(*args)
  File "/home/senaite/senaitelims/eggs/cp27mu/ZEO-5.3.0-py2.7.egg/ZEO/StorageServer.py", line 374, in vote
    return self.lock_manager.lock(self, self._vote)
  File "/home/senaite/senaitelims/eggs/cp27mu/ZEO-5.3.0-py2.7.egg/ZEO/StorageServer.py", line 1168, in lock
    result = func()
  File "/home/senaite/senaitelims/eggs/cp27mu/ZEO-5.3.0-py2.7.egg/ZEO/StorageServer.py", line 395, in _vote
    getattr(self, op)(*args)
  File "/home/senaite/senaitelims/eggs/cp27mu/ZEO-5.3.0-py2.7.egg/ZEO/StorageServer.py", line 529, in _store
    self.storage.store(oid, serial, data, '', self.transaction)
  File "/home/senaite/senaitelims/eggs/cp27mu/ZODB-5.8.0-py2.7.egg/ZODB/FileStorage/FileStorage.py", line 616, in store
    oldserial, data)
  File "/home/senaite/senaitelims/eggs/cp27mu/ZODB-5.8.0-py2.7.egg/ZODB/ConflictResolution.py", line 311, in tryToResolveConflict
    data=newpickle)
ConflictError: database conflict error (oid 0x275d, class Products.ZCatalog.Catalog.Catalog, serial this txn started with 0x03faf6d05521a522 2024-08-30 04:32:19.952678, serial currently committed 0x03fb5c65c5370f11 2024-09-17 05:57:46.222283)
2024-09-17T06:22:13 (:8080) no current transaction: tpc_abort()
2024-09-17T06:30:14 (:8080) pack(time=1723962614.696145) started...
2024-09-17T06:37:39 (:8080) pack(time=1723962614.696145) complete
2024-09-17T06:56:32 (:8080) pack(time=1725692192.579514) started...
2024-09-17T07:00:28 Unexpected error while trying to resolve conflict on <ZODB.ConflictResolution.BadClass object at 0x7f972ba819d0>
Traceback (most recent call last):
  File "/home/senaite/senaitelims/eggs/cp27mu/ZODB-5.8.0-py2.7.egg/ZODB/ConflictResolution.py", line 274, in tryToResolveConflict
    inst = klass.__new__(klass, *newargs)
TypeError: object.__new__(X): X is not a type object (BadClass)
2024-09-17T07:00:28 Bad request, 'vote'
Traceback (most recent call last):
  File "/home/senaite/senaitelims/eggs/cp27mu/ZEO-5.3.0-py2.7.egg/ZEO/asyncio/server.py", line 103, in message_received
    result = getattr(self.zeo_storage, name)(*args)
  File "/home/senaite/senaitelims/eggs/cp27mu/ZEO-5.3.0-py2.7.egg/ZEO/StorageServer.py", line 374, in vote
    return self.lock_manager.lock(self, self._vote)
  File "/home/senaite/senaitelims/eggs/cp27mu/ZEO-5.3.0-py2.7.egg/ZEO/StorageServer.py", line 1168, in lock
    result = func()
  File "/home/senaite/senaitelims/eggs/cp27mu/ZEO-5.3.0-py2.7.egg/ZEO/StorageServer.py", line 395, in _vote
    getattr(self, op)(*args)
  File "/home/senaite/senaitelims/eggs/cp27mu/ZEO-5.3.0-py2.7.egg/ZEO/StorageServer.py", line 529, in _store
    self.storage.store(oid, serial, data, '', self.transaction)
  File "/home/senaite/senaitelims/eggs/cp27mu/ZODB-5.8.0-py2.7.egg/ZODB/FileStorage/FileStorage.py", line 616, in store
    oldserial, data)
  File "/home/senaite/senaitelims/eggs/cp27mu/ZODB-5.8.0-py2.7.egg/ZODB/ConflictResolution.py", line 311, in tryToResolveConflict
    data=newpickle)
ConflictError: database conflict error (oid 0x222d, class Products.ZCatalog.Catalog.Catalog, serial this txn started with 0x03faf6d05521a522 2024-08-30 04:32:19.952678, serial currently committed 0x03fb5c93dff09255 2024-09-17 06:43:52.485875)
2024-09-17T07:00:28 (:8080) no current transaction: tpc_abort()
2024-09-17T07:03:32 (:8080) pack(time=1725692192.579514) complete
2024-09-17T07:22:46 (:8080) pack(time=1726471366.166567) started...
2024-09-17T07:28:53 (:8080) pack(time=1726471366.166567) complete
2024-09-17T07:33:09 (:8080) pack(time=1726558389.146057) started...
2024-09-17T07:37:12 (:8080) pack(time=1726558389.146057) complete
2024-09-17T07:43:45 (:8080) pack(time=1717919025.856788) started...
2024-09-17T07:43:46 The database has already been packed to a later time or no changes have been made since the last pack
2024-09-17T07:43:46 (:8080) pack(time=1717919025.856788) complete
2024-09-17T07:43:55 (:8080) pack(time=1709279035.428459) started...
2024-09-17T07:43:55 The database has already been packed to a later time or no changes have been made since the last pack
2024-09-17T07:43:55 (:8080) pack(time=1709279035.428459) complete
2024-09-17T07:44:00 (:8080) pack(time=1725695040.791979) started...
2024-09-17T07:44:19 The database has already been packed to a later time or no changes have been made since the last pack
2024-09-17T07:44:19 (:8080) pack(time=1725695040.791979) complete
2024-09-17T07:44:29 (:8080) pack(time=1718783069.017647) started...
2024-09-17T07:44:29 The database has already been packed to a later time or no changes have been made since the last pack
2024-09-17T07:44:29 (:8080) pack(time=1718783069.017647) complete
2024-09-17T07:44:32 (:8080) pack(time=1719647072.711257) started...
2024-09-17T07:44:42 The database has already been packed to a later time or no changes have been made since the last pack
2024-09-17T07:44:42 (:8080) pack(time=1719647072.711257) complete
2024-09-17T08:19:18 (:8080) disconnected
2024-09-17T08:19:18 (:8080) disconnected
2024-09-17T08:20:32 (37) created PID file '/data/zeoserver/zeoserver.pid'
2024-09-17T08:20:32 (37) opening storage u'1' using FileStorage
2024-09-17T08:20:32 Ignoring index for /data/filestorage/Data.fs
2024-09-17T08:20:32 (37) Blob directory /data/blobstorage does not exist. Selected `bushy` layout. 
2024-09-17T08:20:32 (37) Blob directory '/data/blobstorage/' does not exist. Created new directory.
2024-09-17T08:20:32 (37) Blob temporary directory '/data/blobstorage/tmp' does not exist. Created new directory.
2024-09-17T08:20:33 StorageServer created RW with storages: 1:RW:/data/filestorage/Data.fs
2024-09-17T08:20:33 listening on ('', 8080)
2024-09-17T08:20:39 Connected server protocol
2024-09-17T08:20:39 received handshake 'Z5'
2024-09-17T08:20:39 Connected server protocol
2024-09-17T08:20:39 received handshake 'Z5'
2024-09-17T08:20:55 Unexpected error while trying to resolve conflict on <ZODB.ConflictResolution.BadClass object at 0x7f7c3d098650>
Traceback (most recent call last):
  File "/home/senaite/senaitelims/eggs/cp27mu/ZODB-5.8.0-py2.7.egg/ZODB/ConflictResolution.py", line 274, in tryToResolveConflict
    inst = klass.__new__(klass, *newargs)
TypeError: object.__new__(X): X is not a type object (BadClass)
2024-09-17T08:20:55 Bad request, 'vote'
Traceback (most recent call last):
  File "/home/senaite/senaitelims/eggs/cp27mu/ZEO-5.3.0-py2.7.egg/ZEO/asyncio/server.py", line 103, in message_received
    result = getattr(self.zeo_storage, name)(*args)
  File "/home/senaite/senaitelims/eggs/cp27mu/ZEO-5.3.0-py2.7.egg/ZEO/StorageServer.py", line 374, in vote
    return self.lock_manager.lock(self, self._vote)
  File "/home/senaite/senaitelims/eggs/cp27mu/ZEO-5.3.0-py2.7.egg/ZEO/StorageServer.py", line 1168, in lock
    result = func()
  File "/home/senaite/senaitelims/eggs/cp27mu/ZEO-5.3.0-py2.7.egg/ZEO/StorageServer.py", line 395, in _vote
    getattr(self, op)(*args)
  File "/home/senaite/senaitelims/eggs/cp27mu/ZEO-5.3.0-py2.7.egg/ZEO/StorageServer.py", line 529, in _store
    self.storage.store(oid, serial, data, '', self.transaction)
  File "/home/senaite/senaitelims/eggs/cp27mu/ZODB-5.8.0-py2.7.egg/ZODB/FileStorage/FileStorage.py", line 616, in store
    oldserial, data)
  File "/home/senaite/senaitelims/eggs/cp27mu/ZODB-5.8.0-py2.7.egg/ZODB/ConflictResolution.py", line 311, in tryToResolveConflict
    data=newpickle)
ConflictError: database conflict error (oid 0x01, class OFS.Application.Application, serial this txn started with 0x03fb5cf4ead12600 2024-09-17 08:20:55.035231, serial currently committed 0x03fb5cf4eb976d77 2024-09-17 08:20:55.216761)
2024-09-17T08:20:55 (:8080) no current transaction: tpc_abort()
2024-09-17T08:20:55 (:8080) disconnected
2024-09-17T08:25:58 Unexpected error while trying to resolve conflict on <type 'BTrees.OIBTree.OIBucket'>
Traceback (most recent call last):
  File "/home/senaite/senaitelims/eggs/cp27mu/ZODB-5.8.0-py2.7.egg/ZODB/ConflictResolution.py", line 286, in tryToResolveConflict
    newstate = unpickler.load()
UnpicklingError: NEWOBJ class argument isn't a type object
2024-09-17T08:25:58 Bad request, 'vote'
Traceback (most recent call last):
  File "/home/senaite/senaitelims/eggs/cp27mu/ZEO-5.3.0-py2.7.egg/ZEO/asyncio/server.py", line 103, in message_received
    result = getattr(self.zeo_storage, name)(*args)
  File "/home/senaite/senaitelims/eggs/cp27mu/ZEO-5.3.0-py2.7.egg/ZEO/StorageServer.py", line 374, in vote
    return self.lock_manager.lock(self, self._vote)
  File "/home/senaite/senaitelims/eggs/cp27mu/ZEO-5.3.0-py2.7.egg/ZEO/StorageServer.py", line 1168, in lock
    result = func()
  File "/home/senaite/senaitelims/eggs/cp27mu/ZEO-5.3.0-py2.7.egg/ZEO/StorageServer.py", line 395, in _vote
    getattr(self, op)(*args)
  File "/home/senaite/senaitelims/eggs/cp27mu/ZEO-5.3.0-py2.7.egg/ZEO/StorageServer.py", line 529, in _store
    self.storage.store(oid, serial, data, '', self.transaction)
  File "/home/senaite/senaitelims/eggs/cp27mu/ZODB-5.8.0-py2.7.egg/ZODB/FileStorage/FileStorage.py", line 616, in store
    oldserial, data)
  File "/home/senaite/senaitelims/eggs/cp27mu/ZODB-5.8.0-py2.7.egg/ZODB/ConflictResolution.py", line 311, in tryToResolveConflict
    data=newpickle)
ConflictError: database conflict error (oid 0x4707, class BTrees.OIBTree.OIBucket, serial this txn started with 0x03fb5cf9f7ffc233 2024-09-17 08:25:58.124779, serial currently committed 0x03fb5cf9fa7085aa 2024-09-17 08:25:58.696767)
2024-09-17T08:25:58 (:8080) no current transaction: tpc_abort()
2024-09-17T08:32:35 (:8080) disconnected
2024-09-17T08:40:09 (36) created PID file '/data/zeoserver/zeoserver.pid'
2024-09-17T08:40:09 (36) opening storage u'1' using FileStorage
2024-09-17T08:40:09 Ignoring index for /data/filestorage/Data.fs
2024-09-17T08:40:35 StorageServer created RW with storages: 1:RW:/data/filestorage/Data.fs
2024-09-17T08:40:36 listening on ('', 8080)
2024-09-17T08:40:36 Connected server protocol
2024-09-17T08:40:36 received handshake 'Z5'
2024-09-17T08:40:36 Connected server protocol
2024-09-17T08:40:36 received handshake 'Z5'
2024-09-17T08:47:22 Unexpected error while trying to resolve conflict on <ZODB.ConflictResolution.BadClass object at 0x7f22a8fc3650>
Traceback (most recent call last):
  File "/home/senaite/senaitelims/eggs/cp27mu/ZODB-5.8.0-py2.7.egg/ZODB/ConflictResolution.py", line 274, in tryToResolveConflict
    inst = klass.__new__(klass, *newargs)
TypeError: object.__new__(X): X is not a type object (BadClass)
2024-09-17T08:47:22 Bad request, 'vote'
Traceback (most recent call last):
  File "/home/senaite/senaitelims/eggs/cp27mu/ZEO-5.3.0-py2.7.egg/ZEO/asyncio/server.py", line 103, in message_received
    result = getattr(self.zeo_storage, name)(*args)
  File "/home/senaite/senaitelims/eggs/cp27mu/ZEO-5.3.0-py2.7.egg/ZEO/StorageServer.py", line 374, in vote
    return self.lock_manager.lock(self, self._vote)
  File "/home/senaite/senaitelims/eggs/cp27mu/ZEO-5.3.0-py2.7.egg/ZEO/StorageServer.py", line 1168, in lock
    result = func()
  File "/home/senaite/senaitelims/eggs/cp27mu/ZEO-5.3.0-py2.7.egg/ZEO/StorageServer.py", line 395, in _vote
    getattr(self, op)(*args)
  File "/home/senaite/senaitelims/eggs/cp27mu/ZEO-5.3.0-py2.7.egg/ZEO/StorageServer.py", line 529, in _store
    self.storage.store(oid, serial, data, '', self.transaction)
  File "/home/senaite/senaitelims/eggs/cp27mu/ZODB-5.8.0-py2.7.egg/ZODB/FileStorage/FileStorage.py", line 616, in store
    oldserial, data)
  File "/home/senaite/senaitelims/eggs/cp27mu/ZODB-5.8.0-py2.7.egg/ZODB/ConflictResolution.py", line 311, in tryToResolveConflict
    data=newpickle)
ConflictError: database conflict error (oid 0x0127d302, class bika.lims.content.analysisrequest.AnalysisRequest, serial this txn started with 0x03fb1323c404a1dd 2024-09-04 05:23:45.941741, serial currently committed 0x03fb5d0f5d50f1cc 2024-09-17 08:47:21.870982)
2024-09-17T08:47:22 (:8080) no current transaction: tpc_abort()
2024-09-17T08:47:45 Unexpected error while trying to resolve conflict on <type 'BTrees.OIBTree.OIBucket'>
Traceback (most recent call last):
  File "/home/senaite/senaitelims/eggs/cp27mu/ZODB-5.8.0-py2.7.egg/ZODB/ConflictResolution.py", line 286, in tryToResolveConflict
    newstate = unpickler.load()
UnpicklingError: NEWOBJ class argument isn't a type object
2024-09-17T08:47:45 Bad request, 'vote'
Traceback (most recent call last):
  File "/home/senaite/senaitelims/eggs/cp27mu/ZEO-5.3.0-py2.7.egg/ZEO/asyncio/server.py", line 103, in message_received
    result = getattr(self.zeo_storage, name)(*args)
  File "/home/senaite/senaitelims/eggs/cp27mu/ZEO-5.3.0-py2.7.egg/ZEO/StorageServer.py", line 374, in vote
    return self.lock_manager.lock(self, self._vote)
  File "/home/senaite/senaitelims/eggs/cp27mu/ZEO-5.3.0-py2.7.egg/ZEO/StorageServer.py", line 1168, in lock
    result = func()
  File "/home/senaite/senaitelims/eggs/cp27mu/ZEO-5.3.0-py2.7.egg/ZEO/StorageServer.py", line 395, in _vote
    getattr(self, op)(*args)
  File "/home/senaite/senaitelims/eggs/cp27mu/ZEO-5.3.0-py2.7.egg/ZEO/StorageServer.py", line 529, in _store
    self.storage.store(oid, serial, data, '', self.transaction)
  File "/home/senaite/senaitelims/eggs/cp27mu/ZODB-5.8.0-py2.7.egg/ZODB/FileStorage/FileStorage.py", line 616, in store
    oldserial, data)
  File "/home/senaite/senaitelims/eggs/cp27mu/ZODB-5.8.0-py2.7.egg/ZODB/ConflictResolution.py", line 311, in tryToResolveConflict
    data=newpickle)
ConflictError: database conflict error (oid 0x012cabfb, class BTrees.OIBTree.OIBucket, serial this txn started with 0x03fb5d0fbd5da422 2024-09-17 08:47:44.382606, serial currently committed 0x03fb5d0fc04bc111 2024-09-17 08:47:45.069355)
2024-09-17T08:47:45 (:8080) no current transaction: tpc_abort()
2024-09-17T08:48:06 Unexpected error while trying to resolve conflict on <type 'BTrees.OIBTree.OIBucket'>
Traceback (most recent call last):
  File "/home/senaite/senaitelims/eggs/cp27mu/ZODB-5.8.0-py2.7.egg/ZODB/ConflictResolution.py", line 286, in tryToResolveConflict
    newstate = unpickler.load()
UnpicklingError: NEWOBJ class argument isn't a type object
2024-09-17T08:48:06 Bad request, 'vote'
Traceback (most recent call last):
  File "/home/senaite/senaitelims/eggs/cp27mu/ZEO-5.3.0-py2.7.egg/ZEO/asyncio/server.py", line 103, in message_received
    result = getattr(self.zeo_storage, name)(*args)
  File "/home/senaite/senaitelims/eggs/cp27mu/ZEO-5.3.0-py2.7.egg/ZEO/StorageServer.py", line 374, in vote
    return self.lock_manager.lock(self, self._vote)
  File "/home/senaite/senaitelims/eggs/cp27mu/ZEO-5.3.0-py2.7.egg/ZEO/StorageServer.py", line 1168, in lock
    result = func()
  File "/home/senaite/senaitelims/eggs/cp27mu/ZEO-5.3.0-py2.7.egg/ZEO/StorageServer.py", line 395, in _vote
    getattr(self, op)(*args)
  File "/home/senaite/senaitelims/eggs/cp27mu/ZEO-5.3.0-py2.7.egg/ZEO/StorageServer.py", line 529, in _store
    self.storage.store(oid, serial, data, '', self.transaction)
  File "/home/senaite/senaitelims/eggs/cp27mu/ZODB-5.8.0-py2.7.egg/ZODB/FileStorage/FileStorage.py", line 616, in store
    oldserial, data)
  File "/home/senaite/senaitelims/eggs/cp27mu/ZODB-5.8.0-py2.7.egg/ZODB/ConflictResolution.py", line 311, in tryToResolveConflict
    data=newpickle)
ConflictError: database conflict error (oid 0x012cabfb, class BTrees.OIBTree.OIBucket, serial this txn started with 0x03fb5d101ad50c33 2024-09-17 08:48:06.288801, serial currently committed 0x03fb5d101d3fb0aa 2024-09-17 08:48:06.855185)
2024-09-17T08:48:06 (:8080) no current transaction: tpc_abort()
2024-09-17T08:48:32 Unexpected error while trying to resolve conflict on <type 'BTrees.OIBTree.OIBucket'>
Traceback (most recent call last):
  File "/home/senaite/senaitelims/eggs/cp27mu/ZODB-5.8.0-py2.7.egg/ZODB/ConflictResolution.py", line 286, in tryToResolveConflict
    newstate = unpickler.load()
UnpicklingError: NEWOBJ class argument isn't a type object
2024-09-17T08:48:32 Bad request, 'vote'
Traceback (most recent call last):
  File "/home/senaite/senaitelims/eggs/cp27mu/ZEO-5.3.0-py2.7.egg/ZEO/asyncio/server.py", line 103, in message_received
    result = getattr(self.zeo_storage, name)(*args)
  File "/home/senaite/senaitelims/eggs/cp27mu/ZEO-5.3.0-py2.7.egg/ZEO/StorageServer.py", line 374, in vote
    return self.lock_manager.lock(self, self._vote)
  File "/home/senaite/senaitelims/eggs/cp27mu/ZEO-5.3.0-py2.7.egg/ZEO/StorageServer.py", line 1168, in lock
    result = func()
  File "/home/senaite/senaitelims/eggs/cp27mu/ZEO-5.3.0-py2.7.egg/ZEO/StorageServer.py", line 395, in _vote
    getattr(self, op)(*args)
  File "/home/senaite/senaitelims/eggs/cp27mu/ZEO-5.3.0-py2.7.egg/ZEO/StorageServer.py", line 529, in _store
    self.storage.store(oid, serial, data, '', self.transaction)
  File "/home/senaite/senaitelims/eggs/cp27mu/ZODB-5.8.0-py2.7.egg/ZODB/FileStorage/FileStorage.py", line 616, in store
    oldserial, data)
  File "/home/senaite/senaitelims/eggs/cp27mu/ZODB-5.8.0-py2.7.egg/ZODB/ConflictResolution.py", line 311, in tryToResolveConflict
    data=newpickle)
ConflictError: database conflict error (oid 0x012cabfb, class BTrees.OIBTree.OIBucket, serial this txn started with 0x03fb5d1089d60c55 2024-09-17 08:48:32.305342, serial currently committed 0x03fb5d108c09f933 2024-09-17 08:48:32.821631)
2024-09-17T08:48:32 (:8080) no current transaction: tpc_abort()
2024-09-17T08:48:44 Unexpected error while trying to resolve conflict on <type 'BTrees.OIBTree.OIBucket'>
Traceback (most recent call last):
  File "/home/senaite/senaitelims/eggs/cp27mu/ZODB-5.8.0-py2.7.egg/ZODB/ConflictResolution.py", line 286, in tryToResolveConflict
    newstate = unpickler.load()
UnpicklingError: NEWOBJ class argument isn't a type object
2024-09-17T08:48:44 Bad request, 'vote'
Traceback (most recent call last):
  File "/home/senaite/senaitelims/eggs/cp27mu/ZEO-5.3.0-py2.7.egg/ZEO/asyncio/server.py", line 103, in message_received
    result = getattr(self.zeo_storage, name)(*args)
  File "/home/senaite/senaitelims/eggs/cp27mu/ZEO-5.3.0-py2.7.egg/ZEO/StorageServer.py", line 374, in vote
    return self.lock_manager.lock(self, self._vote)
  File "/home/senaite/senaitelims/eggs/cp27mu/ZEO-5.3.0-py2.7.egg/ZEO/StorageServer.py", line 1168, in lock
    result = func()
  File "/home/senaite/senaitelims/eggs/cp27mu/ZEO-5.3.0-py2.7.egg/ZEO/StorageServer.py", line 395, in _vote
    getattr(self, op)(*args)
  File "/home/senaite/senaitelims/eggs/cp27mu/ZEO-5.3.0-py2.7.egg/ZEO/StorageServer.py", line 529, in _store
    self.storage.store(oid, serial, data, '', self.transaction)
  File "/home/senaite/senaitelims/eggs/cp27mu/ZODB-5.8.0-py2.7.egg/ZODB/FileStorage/FileStorage.py", line 616, in store
    oldserial, data)
  File "/home/senaite/senaitelims/eggs/cp27mu/ZODB-5.8.0-py2.7.egg/ZODB/ConflictResolution.py", line 311, in tryToResolveConflict
    data=newpickle)
ConflictError: database conflict error (oid 0x012cabfb, class BTrees.OIBTree.OIBucket, serial this txn started with 0x03fb5d10b64d6faa 2024-09-17 08:48:42.727145, serial currently committed 0x03fb5d10bd549800 2024-09-17 08:48:44.374323)
2024-09-17T08:48:44 (:8080) no current transaction: tpc_abort()
2024-09-17T08:49:07 Unexpected error while trying to resolve conflict on <type 'BTrees.OIBTree.OIBucket'>
Traceback (most recent call last):
  File "/home/senaite/senaitelims/eggs/cp27mu/ZODB-5.8.0-py2.7.egg/ZODB/ConflictResolution.py", line 286, in tryToResolveConflict
    newstate = unpickler.load()
UnpicklingError: NEWOBJ class argument isn't a type object
2024-09-17T08:49:07 Bad request, 'vote'
Traceback (most recent call last):
  File "/home/senaite/senaitelims/eggs/cp27mu/ZEO-5.3.0-py2.7.egg/ZEO/asyncio/server.py", line 103, in message_received
    result = getattr(self.zeo_storage, name)(*args)
  File "/home/senaite/senaitelims/eggs/cp27mu/ZEO-5.3.0-py2.7.egg/ZEO/StorageServer.py", line 374, in vote
    return self.lock_manager.lock(self, self._vote)
  File "/home/senaite/senaitelims/eggs/cp27mu/ZEO-5.3.0-py2.7.egg/ZEO/StorageServer.py", line 1168, in lock
    result = func()
  File "/home/senaite/senaitelims/eggs/cp27mu/ZEO-5.3.0-py2.7.egg/ZEO/StorageServer.py", line 395, in _vote
    getattr(self, op)(*args)
  File "/home/senaite/senaitelims/eggs/cp27mu/ZEO-5.3.0-py2.7.egg/ZEO/StorageServer.py", line 529, in _store
    self.storage.store(oid, serial, data, '', self.transaction)
  File "/home/senaite/senaitelims/eggs/cp27mu/ZODB-5.8.0-py2.7.egg/ZODB/FileStorage/FileStorage.py", line 616, in store
    oldserial, data)
  File "/home/senaite/senaitelims/eggs/cp27mu/ZODB-5.8.0-py2.7.egg/ZODB/ConflictResolution.py", line 311, in tryToResolveConflict
    data=newpickle)
ConflictError: database conflict error (oid 0x012cabfb, class BTrees.OIBTree.OIBucket, serial this txn started with 0x03fb5d111c4710ee 2024-09-17 08:49:06.627563, serial currently committed 0x03fb5d111e974333 2024-09-17 08:49:07.169735)
2024-09-17T08:49:07 (:8080) no current transaction: tpc_abort()
2024-09-17T08:49:40 Unexpected error while trying to resolve conflict on <type 'BTrees.OIBTree.OIBucket'>
Traceback (most recent call last):
  File "/home/senaite/senaitelims/eggs/cp27mu/ZODB-5.8.0-py2.7.egg/ZODB/ConflictResolution.py", line 286, in tryToResolveConflict
    newstate = unpickler.load()
UnpicklingError: NEWOBJ class argument isn't a type object
2024-09-17T08:49:40 Bad request, 'vote'
Traceback (most recent call last):
  File "/home/senaite/senaitelims/eggs/cp27mu/ZEO-5.3.0-py2.7.egg/ZEO/asyncio/server.py", line 103, in message_received
    result = getattr(self.zeo_storage, name)(*args)
  File "/home/senaite/senaitelims/eggs/cp27mu/ZEO-5.3.0-py2.7.egg/ZEO/StorageServer.py", line 374, in vote
    return self.lock_manager.lock(self, self._vote)
  File "/home/senaite/senaitelims/eggs/cp27mu/ZEO-5.3.0-py2.7.egg/ZEO/StorageServer.py", line 1168, in lock
    result = func()
  File "/home/senaite/senaitelims/eggs/cp27mu/ZEO-5.3.0-py2.7.egg/ZEO/StorageServer.py", line 395, in _vote
    getattr(self, op)(*args)
  File "/home/senaite/senaitelims/eggs/cp27mu/ZEO-5.3.0-py2.7.egg/ZEO/StorageServer.py", line 529, in _store
    self.storage.store(oid, serial, data, '', self.transaction)
  File "/home/senaite/senaitelims/eggs/cp27mu/ZODB-5.8.0-py2.7.egg/ZODB/FileStorage/FileStorage.py", line 616, in store
    oldserial, data)
  File "/home/senaite/senaitelims/eggs/cp27mu/ZODB-5.8.0-py2.7.egg/ZODB/ConflictResolution.py", line 311, in tryToResolveConflict
    data=newpickle)
ConflictError: database conflict error (oid 0x012cabfb, class BTrees.OIBTree.OIBucket, serial this txn started with 0x03fb5d11aab7e9ee 2024-09-17 08:49:40.012128, serial currently committed 0x03fb5d11ad052dee 2024-09-17 08:49:40.551617)
2024-09-17T08:49:40 (:8080) no current transaction: tpc_abort()
2024-09-17T08:50:23 Unexpected error while trying to resolve conflict on <type 'BTrees.OIBTree.OIBucket'>
Traceback (most recent call last):
  File "/home/senaite/senaitelims/eggs/cp27mu/ZODB-5.8.0-py2.7.egg/ZODB/ConflictResolution.py", line 286, in tryToResolveConflict
    newstate = unpickler.load()
UnpicklingError: NEWOBJ class argument isn't a type object
2024-09-17T08:50:23 Bad request, 'vote'
Traceback (most recent call last):
  File "/home/senaite/senaitelims/eggs/cp27mu/ZEO-5.3.0-py2.7.egg/ZEO/asyncio/server.py", line 103, in message_received
    result = getattr(self.zeo_storage, name)(*args)
  File "/home/senaite/senaitelims/eggs/cp27mu/ZEO-5.3.0-py2.7.egg/ZEO/StorageServer.py", line 374, in vote
    return self.lock_manager.lock(self, self._vote)
  File "/home/senaite/senaitelims/eggs/cp27mu/ZEO-5.3.0-py2.7.egg/ZEO/StorageServer.py", line 1168, in lock
    result = func()
  File "/home/senaite/senaitelims/eggs/cp27mu/ZEO-5.3.0-py2.7.egg/ZEO/StorageServer.py", line 395, in _vote
    getattr(self, op)(*args)
  File "/home/senaite/senaitelims/eggs/cp27mu/ZEO-5.3.0-py2.7.egg/ZEO/StorageServer.py", line 529, in _store
    self.storage.store(oid, serial, data, '', self.transaction)
  File "/home/senaite/senaitelims/eggs/cp27mu/ZODB-5.8.0-py2.7.egg/ZODB/FileStorage/FileStorage.py", line 616, in store
    oldserial, data)
  File "/home/senaite/senaitelims/eggs/cp27mu/ZODB-5.8.0-py2.7.egg/ZODB/ConflictResolution.py", line 311, in tryToResolveConflict
    data=newpickle)
ConflictError: database conflict error (oid 0x012cabfb, class BTrees.OIBTree.OIBucket, serial this txn started with 0x03fb5d125fa2a6cc 2024-09-17 08:50:22.414537, serial currently committed 0x03fb5d1262013daa 2024-09-17 08:50:22.969886)
2024-09-17T08:50:23 (:8080) no current transaction: tpc_abort()
2024-09-17T09:03:16 Unexpected error while trying to resolve conflict on <type 'BTrees.OIBTree.OIBucket'>
Traceback (most recent call last):
  File "/home/senaite/senaitelims/eggs/cp27mu/ZODB-5.8.0-py2.7.egg/ZODB/ConflictResolution.py", line 286, in tryToResolveConflict
    newstate = unpickler.load()
UnpicklingError: NEWOBJ class argument isn't a type object
2024-09-17T09:03:16 Bad request, 'vote'
Traceback (most recent call last):
  File "/home/senaite/senaitelims/eggs/cp27mu/ZEO-5.3.0-py2.7.egg/ZEO/asyncio/server.py", line 103, in message_received
    result = getattr(self.zeo_storage, name)(*args)
  File "/home/senaite/senaitelims/eggs/cp27mu/ZEO-5.3.0-py2.7.egg/ZEO/StorageServer.py", line 374, in vote
    return self.lock_manager.lock(self, self._vote)
  File "/home/senaite/senaitelims/eggs/cp27mu/ZEO-5.3.0-py2.7.egg/ZEO/StorageServer.py", line 1168, in lock
    result = func()
  File "/home/senaite/senaitelims/eggs/cp27mu/ZEO-5.3.0-py2.7.egg/ZEO/StorageServer.py", line 395, in _vote
    getattr(self, op)(*args)
  File "/home/senaite/senaitelims/eggs/cp27mu/ZEO-5.3.0-py2.7.egg/ZEO/StorageServer.py", line 529, in _store
    self.storage.store(oid, serial, data, '', self.transaction)
  File "/home/senaite/senaitelims/eggs/cp27mu/ZODB-5.8.0-py2.7.egg/ZODB/FileStorage/FileStorage.py", line 616, in store
    oldserial, data)
  File "/home/senaite/senaitelims/eggs/cp27mu/ZODB-5.8.0-py2.7.egg/ZODB/ConflictResolution.py", line 311, in tryToResolveConflict
    data=newpickle)
ConflictError: database conflict error (oid 0x012cadf8, class BTrees.OIBTree.OIBucket, serial this txn started with 0x03fb5d1e81441c44 2024-09-17 09:02:30.296732, serial currently committed 0x03fb5d1f480411dd 2024-09-17 09:03:16.878726)
2024-09-17T09:03:16 (:8080) no current transaction: tpc_abort()
2024-09-17T09:03:18 Unexpected error while trying to resolve conflict on <type 'BTrees.OIBTree.OIBucket'>
Traceback (most recent call last):
  File "/home/senaite/senaitelims/eggs/cp27mu/ZODB-5.8.0-py2.7.egg/ZODB/ConflictResolution.py", line 286, in tryToResolveConflict
    newstate = unpickler.load()
UnpicklingError: NEWOBJ class argument isn't a type object
2024-09-17T09:03:18 Bad request, 'vote'
Traceback (most recent call last):
  File "/home/senaite/senaitelims/eggs/cp27mu/ZEO-5.3.0-py2.7.egg/ZEO/asyncio/server.py", line 103, in message_received
    result = getattr(self.zeo_storage, name)(*args)
  File "/home/senaite/senaitelims/eggs/cp27mu/ZEO-5.3.0-py2.7.egg/ZEO/StorageServer.py", line 374, in vote
    return self.lock_manager.lock(self, self._vote)
  File "/home/senaite/senaitelims/eggs/cp27mu/ZEO-5.3.0-py2.7.egg/ZEO/StorageServer.py", line 1168, in lock
    result = func()
  File "/home/senaite/senaitelims/eggs/cp27mu/ZEO-5.3.0-py2.7.egg/ZEO/StorageServer.py", line 395, in _vote
    getattr(self, op)(*args)
  File "/home/senaite/senaitelims/eggs/cp27mu/ZEO-5.3.0-py2.7.egg/ZEO/StorageServer.py", line 529, in _store
    self.storage.store(oid, serial, data, '', self.transaction)
  File "/home/senaite/senaitelims/eggs/cp27mu/ZODB-5.8.0-py2.7.egg/ZODB/FileStorage/FileStorage.py", line 616, in store
    oldserial, data)
  File "/home/senaite/senaitelims/eggs/cp27mu/ZODB-5.8.0-py2.7.egg/ZODB/ConflictResolution.py", line 311, in tryToResolveConflict
    data=newpickle)
ConflictError: database conflict error (oid 0x012cafaa, class BTrees.OIBTree.OIBucket, serial this txn started with 0x03fb5d1f480411dd 2024-09-17 09:03:16.878726, serial currently committed 0x03fb5d1f4ee9ee00 2024-09-17 09:03:18.495419)
2024-09-17T09:03:18 (:8080) no current transaction: tpc_abort()
2024-09-17T11:23:33 (:8080) disconnected
2024-09-17T11:23:33 (:8080) disconnected
2024-09-17T11:51:35 (36) created PID file '/data/zeoserver/zeoserver.pid'
2024-09-17T11:51:35 (36) opening storage u'1' using FileStorage
2024-09-17T11:51:35 StorageServer created RW with storages: 1:RW:/data/filestorage/Data.fs
2024-09-17T11:51:35 listening on ('', 8080)
2024-09-17T11:51:42 Connected server protocol
2024-09-17T11:51:42 Connected server protocol
2024-09-17T11:51:42 received handshake 'Z5'
2024-09-17T11:51:42 received handshake 'Z5'
2024-09-17T18:19:38 (:8080) disconnected
2024-09-17T18:19:38 (:8080) disconnected
2024-09-18T04:49:45 (36) created PID file '/data/zeoserver/zeoserver.pid'
2024-09-18T04:49:45 (36) opening storage u'1' using FileStorage
2024-09-18T04:49:45 StorageServer created RW with storages: 1:RW:/data/filestorage/Data.fs
2024-09-18T04:49:45 listening on ('', 8080)
2024-09-18T04:49:54 Connected server protocol
2024-09-18T04:49:54 Connected server protocol
2024-09-18T04:49:54 received handshake 'Z5'
2024-09-18T04:49:54 received handshake 'Z5'
2024-09-18T04:57:31 (:8080) disconnected
2024-09-18T04:57:43 Connected server protocol
2024-09-18T04:57:43 received handshake 'Z5'
2024-09-18T05:07:54 (:8080) disconnected
2024-09-18T05:08:07 Connected server protocol
2024-09-18T05:08:07 received handshake 'Z5'
2024-09-18T05:14:08 (:8080) disconnected
2024-09-18T05:14:20 Connected server protocol
2024-09-18T05:14:20 received handshake 'Z5'
2024-09-18T05:16:37 (:8080) disconnected
2024-09-18T05:16:54 Connected server protocol
2024-09-18T05:16:54 received handshake 'Z5'
2024-09-18T06:46:21 (:8080) disconnected
2024-09-18T06:46:36 Connected server protocol
2024-09-18T06:46:36 received handshake 'Z5'
2024-09-18T06:48:58 (:8080) disconnected
2024-09-18T06:49:07 Connected server protocol
2024-09-18T06:49:07 received handshake 'Z5'
2024-09-18T07:10:08 (:8080) disconnected
2024-09-18T07:10:20 Connected server protocol
2024-09-18T07:10:20 received handshake 'Z5'
2024-09-18T07:14:28 (:8080) disconnected
2024-09-18T07:14:36 Connected server protocol
2024-09-18T07:14:36 received handshake 'Z5'
2024-09-18T07:35:32 (37) created PID file '/data/zeoserver/zeoserver.pid'
2024-09-18T07:35:32 (37) opening storage u'1' using FileStorage
2024-09-18T07:35:33 StorageServer created RW with storages: 1:RW:/data/filestorage/Data.fs
2024-09-18T07:35:33 listening on ('', 8080)
2024-09-18T07:35:47 Connected server protocol
2024-09-18T07:35:47 received handshake 'Z5'
2024-09-18T07:35:47 Connected server protocol
2024-09-18T07:35:47 received handshake 'Z5'
2024-09-18T07:37:17 (:8080) disconnected
2024-09-18T07:37:29 Connected server protocol
2024-09-18T07:37:29 received handshake 'Z5'
2024-09-18T07:50:52 (:8080) disconnected
2024-09-18T07:51:05 Connected server protocol
2024-09-18T07:51:05 received handshake 'Z5'
2024-09-18T07:56:08 (:8080) disconnected
2024-09-18T07:56:24 Connected server protocol
2024-09-18T07:56:24 received handshake 'Z5'
2024-09-18T08:00:45 (:8080) disconnected
2024-09-18T08:00:54 Connected server protocol
2024-09-18T08:00:54 received handshake 'Z5'
2024-09-18T08:09:08 (:8080) disconnected
2024-09-18T08:09:21 Connected server protocol
2024-09-18T08:09:21 received handshake 'Z5'
2024-09-18T08:16:38 (:8080) disconnected
2024-09-18T08:16:50 Connected server protocol
2024-09-18T08:16:50 received handshake 'Z5'
2024-09-18T08:20:12 (:8080) disconnected
2024-09-18T08:20:21 Connected server protocol
2024-09-18T08:20:21 received handshake 'Z5'
2024-09-18T08:22:04 (:8080) disconnected
2024-09-18T08:22:16 Connected server protocol
2024-09-18T08:22:16 received handshake 'Z5'
2024-09-18T08:32:39 (:8080) disconnected
2024-09-18T08:32:51 Connected server protocol
2024-09-18T08:32:51 received handshake 'Z5'
2024-09-18T08:55:48 (:8080) disconnected
2024-09-18T08:56:01 Connected server protocol
2024-09-18T08:56:01 received handshake 'Z5'
2024-09-18T08:57:19 (:8080) disconnected
2024-09-18T08:57:28 Connected server protocol
2024-09-18T08:57:28 received handshake 'Z5'
2024-09-18T11:03:05 (:8080) disconnected
2024-09-18T11:03:18 Connected server protocol
2024-09-18T11:03:18 received handshake 'Z5'
2024-09-18T18:17:43 (:8080) disconnected
2024-09-18T18:17:43 (:8080) disconnected
2024-09-19T03:57:27 (37) created PID file '/data/zeoserver/zeoserver.pid'
2024-09-19T03:57:27 (37) opening storage u'1' using FileStorage
2024-09-19T03:57:28 StorageServer created RW with storages: 1:RW:/data/filestorage/Data.fs
2024-09-19T03:57:28 listening on ('', 8080)
2024-09-19T03:57:38 Connected server protocol
2024-09-19T03:57:38 Connected server protocol
2024-09-19T03:57:38 received handshake 'Z5'
2024-09-19T03:57:38 received handshake 'Z5'
2024-09-19T04:09:40 (:8080) disconnected
2024-09-19T04:09:53 Connected server protocol
2024-09-19T04:09:53 received handshake 'Z5'
2024-09-19T04:44:56 (:8080) disconnected
2024-09-19T04:44:56 (:8080) disconnected
2024-09-19T04:56:25 (37) created PID file '/data/zeoserver/zeoserver.pid'
2024-09-19T04:56:25 (37) opening storage u'1' using FileStorage
2024-09-19T04:56:25 StorageServer created RW with storages: 1:RW:/data/filestorage/Data.fs
2024-09-19T04:56:25 listening on ('', 8080)
2024-09-19T04:56:35 Connected server protocol
2024-09-19T04:56:35 received handshake 'Z5'
2024-09-19T04:56:35 Connected server protocol
2024-09-19T04:56:35 received handshake 'Z5'
2024-09-19T04:59:41 Unexpected error while trying to resolve conflict on <ZODB.ConflictResolution.BadClass object at 0x7f4cbf1e1610>
Traceback (most recent call last):
  File "/home/senaite/senaitelims/eggs/cp27mu/ZODB-5.8.0-py2.7.egg/ZODB/ConflictResolution.py", line 274, in tryToResolveConflict
    inst = klass.__new__(klass, *newargs)
TypeError: object.__new__(X): X is not a type object (BadClass)
2024-09-19T04:59:41 Bad request, 'vote'
Traceback (most recent call last):
  File "/home/senaite/senaitelims/eggs/cp27mu/ZEO-5.3.0-py2.7.egg/ZEO/asyncio/server.py", line 103, in message_received
    result = getattr(self.zeo_storage, name)(*args)
  File "/home/senaite/senaitelims/eggs/cp27mu/ZEO-5.3.0-py2.7.egg/ZEO/StorageServer.py", line 374, in vote
    return self.lock_manager.lock(self, self._vote)
  File "/home/senaite/senaitelims/eggs/cp27mu/ZEO-5.3.0-py2.7.egg/ZEO/StorageServer.py", line 1168, in lock
    result = func()
  File "/home/senaite/senaitelims/eggs/cp27mu/ZEO-5.3.0-py2.7.egg/ZEO/StorageServer.py", line 395, in _vote
    getattr(self, op)(*args)
  File "/home/senaite/senaitelims/eggs/cp27mu/ZEO-5.3.0-py2.7.egg/ZEO/StorageServer.py", line 529, in _store
    self.storage.store(oid, serial, data, '', self.transaction)
  File "/home/senaite/senaitelims/eggs/cp27mu/ZODB-5.8.0-py2.7.egg/ZODB/FileStorage/FileStorage.py", line 616, in store
    oldserial, data)
  File "/home/senaite/senaitelims/eggs/cp27mu/ZODB-5.8.0-py2.7.egg/ZODB/ConflictResolution.py", line 311, in tryToResolveConflict
    data=newpickle)
ConflictError: database conflict error (oid 0x0127d302, class bika.lims.content.analysisrequest.AnalysisRequest, serial this txn started with 0x03fb5d0f5d50f1cc 2024-09-17 08:47:21.870982, serial currently committed 0x03fb676babb32011 2024-09-19 04:59:40.242119)
2024-09-19T04:59:41 (:8080) no current transaction: tpc_abort()
2024-09-19T04:59:54 (:8080) disconnected
2024-09-19T05:00:03 Connected server protocol
2024-09-19T05:00:03 received handshake 'Z5'
2024-09-19T07:35:47 (:8080) disconnected
2024-09-19T07:36:00 Connected server protocol
2024-09-19T07:36:00 received handshake 'Z5'
2024-09-19T07:39:35 (:8080) disconnected
2024-09-19T07:39:43 Connected server protocol
2024-09-19T07:39:43 received handshake 'Z5'
2024-09-19T07:44:38 (:8080) disconnected
2024-09-19T07:44:50 Connected server protocol
2024-09-19T07:44:50 received handshake 'Z5'
2024-09-19T07:46:57 (:8080) disconnected
2024-09-19T07:47:06 Connected server protocol
2024-09-19T07:47:06 received handshake 'Z5'
2024-09-19T07:48:08 (:8080) disconnected
2024-09-19T07:48:16 Connected server protocol
2024-09-19T07:48:16 received handshake 'Z5'
2024-09-19T07:58:31 (:8080) disconnected
2024-09-19T07:58:44 Connected server protocol
2024-09-19T07:58:44 received handshake 'Z5'
2024-09-19T07:59:49 (:8080) disconnected
2024-09-19T07:59:57 Connected server protocol
2024-09-19T07:59:57 received handshake 'Z5'
2024-09-19T08:00:37 (:8080) disconnected
2024-09-19T08:00:46 Connected server protocol
2024-09-19T08:00:46 received handshake 'Z5'
2024-09-19T08:01:41 Disconnected ConnectionResetError:[Errno 104] Connection reset by peer
2024-09-19T08:01:41 (:8080) disconnected
2024-09-19T08:01:51 Connected server protocol
2024-09-19T08:01:51 received handshake 'Z5'
2024-09-19T08:03:20 (:8080) disconnected
2024-09-19T08:03:28 Connected server protocol
2024-09-19T08:03:28 received handshake 'Z5'
2024-09-19T08:06:43 (:8080) disconnected
2024-09-19T08:06:59 Connected server protocol
2024-09-19T08:06:59 received handshake 'Z5'
2024-09-19T08:08:08 (:8080) disconnected
2024-09-19T08:08:17 Connected server protocol
2024-09-19T08:08:17 received handshake 'Z5'
2024-09-19T08:13:29 (:8080) disconnected
2024-09-19T08:13:42 Connected server protocol
2024-09-19T08:13:42 received handshake 'Z5'
2024-09-19T08:13:53 (:8080) disconnected
2024-09-19T08:14:01 Connected server protocol
2024-09-19T08:14:01 received handshake 'Z5'
2024-09-19T10:35:16 Unexpected error while trying to resolve conflict on <type 'BTrees.OIBTree.OIBucket'>
Traceback (most recent call last):
  File "/home/senaite/senaitelims/eggs/cp27mu/ZODB-5.8.0-py2.7.egg/ZODB/ConflictResolution.py", line 286, in tryToResolveConflict
    newstate = unpickler.load()
UnpicklingError: NEWOBJ class argument isn't a type object
2024-09-19T10:35:16 Bad request, 'vote'
Traceback (most recent call last):
  File "/home/senaite/senaitelims/eggs/cp27mu/ZEO-5.3.0-py2.7.egg/ZEO/asyncio/server.py", line 103, in message_received
    result = getattr(self.zeo_storage, name)(*args)
  File "/home/senaite/senaitelims/eggs/cp27mu/ZEO-5.3.0-py2.7.egg/ZEO/StorageServer.py", line 374, in vote
    return self.lock_manager.lock(self, self._vote)
  File "/home/senaite/senaitelims/eggs/cp27mu/ZEO-5.3.0-py2.7.egg/ZEO/StorageServer.py", line 1168, in lock
    result = func()
  File "/home/senaite/senaitelims/eggs/cp27mu/ZEO-5.3.0-py2.7.egg/ZEO/StorageServer.py", line 395, in _vote
    getattr(self, op)(*args)
  File "/home/senaite/senaitelims/eggs/cp27mu/ZEO-5.3.0-py2.7.egg/ZEO/StorageServer.py", line 529, in _store
    self.storage.store(oid, serial, data, '', self.transaction)
  File "/home/senaite/senaitelims/eggs/cp27mu/ZODB-5.8.0-py2.7.egg/ZODB/FileStorage/FileStorage.py", line 616, in store
    oldserial, data)
  File "/home/senaite/senaitelims/eggs/cp27mu/ZODB-5.8.0-py2.7.egg/ZODB/ConflictResolution.py", line 311, in tryToResolveConflict
    data=newpickle)
ConflictError: database conflict error (oid 0x012cafaa, class BTrees.OIBTree.OIBucket, serial this txn started with 0x03fb68bb41cea633 2024-09-19 10:35:15.423568, serial currently committed 0x03fb68bb44fcdf77 2024-09-19 10:35:16.169012)
2024-09-19T10:35:16 (:8080) no current transaction: tpc_abort()
2024-09-19T10:35:31 Unexpected error while trying to resolve conflict on <type 'BTrees.OIBTree.OIBucket'>
Traceback (most recent call last):
  File "/home/senaite/senaitelims/eggs/cp27mu/ZODB-5.8.0-py2.7.egg/ZODB/ConflictResolution.py", line 286, in tryToResolveConflict
    newstate = unpickler.load()
UnpicklingError: NEWOBJ class argument isn't a type object
2024-09-19T10:35:31 Bad request, 'vote'
Traceback (most recent call last):
  File "/home/senaite/senaitelims/eggs/cp27mu/ZEO-5.3.0-py2.7.egg/ZEO/asyncio/server.py", line 103, in message_received
    result = getattr(self.zeo_storage, name)(*args)
  File "/home/senaite/senaitelims/eggs/cp27mu/ZEO-5.3.0-py2.7.egg/ZEO/StorageServer.py", line 374, in vote
    return self.lock_manager.lock(self, self._vote)
  File "/home/senaite/senaitelims/eggs/cp27mu/ZEO-5.3.0-py2.7.egg/ZEO/StorageServer.py", line 1168, in lock
    result = func()
  File "/home/senaite/senaitelims/eggs/cp27mu/ZEO-5.3.0-py2.7.egg/ZEO/StorageServer.py", line 395, in _vote
    getattr(self, op)(*args)
  File "/home/senaite/senaitelims/eggs/cp27mu/ZEO-5.3.0-py2.7.egg/ZEO/StorageServer.py", line 529, in _store
    self.storage.store(oid, serial, data, '', self.transaction)
  File "/home/senaite/senaitelims/eggs/cp27mu/ZODB-5.8.0-py2.7.egg/ZODB/FileStorage/FileStorage.py", line 616, in store
    oldserial, data)
  File "/home/senaite/senaitelims/eggs/cp27mu/ZODB-5.8.0-py2.7.egg/ZODB/ConflictResolution.py", line 311, in tryToResolveConflict
    data=newpickle)
ConflictError: database conflict error (oid 0x012cafaa, class BTrees.OIBTree.OIBucket, serial this txn started with 0x03fb68bb7f643722 2024-09-19 10:35:29.857375, serial currently committed 0x03fb68bb84c47b77 2024-09-19 10:35:31.117385)
2024-09-19T10:35:31 (:8080) no current transaction: tpc_abort()
2024-09-19T10:35:44 Unexpected error while trying to resolve conflict on <type 'BTrees.OIBTree.OIBucket'>
Traceback (most recent call last):
  File "/home/senaite/senaitelims/eggs/cp27mu/ZODB-5.8.0-py2.7.egg/ZODB/ConflictResolution.py", line 286, in tryToResolveConflict
    newstate = unpickler.load()
UnpicklingError: NEWOBJ class argument isn't a type object
2024-09-19T10:35:44 Bad request, 'vote'
Traceback (most recent call last):
  File "/home/senaite/senaitelims/eggs/cp27mu/ZEO-5.3.0-py2.7.egg/ZEO/asyncio/server.py", line 103, in message_received
    result = getattr(self.zeo_storage, name)(*args)
  File "/home/senaite/senaitelims/eggs/cp27mu/ZEO-5.3.0-py2.7.egg/ZEO/StorageServer.py", line 374, in vote
    return self.lock_manager.lock(self, self._vote)
  File "/home/senaite/senaitelims/eggs/cp27mu/ZEO-5.3.0-py2.7.egg/ZEO/StorageServer.py", line 1168, in lock
    result = func()
  File "/home/senaite/senaitelims/eggs/cp27mu/ZEO-5.3.0-py2.7.egg/ZEO/StorageServer.py", line 395, in _vote
    getattr(self, op)(*args)
  File "/home/senaite/senaitelims/eggs/cp27mu/ZEO-5.3.0-py2.7.egg/ZEO/StorageServer.py", line 529, in _store
    self.storage.store(oid, serial, data, '', self.transaction)
  File "/home/senaite/senaitelims/eggs/cp27mu/ZODB-5.8.0-py2.7.egg/ZODB/FileStorage/FileStorage.py", line 616, in store
    oldserial, data)
  File "/home/senaite/senaitelims/eggs/cp27mu/ZODB-5.8.0-py2.7.egg/ZODB/ConflictResolution.py", line 311, in tryToResolveConflict
    data=newpickle)
ConflictError: database conflict error (oid 0x012cb530, class BTrees.OIBTree.OIBucket, serial this txn started with 0x03fb68bbb9ba7066 2024-09-19 10:35:43.530065, serial currently committed 0x03fb68bbbc411c22 2024-09-19 10:35:44.122110)
2024-09-19T10:35:44 (:8080) no current transaction: tpc_abort()
2024-09-20T03:27:36 (:8080) disconnected
2024-09-20T03:28:09 Connected server protocol
2024-09-20T03:28:09 received handshake 'Z5'
2024-09-20T03:30:43 (:8080) disconnected
2024-09-20T03:30:52 Connected server protocol
2024-09-20T03:30:52 received handshake 'Z5'
2024-09-20T04:20:07 (36) created PID file '/data/zeoserver/zeoserver.pid'
2024-09-20T04:20:07 (36) opening storage u'1' using FileStorage
2024-09-20T04:20:10 StorageServer created RW with storages: 1:RW:/data/filestorage/Data.fs
2024-09-20T04:20:10 listening on ('', 8080)
2024-09-20T04:20:21 Connected server protocol
2024-09-20T04:20:21 received handshake 'Z5'
2024-09-20T04:20:22 Connected server protocol
2024-09-20T04:20:22 received handshake 'Z5'
2024-09-20T04:33:03 (36) created PID file '/data/zeoserver/zeoserver.pid'
2024-09-20T04:33:03 (36) opening storage u'1' using FileStorage
2024-09-20T04:33:04 StorageServer created RW with storages: 1:RW:/data/filestorage/Data.fs
2024-09-20T04:33:04 listening on ('', 8080)
2024-09-20T04:33:15 Connected server protocol
2024-09-20T04:33:15 received handshake 'Z5'
2024-09-20T04:33:15 Connected server protocol
2024-09-20T04:33:15 received handshake 'Z5'
2024-09-20T05:05:48 (:8080) disconnected
2024-09-20T05:06:03 Connected server protocol
2024-09-20T05:06:03 received handshake 'Z5'
2024-09-20T05:08:29 (:8080) disconnected
2024-09-20T05:08:42 Connected server protocol
2024-09-20T05:08:42 received handshake 'Z5'
2024-09-20T05:10:55 (:8080) disconnected
2024-09-20T05:11:08 Connected server protocol
2024-09-20T05:11:08 received handshake 'Z5'
2024-09-20T05:20:52 (:8080) disconnected
2024-09-20T05:21:08 Connected server protocol
2024-09-20T05:21:08 received handshake 'Z5'
2024-09-20T05:28:04 (:8080) disconnected
2024-09-20T05:28:18 Connected server protocol
2024-09-20T05:28:18 received handshake 'Z5'
2024-09-20T05:31:56 (:8080) disconnected
2024-09-20T05:32:06 Connected server protocol
2024-09-20T05:32:06 received handshake 'Z5'
2024-09-20T05:33:11 (:8080) disconnected
2024-09-20T05:33:25 Connected server protocol
2024-09-20T05:33:25 received handshake 'Z5'
2024-09-20T05:35:59 (:8080) disconnected
2024-09-20T05:36:10 Connected server protocol
2024-09-20T05:36:10 received handshake 'Z5'
2024-09-20T05:38:10 (:8080) disconnected
2024-09-20T05:38:19 Connected server protocol
2024-09-20T05:38:19 received handshake 'Z5'
2024-09-20T07:17:38 (:8080) disconnected
2024-09-20T07:17:58 Connected server protocol
2024-09-20T07:17:58 received handshake 'Z5'
2024-09-20T07:52:55 (:8080) disconnected
2024-09-20T07:53:20 Connected server protocol
2024-09-20T07:53:20 received handshake 'Z5'
2024-09-20T08:43:09 (:8080) disconnected
2024-09-20T08:43:23 Connected server protocol
2024-09-20T08:43:23 received handshake 'Z5'
2024-09-20T08:43:30 (:8080) disconnected
2024-09-20T08:48:22 Connected server protocol
2024-09-20T08:48:22 received handshake 'Z5'
2024-09-20T08:48:35 (:8080) disconnected
2024-09-20T08:49:45 Connected server protocol
2024-09-20T08:49:45 received handshake 'Z5'
2024-09-20T08:49:52 (:8080) disconnected
2024-09-20T08:53:07 Connected server protocol
2024-09-20T08:53:07 received handshake 'Z5'
2024-09-20T08:57:54 Unexpected error while trying to resolve conflict on <type 'BTrees.OIBTree.OIBucket'>
Traceback (most recent call last):
  File "/home/senaite/senaitelims/eggs/cp27mu/ZODB-5.8.0-py2.7.egg/ZODB/ConflictResolution.py", line 286, in tryToResolveConflict
    newstate = unpickler.load()
UnpicklingError: NEWOBJ class argument isn't a type object
2024-09-20T08:57:54 Bad request, 'vote'
Traceback (most recent call last):
  File "/home/senaite/senaitelims/eggs/cp27mu/ZEO-5.3.0-py2.7.egg/ZEO/asyncio/server.py", line 103, in message_received
    result = getattr(self.zeo_storage, name)(*args)
  File "/home/senaite/senaitelims/eggs/cp27mu/ZEO-5.3.0-py2.7.egg/ZEO/StorageServer.py", line 374, in vote
    return self.lock_manager.lock(self, self._vote)
  File "/home/senaite/senaitelims/eggs/cp27mu/ZEO-5.3.0-py2.7.egg/ZEO/StorageServer.py", line 1168, in lock
    result = func()
  File "/home/senaite/senaitelims/eggs/cp27mu/ZEO-5.3.0-py2.7.egg/ZEO/StorageServer.py", line 395, in _vote
    getattr(self, op)(*args)
  File "/home/senaite/senaitelims/eggs/cp27mu/ZEO-5.3.0-py2.7.egg/ZEO/StorageServer.py", line 529, in _store
    self.storage.store(oid, serial, data, '', self.transaction)
  File "/home/senaite/senaitelims/eggs/cp27mu/ZODB-5.8.0-py2.7.egg/ZODB/FileStorage/FileStorage.py", line 616, in store
    oldserial, data)
  File "/home/senaite/senaitelims/eggs/cp27mu/ZODB-5.8.0-py2.7.egg/ZODB/ConflictResolution.py", line 311, in tryToResolveConflict
    data=newpickle)
ConflictError: database conflict error (oid 0x012cb8dc, class BTrees.OIBTree.OIBucket, serial this txn started with 0x03fb6df9df896b00 2024-09-20 08:57:52.391435, serial currently committed 0x03fb6df9e5089a99 2024-09-20 08:57:53.679752)
2024-09-20T08:57:54 (:8080) no current transaction: tpc_abort()
2024-09-20T09:02:07 Unexpected error while trying to resolve conflict on <type 'BTrees.OIBTree.OIBucket'>
Traceback (most recent call last):
  File "/home/senaite/senaitelims/eggs/cp27mu/ZODB-5.8.0-py2.7.egg/ZODB/ConflictResolution.py", line 286, in tryToResolveConflict
    newstate = unpickler.load()
UnpicklingError: NEWOBJ class argument isn't a type object
2024-09-20T09:02:07 Bad request, 'vote'
Traceback (most recent call last):
  File "/home/senaite/senaitelims/eggs/cp27mu/ZEO-5.3.0-py2.7.egg/ZEO/asyncio/server.py", line 103, in message_received
    result = getattr(self.zeo_storage, name)(*args)
  File "/home/senaite/senaitelims/eggs/cp27mu/ZEO-5.3.0-py2.7.egg/ZEO/StorageServer.py", line 374, in vote
    return self.lock_manager.lock(self, self._vote)
  File "/home/senaite/senaitelims/eggs/cp27mu/ZEO-5.3.0-py2.7.egg/ZEO/StorageServer.py", line 1168, in lock
    result = func()
  File "/home/senaite/senaitelims/eggs/cp27mu/ZEO-5.3.0-py2.7.egg/ZEO/StorageServer.py", line 395, in _vote
    getattr(self, op)(*args)
  File "/home/senaite/senaitelims/eggs/cp27mu/ZEO-5.3.0-py2.7.egg/ZEO/StorageServer.py", line 529, in _store
    self.storage.store(oid, serial, data, '', self.transaction)
  File "/home/senaite/senaitelims/eggs/cp27mu/ZODB-5.8.0-py2.7.egg/ZODB/FileStorage/FileStorage.py", line 616, in store
    oldserial, data)
  File "/home/senaite/senaitelims/eggs/cp27mu/ZODB-5.8.0-py2.7.egg/ZODB/ConflictResolution.py", line 311, in tryToResolveConflict
    data=newpickle)
ConflictError: database conflict error (oid 0x012cbb8a, class BTrees.OIBTree.OIBucket, serial this txn started with 0x03fb6dfe1ce4e388 2024-09-20 09:02:06.772054, serial currently committed 0x03fb6dfe1f8b4dee 2024-09-20 09:02:07.393162)
2024-09-20T09:02:07 (:8080) no current transaction: tpc_abort()
2024-09-20T09:03:07 Unexpected error while trying to resolve conflict on <type 'BTrees.OIBTree.OIBucket'>
Traceback (most recent call last):
  File "/home/senaite/senaitelims/eggs/cp27mu/ZODB-5.8.0-py2.7.egg/ZODB/ConflictResolution.py", line 286, in tryToResolveConflict
    newstate = unpickler.load()
UnpicklingError: NEWOBJ class argument isn't a type object
2024-09-20T09:03:07 Bad request, 'vote'
Traceback (most recent call last):
  File "/home/senaite/senaitelims/eggs/cp27mu/ZEO-5.3.0-py2.7.egg/ZEO/asyncio/server.py", line 103, in message_received
    result = getattr(self.zeo_storage, name)(*args)
  File "/home/senaite/senaitelims/eggs/cp27mu/ZEO-5.3.0-py2.7.egg/ZEO/StorageServer.py", line 374, in vote
    return self.lock_manager.lock(self, self._vote)
  File "/home/senaite/senaitelims/eggs/cp27mu/ZEO-5.3.0-py2.7.egg/ZEO/StorageServer.py", line 1168, in lock
    result = func()
  File "/home/senaite/senaitelims/eggs/cp27mu/ZEO-5.3.0-py2.7.egg/ZEO/StorageServer.py", line 395, in _vote
    getattr(self, op)(*args)
  File "/home/senaite/senaitelims/eggs/cp27mu/ZEO-5.3.0-py2.7.egg/ZEO/StorageServer.py", line 529, in _store
    self.storage.store(oid, serial, data, '', self.transaction)
  File "/home/senaite/senaitelims/eggs/cp27mu/ZODB-5.8.0-py2.7.egg/ZODB/FileStorage/FileStorage.py", line 616, in store
    oldserial, data)
  File "/home/senaite/senaitelims/eggs/cp27mu/ZODB-5.8.0-py2.7.egg/ZODB/ConflictResolution.py", line 311, in tryToResolveConflict
    data=newpickle)
ConflictError: database conflict error (oid 0x012cbb8a, class BTrees.OIBTree.OIBucket, serial this txn started with 0x03fb6dff1dbe4477 2024-09-20 09:03:06.971070, serial currently committed 0x03fb6dff201c6544 2024-09-20 09:03:07.525997)
2024-09-20T09:03:07 (:8080) no current transaction: tpc_abort()
2024-09-20T09:05:01 Unexpected error while trying to resolve conflict on <type 'BTrees.OIBTree.OIBucket'>
Traceback (most recent call last):
  File "/home/senaite/senaitelims/eggs/cp27mu/ZODB-5.8.0-py2.7.egg/ZODB/ConflictResolution.py", line 286, in tryToResolveConflict
    newstate = unpickler.load()
UnpicklingError: NEWOBJ class argument isn't a type object
2024-09-20T09:05:01 Bad request, 'vote'
Traceback (most recent call last):
  File "/home/senaite/senaitelims/eggs/cp27mu/ZEO-5.3.0-py2.7.egg/ZEO/asyncio/server.py", line 103, in message_received
    result = getattr(self.zeo_storage, name)(*args)
  File "/home/senaite/senaitelims/eggs/cp27mu/ZEO-5.3.0-py2.7.egg/ZEO/StorageServer.py", line 374, in vote
    return self.lock_manager.lock(self, self._vote)
  File "/home/senaite/senaitelims/eggs/cp27mu/ZEO-5.3.0-py2.7.egg/ZEO/StorageServer.py", line 1168, in lock
    result = func()
  File "/home/senaite/senaitelims/eggs/cp27mu/ZEO-5.3.0-py2.7.egg/ZEO/StorageServer.py", line 395, in _vote
    getattr(self, op)(*args)
  File "/home/senaite/senaitelims/eggs/cp27mu/ZEO-5.3.0-py2.7.egg/ZEO/StorageServer.py", line 529, in _store
    self.storage.store(oid, serial, data, '', self.transaction)
  File "/home/senaite/senaitelims/eggs/cp27mu/ZODB-5.8.0-py2.7.egg/ZODB/FileStorage/FileStorage.py", line 616, in store
    oldserial, data)
  File "/home/senaite/senaitelims/eggs/cp27mu/ZODB-5.8.0-py2.7.egg/ZODB/ConflictResolution.py", line 311, in tryToResolveConflict
    data=newpickle)
ConflictError: database conflict error (oid 0x012cbb8a, class BTrees.OIBTree.OIBucket, serial this txn started with 0x03fb6e01054e6ddd 2024-09-20 09:05:01.243679, serial currently committed 0x03fb6e010779bd55 2024-09-20 09:05:01.752081)
2024-09-20T09:05:01 (:8080) no current transaction: tpc_abort()
2024-09-20T09:10:22 (:8080) disconnected
2024-09-20T09:10:37 Connected server protocol
2024-09-20T09:10:37 received handshake 'Z5'
2024-09-20T09:12:32 (:8080) disconnected
2024-09-20T09:12:44 Connected server protocol
2024-09-20T09:12:44 received handshake 'Z5'
2024-09-20T09:13:32 Unexpected error while trying to resolve conflict on <type 'BTrees.OIBTree.OIBucket'>
Traceback (most recent call last):
  File "/home/senaite/senaitelims/eggs/cp27mu/ZODB-5.8.0-py2.7.egg/ZODB/ConflictResolution.py", line 286, in tryToResolveConflict
    newstate = unpickler.load()
UnpicklingError: NEWOBJ class argument isn't a type object
2024-09-20T09:13:32 Bad request, 'vote'
Traceback (most recent call last):
  File "/home/senaite/senaitelims/eggs/cp27mu/ZEO-5.3.0-py2.7.egg/ZEO/asyncio/server.py", line 103, in message_received
    result = getattr(self.zeo_storage, name)(*args)
  File "/home/senaite/senaitelims/eggs/cp27mu/ZEO-5.3.0-py2.7.egg/ZEO/StorageServer.py", line 374, in vote
    return self.lock_manager.lock(self, self._vote)
  File "/home/senaite/senaitelims/eggs/cp27mu/ZEO-5.3.0-py2.7.egg/ZEO/StorageServer.py", line 1168, in lock
    result = func()
  File "/home/senaite/senaitelims/eggs/cp27mu/ZEO-5.3.0-py2.7.egg/ZEO/StorageServer.py", line 395, in _vote
    getattr(self, op)(*args)
  File "/home/senaite/senaitelims/eggs/cp27mu/ZEO-5.3.0-py2.7.egg/ZEO/StorageServer.py", line 529, in _store
    self.storage.store(oid, serial, data, '', self.transaction)
  File "/home/senaite/senaitelims/eggs/cp27mu/ZODB-5.8.0-py2.7.egg/ZODB/FileStorage/FileStorage.py", line 616, in store
    oldserial, data)
  File "/home/senaite/senaitelims/eggs/cp27mu/ZODB-5.8.0-py2.7.egg/ZODB/ConflictResolution.py", line 311, in tryToResolveConflict
    data=newpickle)
ConflictError: database conflict error (oid 0x012cbb8a, class BTrees.OIBTree.OIBucket, serial this txn started with 0x03fb6e07292fc266 2024-09-20 09:11:09.653100, serial currently committed 0x03fb6e09897e3c88 2024-09-20 09:13:32.224948)
2024-09-20T09:13:32 (:8080) no current transaction: tpc_abort()
2024-09-20T09:18:47 (:8080) disconnected
2024-09-20T09:19:01 Connected server protocol
2024-09-20T09:19:01 received handshake 'Z5'
2024-09-20T09:21:13 (:8080) disconnected
2024-09-20T09:21:24 Connected server protocol
2024-09-20T09:21:24 received handshake 'Z5'
2024-09-20T09:25:39 (:8080) disconnected
2024-09-20T09:25:55 Connected server protocol
2024-09-20T09:25:55 received handshake 'Z5'
2024-09-20T09:32:28 (:8080) disconnected
2024-09-20T09:32:42 Connected server protocol
2024-09-20T09:32:42 received handshake 'Z5'
2024-09-20T09:34:01 (:8080) disconnected
2024-09-20T09:34:11 Connected server protocol
2024-09-20T09:34:11 received handshake 'Z5'
2024-09-20T09:36:26 (:8080) disconnected
2024-09-20T09:36:36 Connected server protocol
2024-09-20T09:36:36 received handshake 'Z5'
2024-09-20T09:38:45 (:8080) disconnected
2024-09-20T09:38:59 Connected server protocol
2024-09-20T09:38:59 received handshake 'Z5'
2024-09-20T09:42:06 (:8080) disconnected
2024-09-20T09:42:16 Connected server protocol
2024-09-20T09:42:16 received handshake 'Z5'
2024-09-20T09:48:43 (:8080) disconnected
2024-09-20T09:48:57 Connected server protocol
2024-09-20T09:48:57 received handshake 'Z5'
2024-09-20T09:54:45 (:8080) disconnected
2024-09-20T09:55:01 Connected server protocol
2024-09-20T09:55:01 received handshake 'Z5'
2024-09-20T09:55:29 (:8080) disconnected
2024-09-20T09:55:41 Connected server protocol
2024-09-20T09:55:41 received handshake 'Z5'
2024-09-20T09:56:45 (:8080) disconnected
2024-09-20T09:56:55 Connected server protocol
2024-09-20T09:56:55 received handshake 'Z5'
2024-09-20T09:58:06 (:8080) disconnected
2024-09-20T09:58:19 Connected server protocol
2024-09-20T09:58:19 received handshake 'Z5'
2024-09-20T10:08:28 (:8080) disconnected
2024-09-20T10:08:42 Connected server protocol
2024-09-20T10:08:42 received handshake 'Z5'
2024-09-20T10:34:53 (:8080) disconnected
2024-09-20T10:35:09 Connected server protocol
2024-09-20T10:35:09 received handshake 'Z5'
2024-09-20T10:36:24 (:8080) disconnected
2024-09-20T10:36:36 Connected server protocol
2024-09-20T10:36:36 received handshake 'Z5'
2024-09-20T10:43:24 (:8080) disconnected
2024-09-20T10:43:40 Connected server protocol
2024-09-20T10:43:40 received handshake 'Z5'
2024-09-20T10:45:02 (:8080) disconnected
2024-09-20T10:45:14 Connected server protocol
2024-09-20T10:45:14 received handshake 'Z5'
2024-09-20T10:48:43 (:8080) disconnected
2024-09-20T10:48:58 Connected server protocol
2024-09-20T10:48:58 received handshake 'Z5'
2024-09-20T11:06:43 (:8080) disconnected
2024-09-20T11:07:01 Connected server protocol
2024-09-20T11:07:01 received handshake 'Z5'
2024-09-20T11:42:33 (:8080) disconnected
2024-09-20T11:42:51 Connected server protocol
2024-09-20T11:42:51 received handshake 'Z5'
2024-09-21T05:25:49 (:8080) disconnected
2024-09-21T05:25:49 (:8080) disconnected
2024-09-23T03:44:18 (37) created PID file '/data/zeoserver/zeoserver.pid'
2024-09-23T03:44:18 (37) opening storage u'1' using FileStorage
2024-09-23T03:44:19 StorageServer created RW with storages: 1:RW:/data/filestorage/Data.fs
2024-09-23T03:44:19 listening on ('', 8080)
2024-09-23T03:44:28 Connected server protocol
2024-09-23T03:44:28 Connected server protocol
2024-09-23T03:44:28 received handshake 'Z5'
2024-09-23T03:44:28 received handshake 'Z5'
2024-09-23T08:46:10 (:8080) disconnected
2024-09-23T08:46:26 Connected server protocol
2024-09-23T08:46:26 received handshake 'Z5'
2024-09-23T08:50:55 (:8080) pack(time=1726476655.797488) started...
2024-09-23T08:51:16 The database has already been packed to a later time or no changes have been made since the last pack
2024-09-23T08:51:16 (:8080) pack(time=1726476655.797488) complete
2024-09-23T10:19:42 (36) created PID file '/data/zeoserver/zeoserver.pid'
2024-09-23T10:19:42 (36) opening storage u'1' using FileStorage
2024-09-23T10:19:43 StorageServer created RW with storages: 1:RW:/data/filestorage/Data.fs
2024-09-23T10:19:43 listening on ('', 8080)
2024-09-23T10:19:50 Connected server protocol
2024-09-23T10:19:50 received handshake 'Z5'
2024-09-23T10:19:50 Connected server protocol
2024-09-23T10:19:50 received handshake 'Z5'
2024-09-23T10:25:08 (36) created PID file '/data/zeoserver/zeoserver.pid'
2024-09-23T10:25:08 (36) opening storage u'1' using FileStorage
2024-09-23T10:25:08 StorageServer created RW with storages: 1:RW:/data/filestorage/Data.fs
2024-09-23T10:25:09 listening on ('', 8080)
2024-09-23T10:25:15 Connected server protocol
2024-09-23T10:25:15 Connected server protocol
2024-09-23T10:25:15 received handshake 'Z5'
2024-09-23T10:25:15 received handshake 'Z5'
2024-09-23T10:27:33 (:8080) disconnected
2024-09-23T10:27:43 Connected server protocol
2024-09-23T10:27:43 received handshake 'Z5'
2024-09-23T10:34:09 (:8080) disconnected
2024-09-23T10:34:24 Connected server protocol
2024-09-23T10:34:24 received handshake 'Z5'
2024-09-23T10:34:30 (:8080) disconnected
2024-09-23T10:36:38 Connected server protocol
2024-09-23T10:36:38 received handshake 'Z5'
2024-09-23T10:36:44 (:8080) disconnected
2024-09-23T10:37:29 Connected server protocol
2024-09-23T10:37:29 received handshake 'Z5'
2024-09-23T10:58:15 (:8080) disconnected
2024-09-23T10:58:30 Connected server protocol
2024-09-23T10:58:30 received handshake 'Z5'
2024-09-23T11:00:36 (:8080) disconnected
2024-09-23T11:00:46 Connected server protocol
2024-09-23T11:00:46 received handshake 'Z5'
2024-09-23T11:05:47 (:8080) disconnected
2024-09-23T11:06:00 Connected server protocol
2024-09-23T11:06:00 received handshake 'Z5'
2024-09-23T11:44:25 (:8080) disconnected
2024-09-23T11:44:41 Connected server protocol
2024-09-23T11:44:41 received handshake 'Z5'
2024-09-23T11:49:28 (:8080) disconnected
2024-09-23T11:49:39 Connected server protocol
2024-09-23T11:49:39 received handshake 'Z5'
2024-09-23T11:56:56 (:8080) disconnected
2024-09-23T11:57:12 Connected server protocol
2024-09-23T11:57:12 received handshake 'Z5'
2024-09-23T11:59:48 (:8080) disconnected
2024-09-23T11:59:57 Connected server protocol
2024-09-23T11:59:57 received handshake 'Z5'
2024-09-23T12:06:50 (:8080) disconnected
2024-09-23T12:07:02 Connected server protocol
2024-09-23T12:07:02 received handshake 'Z5'
2024-09-24T06:13:12 (:8080) disconnected
2024-09-24T06:13:30 Connected server protocol
2024-09-24T06:13:30 received handshake 'Z5'
2024-09-24T06:21:59 (:8080) disconnected
2024-09-24T06:22:13 Connected server protocol
2024-09-24T06:22:13 received handshake 'Z5'
2024-09-24T06:34:12 (:8080) disconnected
2024-09-24T06:34:24 Connected server protocol
2024-09-24T06:34:24 received handshake 'Z5'
2024-09-24T06:39:31 (:8080) disconnected
2024-09-24T06:39:43 Connected server protocol
2024-09-24T06:39:43 received handshake 'Z5'
2024-09-24T06:40:58 (:8080) disconnected
2024-09-24T06:41:07 Connected server protocol
2024-09-24T06:41:07 received handshake 'Z5'
2024-09-24T06:44:47 (:8080) disconnected
2024-09-24T06:45:01 Connected server protocol
2024-09-24T06:45:01 received handshake 'Z5'
2024-09-24T06:48:45 (:8080) disconnected
2024-09-24T06:48:54 Connected server protocol
2024-09-24T06:48:54 received handshake 'Z5'
2024-09-24T06:56:50 (:8080) disconnected
2024-09-24T06:57:03 Connected server protocol
2024-09-24T06:57:03 received handshake 'Z5'
2024-09-24T09:21:20 (:8080) disconnected
2024-09-24T09:21:35 Connected server protocol
2024-09-24T09:21:35 received handshake 'Z5'
2024-09-24T09:40:57 (:8080) disconnected
2024-09-24T09:41:09 Connected server protocol
2024-09-24T09:41:09 received handshake 'Z5'
2024-09-24T09:53:36 (:8080) disconnected
2024-09-24T09:53:49 Connected server protocol
2024-09-24T09:53:49 received handshake 'Z5'
2024-09-24T10:00:55 (:8080) disconnected
2024-09-24T10:01:08 Connected server protocol
2024-09-24T10:01:08 received handshake 'Z5'
2024-09-24T10:01:49 (:8080) disconnected
2024-09-24T10:01:58 Connected server protocol
2024-09-24T10:01:58 received handshake 'Z5'
2024-09-24T10:03:30 (:8080) disconnected
2024-09-24T10:03:38 Connected server protocol
2024-09-24T10:03:38 received handshake 'Z5'
2024-09-24T10:05:08 (:8080) disconnected
2024-09-24T10:05:17 Connected server protocol
2024-09-24T10:05:17 received handshake 'Z5'
2024-09-24T10:06:58 (:8080) disconnected
2024-09-24T10:07:11 Connected server protocol
2024-09-24T10:07:11 received handshake 'Z5'
2024-09-24T10:09:37 (:8080) disconnected
2024-09-24T10:09:46 Connected server protocol
2024-09-24T10:09:46 received handshake 'Z5'
2024-09-24T10:22:09 (:8080) disconnected
2024-09-24T10:22:22 Connected server protocol
2024-09-24T10:22:22 received handshake 'Z5'
2024-09-24T10:35:22 (:8080) disconnected
2024-09-24T10:35:35 Connected server protocol
2024-09-24T10:35:35 received handshake 'Z5'
2024-09-24T10:37:24 (:8080) disconnected
2024-09-24T10:37:32 Connected server protocol
2024-09-24T10:37:32 received handshake 'Z5'
2024-09-24T10:43:34 (:8080) disconnected
2024-09-24T10:43:48 Connected server protocol
2024-09-24T10:43:48 received handshake 'Z5'
2024-09-24T10:49:08 (:8080) disconnected
2024-09-24T10:49:20 Connected server protocol
2024-09-24T10:49:20 received handshake 'Z5'
2024-09-24T10:55:45 (:8080) disconnected
2024-09-24T10:55:57 Connected server protocol
2024-09-24T10:55:57 received handshake 'Z5'
2024-09-24T11:01:01 (:8080) disconnected
2024-09-24T11:01:15 Connected server protocol
2024-09-24T11:01:15 received handshake 'Z5'
2024-09-25T03:51:39 (:8080) disconnected
2024-09-25T03:51:59 Connected server protocol
2024-09-25T03:51:59 received handshake 'Z5'
2024-09-25T04:03:29 (:8080) disconnected
2024-09-25T04:03:51 Connected server protocol
2024-09-25T04:03:51 received handshake 'Z5'
2024-09-25T04:22:22 (:8080) disconnected
2024-09-25T04:22:22 (:8080) disconnected
2024-09-25T04:39:28 (36) created PID file '/data/zeoserver/zeoserver.pid'
2024-09-25T04:39:28 (36) opening storage u'1' using FileStorage
2024-09-25T04:39:28 StorageServer created RW with storages: 1:RW:/data/filestorage/Data.fs
2024-09-25T04:39:29 listening on ('', 8080)
2024-09-25T04:39:36 Connected server protocol
2024-09-25T04:39:36 Connected server protocol
2024-09-25T04:39:36 received handshake 'Z5'
2024-09-25T04:39:36 received handshake 'Z5'
2024-09-25T04:42:52 (:8080) disconnected
2024-09-25T04:43:02 Connected server protocol
2024-09-25T04:43:02 received handshake 'Z5'
2024-09-25T04:50:49 (36) created PID file '/data/zeoserver/zeoserver.pid'
2024-09-25T04:50:49 (36) opening storage u'1' using FileStorage
2024-09-25T04:50:50 StorageServer created RW with storages: 1:RW:/data/filestorage/Data.fs
2024-09-25T04:50:50 listening on ('', 8080)
2024-09-25T04:50:58 Connected server protocol
2024-09-25T04:50:58 received handshake 'Z5'
2024-09-25T04:50:58 Connected server protocol
2024-09-25T04:50:58 received handshake 'Z5'
2024-09-25T04:54:13 (37) created PID file '/data/zeoserver/zeoserver.pid'
2024-09-25T04:54:13 (37) opening storage u'1' using FileStorage
2024-09-25T04:54:14 StorageServer created RW with storages: 1:RW:/data/filestorage/Data.fs
2024-09-25T04:54:14 listening on ('', 8080)
2024-09-25T04:54:21 Connected server protocol
2024-09-25T04:54:21 received handshake 'Z5'
2024-09-25T04:54:21 Connected server protocol
2024-09-25T04:54:21 received handshake 'Z5'
2024-09-25T05:01:22 (:8080) disconnected
2024-09-25T05:01:38 Connected server protocol
2024-09-25T05:01:38 received handshake 'Z5'
2024-09-25T05:05:28 (:8080) disconnected
2024-09-25T05:05:28 (:8080) disconnected
2024-09-25T09:03:25 (36) created PID file '/data/zeoserver/zeoserver.pid'
2024-09-25T09:03:25 (36) opening storage u'1' using FileStorage
2024-09-25T09:03:29 StorageServer created RW with storages: 1:RW:/data/filestorage/Data.fs
2024-09-25T09:03:29 listening on ('', 8080)
2024-09-25T09:03:40 Connected server protocol
2024-09-25T09:03:40 Connected server protocol
2024-09-25T09:03:40 received handshake 'Z5'
2024-09-25T09:03:40 received handshake 'Z5'
2024-09-25T09:10:29 Unexpected error while trying to resolve conflict on <ZODB.ConflictResolution.BadClass object at 0x7f4485b9c710>
Traceback (most recent call last):
  File "/home/senaite/senaitelims/eggs/cp27mu/ZODB-5.8.0-py2.7.egg/ZODB/ConflictResolution.py", line 274, in tryToResolveConflict
    inst = klass.__new__(klass, *newargs)
TypeError: object.__new__(X): X is not a type object (BadClass)
2024-09-25T09:10:29 Bad request, 'vote'
Traceback (most recent call last):
  File "/home/senaite/senaitelims/eggs/cp27mu/ZEO-5.3.0-py2.7.egg/ZEO/asyncio/server.py", line 103, in message_received
    result = getattr(self.zeo_storage, name)(*args)
  File "/home/senaite/senaitelims/eggs/cp27mu/ZEO-5.3.0-py2.7.egg/ZEO/StorageServer.py", line 374, in vote
    return self.lock_manager.lock(self, self._vote)
  File "/home/senaite/senaitelims/eggs/cp27mu/ZEO-5.3.0-py2.7.egg/ZEO/StorageServer.py", line 1168, in lock
    result = func()
  File "/home/senaite/senaitelims/eggs/cp27mu/ZEO-5.3.0-py2.7.egg/ZEO/StorageServer.py", line 395, in _vote
    getattr(self, op)(*args)
  File "/home/senaite/senaitelims/eggs/cp27mu/ZEO-5.3.0-py2.7.egg/ZEO/StorageServer.py", line 529, in _store
    self.storage.store(oid, serial, data, '', self.transaction)
  File "/home/senaite/senaitelims/eggs/cp27mu/ZODB-5.8.0-py2.7.egg/ZODB/FileStorage/FileStorage.py", line 616, in store
    oldserial, data)
  File "/home/senaite/senaitelims/eggs/cp27mu/ZODB-5.8.0-py2.7.egg/ZODB/ConflictResolution.py", line 311, in tryToResolveConflict
    data=newpickle)
ConflictError: database conflict error (oid 0x0b17, class Products.CMFCore.TypesTool.FactoryTypeInformation, serial this txn started with 0x03fb8a267af463aa 2024-09-25 09:10:28.817495, serial currently committed 0x03fb8a267d5f3633 2024-09-25 09:10:29.384044)
2024-09-25T09:10:29 (:8080) no current transaction: tpc_abort()
2024-09-25T09:10:32 Unexpected error while trying to resolve conflict on <ZODB.ConflictResolution.BadClass object at 0x7f4485b9ca90>
Traceback (most recent call last):
  File "/home/senaite/senaitelims/eggs/cp27mu/ZODB-5.8.0-py2.7.egg/ZODB/ConflictResolution.py", line 274, in tryToResolveConflict
    inst = klass.__new__(klass, *newargs)
TypeError: object.__new__(X): X is not a type object (BadClass)
2024-09-25T09:10:32 Bad request, 'vote'
Traceback (most recent call last):
  File "/home/senaite/senaitelims/eggs/cp27mu/ZEO-5.3.0-py2.7.egg/ZEO/asyncio/server.py", line 103, in message_received
    result = getattr(self.zeo_storage, name)(*args)
  File "/home/senaite/senaitelims/eggs/cp27mu/ZEO-5.3.0-py2.7.egg/ZEO/StorageServer.py", line 374, in vote
    return self.lock_manager.lock(self, self._vote)
  File "/home/senaite/senaitelims/eggs/cp27mu/ZEO-5.3.0-py2.7.egg/ZEO/StorageServer.py", line 1168, in lock
    result = func()
  File "/home/senaite/senaitelims/eggs/cp27mu/ZEO-5.3.0-py2.7.egg/ZEO/StorageServer.py", line 395, in _vote
    getattr(self, op)(*args)
  File "/home/senaite/senaitelims/eggs/cp27mu/ZEO-5.3.0-py2.7.egg/ZEO/StorageServer.py", line 529, in _store
    self.storage.store(oid, serial, data, '', self.transaction)
  File "/home/senaite/senaitelims/eggs/cp27mu/ZODB-5.8.0-py2.7.egg/ZODB/FileStorage/FileStorage.py", line 616, in store
    oldserial, data)
  File "/home/senaite/senaitelims/eggs/cp27mu/ZODB-5.8.0-py2.7.egg/ZODB/ConflictResolution.py", line 311, in tryToResolveConflict
    data=newpickle)
ConflictError: database conflict error (oid 0x0b17, class Products.CMFCore.TypesTool.FactoryTypeInformation, serial this txn started with 0x03fb8a267d5f3633 2024-09-25 09:10:29.384044, serial currently committed 0x03fb8a268a0f3411 2024-09-25 09:10:32.357669)
2024-09-25T09:10:32 (:8080) no current transaction: tpc_abort()
2024-09-25T09:10:34 Unexpected error while trying to resolve conflict on <ZODB.ConflictResolution.BadClass object at 0x7f4485b9c810>
Traceback (most recent call last):
  File "/home/senaite/senaitelims/eggs/cp27mu/ZODB-5.8.0-py2.7.egg/ZODB/ConflictResolution.py", line 274, in tryToResolveConflict
    inst = klass.__new__(klass, *newargs)
TypeError: object.__new__(X): X is not a type object (BadClass)
2024-09-25T09:10:34 Bad request, 'vote'
Traceback (most recent call last):
  File "/home/senaite/senaitelims/eggs/cp27mu/ZEO-5.3.0-py2.7.egg/ZEO/asyncio/server.py", line 103, in message_received
    result = getattr(self.zeo_storage, name)(*args)
  File "/home/senaite/senaitelims/eggs/cp27mu/ZEO-5.3.0-py2.7.egg/ZEO/StorageServer.py", line 374, in vote
    return self.lock_manager.lock(self, self._vote)
  File "/home/senaite/senaitelims/eggs/cp27mu/ZEO-5.3.0-py2.7.egg/ZEO/StorageServer.py", line 1168, in lock
    result = func()
  File "/home/senaite/senaitelims/eggs/cp27mu/ZEO-5.3.0-py2.7.egg/ZEO/StorageServer.py", line 395, in _vote
    getattr(self, op)(*args)
  File "/home/senaite/senaitelims/eggs/cp27mu/ZEO-5.3.0-py2.7.egg/ZEO/StorageServer.py", line 529, in _store
    self.storage.store(oid, serial, data, '', self.transaction)
  File "/home/senaite/senaitelims/eggs/cp27mu/ZODB-5.8.0-py2.7.egg/ZODB/FileStorage/FileStorage.py", line 616, in store
    oldserial, data)
  File "/home/senaite/senaitelims/eggs/cp27mu/ZODB-5.8.0-py2.7.egg/ZODB/ConflictResolution.py", line 311, in tryToResolveConflict
    data=newpickle)
ConflictError: database conflict error (oid 0x0b17, class Products.CMFCore.TypesTool.FactoryTypeInformation, serial this txn started with 0x03fb8a268fc4f8bb 2024-09-25 09:10:33.695958, serial currently committed 0x03fb8a2692b04322 2024-09-25 09:10:34.380123)
2024-09-25T09:10:34 (:8080) no current transaction: tpc_abort()
2024-09-25T10:31:50 (36) created PID file '/data/zeoserver/zeoserver.pid'
2024-09-25T10:31:50 (36) opening storage u'1' using FileStorage
2024-09-25T10:31:51 StorageServer created RW with storages: 1:RW:/data/filestorage/Data.fs
2024-09-25T10:31:51 listening on ('', 8080)
2024-09-25T10:31:52 Connected server protocol
2024-09-25T10:31:52 received handshake 'Z5'
2024-09-25T10:31:52 Connected server protocol
2024-09-25T10:31:52 received handshake 'Z5'
2024-09-25T10:49:21 (36) created PID file '/data/zeoserver/zeoserver.pid'
2024-09-25T10:49:21 (36) opening storage u'1' using FileStorage
2024-09-25T10:49:22 Ignoring index for /data/filestorage/Data.fs
2024-09-25T10:49:22 StorageServer created RW with storages: 1:RW:/data/filestorage/Data.fs
2024-09-25T10:49:22 listening on ('', 8080)
2024-09-25T10:49:29 Connected server protocol
2024-09-25T10:49:29 received handshake 'Z5'
2024-09-25T10:49:29 Connected server protocol
2024-09-25T10:49:29 received handshake 'Z5'
2024-09-25T10:53:08 (37) created PID file '/data/zeoserver/zeoserver.pid'
2024-09-25T10:53:08 (37) opening storage u'1' using FileStorage
2024-09-25T10:53:08 Ignoring index for /data/filestorage/Data.fs
2024-09-25T10:53:09 StorageServer created RW with storages: 1:RW:/data/filestorage/Data.fs
2024-09-25T10:53:09 listening on ('', 8080)
2024-09-25T10:53:10 Connected server protocol
2024-09-25T10:53:10 received handshake 'Z5'
2024-09-25T10:53:10 (:8080) disconnected
2024-09-25T10:53:11 Connected server protocol
2024-09-25T10:53:11 received handshake 'Z5'
2024-09-25T10:53:11 (:8080) disconnected
2024-09-25T10:53:24 Connected server protocol
2024-09-25T10:53:24 received handshake 'Z5'
2024-09-25T10:53:24 Connected server protocol
2024-09-25T10:53:24 received handshake 'Z5'
2024-09-25T11:00:10 (36) created PID file '/data/zeoserver/zeoserver.pid'
2024-09-25T11:00:10 (36) opening storage u'1' using FileStorage
2024-09-25T11:00:10 Ignoring index for /data/filestorage/Data.fs
2024-09-25T11:00:10 StorageServer created RW with storages: 1:RW:/data/filestorage/Data.fs
2024-09-25T11:00:10 listening on ('', 8080)
2024-09-25T11:00:11 Connected server protocol
2024-09-25T11:00:11 received handshake 'Z5'
2024-09-25T11:00:11 (:8080) disconnected
2024-09-25T11:00:11 Connected server protocol
2024-09-25T11:00:11 received handshake 'Z5'
2024-09-25T11:00:11 (:8080) disconnected
2024-09-25T11:00:22 Connected server protocol
2024-09-25T11:00:22 received handshake 'Z5'
2024-09-25T11:00:22 Connected server protocol
2024-09-25T11:00:22 received handshake 'Z5'
2024-09-25T11:05:38 (37) created PID file '/data/zeoserver/zeoserver.pid'
2024-09-25T11:05:38 (37) opening storage u'1' using FileStorage
2024-09-25T11:05:38 Ignoring index for /data/filestorage/Data.fs
2024-09-25T11:06:31 StorageServer created RW with storages: 1:RW:/data/filestorage/Data.fs
2024-09-25T11:06:32 listening on ('', 8080)
2024-09-25T11:06:47 Connected server protocol
2024-09-25T11:06:47 received handshake 'Z5'
2024-09-25T11:06:50 Connected server protocol
2024-09-25T11:06:50 received handshake 'Z5'
2024-09-25T11:37:27 Unexpected error while trying to resolve conflict on <type 'BTrees.OIBTree.OIBucket'>
Traceback (most recent call last):
  File "/home/senaite/senaitelims/eggs/cp27mu/ZODB-5.8.0-py2.7.egg/ZODB/ConflictResolution.py", line 286, in tryToResolveConflict
    newstate = unpickler.load()
UnpicklingError: NEWOBJ class argument isn't a type object
2024-09-25T11:37:27 Bad request, 'vote'
Traceback (most recent call last):
  File "/home/senaite/senaitelims/eggs/cp27mu/ZEO-5.3.0-py2.7.egg/ZEO/asyncio/server.py", line 103, in message_received
    result = getattr(self.zeo_storage, name)(*args)
  File "/home/senaite/senaitelims/eggs/cp27mu/ZEO-5.3.0-py2.7.egg/ZEO/StorageServer.py", line 374, in vote
    return self.lock_manager.lock(self, self._vote)
  File "/home/senaite/senaitelims/eggs/cp27mu/ZEO-5.3.0-py2.7.egg/ZEO/StorageServer.py", line 1168, in lock
    result = func()
  File "/home/senaite/senaitelims/eggs/cp27mu/ZEO-5.3.0-py2.7.egg/ZEO/StorageServer.py", line 395, in _vote
    getattr(self, op)(*args)
  File "/home/senaite/senaitelims/eggs/cp27mu/ZEO-5.3.0-py2.7.egg/ZEO/StorageServer.py", line 529, in _store
    self.storage.store(oid, serial, data, '', self.transaction)
  File "/home/senaite/senaitelims/eggs/cp27mu/ZODB-5.8.0-py2.7.egg/ZODB/FileStorage/FileStorage.py", line 616, in store
    oldserial, data)
  File "/home/senaite/senaitelims/eggs/cp27mu/ZODB-5.8.0-py2.7.egg/ZODB/ConflictResolution.py", line 311, in tryToResolveConflict
    data=newpickle)
ConflictError: database conflict error (oid 0x012cce0d, class BTrees.OIBTree.OIBucket, serial this txn started with 0x03fb8ab96b8f2099 2024-09-25 11:37:25.209162, serial currently committed 0x03fb8ab973aa5f33 2024-09-25 11:37:27.109105)
2024-09-25T11:37:27 (:8080) no current transaction: tpc_abort()
2024-09-26T04:06:10 Unexpected error while trying to resolve conflict on <ZODB.ConflictResolution.BadClass object at 0x7fe0a8a30b90>
Traceback (most recent call last):
  File "/home/senaite/senaitelims/eggs/cp27mu/ZODB-5.8.0-py2.7.egg/ZODB/ConflictResolution.py", line 274, in tryToResolveConflict
    inst = klass.__new__(klass, *newargs)
TypeError: object.__new__(X): X is not a type object (BadClass)
2024-09-26T04:06:10 Bad request, 'vote'
Traceback (most recent call last):
  File "/home/senaite/senaitelims/eggs/cp27mu/ZEO-5.3.0-py2.7.egg/ZEO/asyncio/server.py", line 103, in message_received
    result = getattr(self.zeo_storage, name)(*args)
  File "/home/senaite/senaitelims/eggs/cp27mu/ZEO-5.3.0-py2.7.egg/ZEO/StorageServer.py", line 374, in vote
    return self.lock_manager.lock(self, self._vote)
  File "/home/senaite/senaitelims/eggs/cp27mu/ZEO-5.3.0-py2.7.egg/ZEO/StorageServer.py", line 1168, in lock
    result = func()
  File "/home/senaite/senaitelims/eggs/cp27mu/ZEO-5.3.0-py2.7.egg/ZEO/StorageServer.py", line 395, in _vote
    getattr(self, op)(*args)
  File "/home/senaite/senaitelims/eggs/cp27mu/ZEO-5.3.0-py2.7.egg/ZEO/StorageServer.py", line 529, in _store
    self.storage.store(oid, serial, data, '', self.transaction)
  File "/home/senaite/senaitelims/eggs/cp27mu/ZODB-5.8.0-py2.7.egg/ZODB/FileStorage/FileStorage.py", line 616, in store
    oldserial, data)
  File "/home/senaite/senaitelims/eggs/cp27mu/ZODB-5.8.0-py2.7.egg/ZODB/ConflictResolution.py", line 311, in tryToResolveConflict
    data=newpickle)
ConflictError: database conflict error (oid 0x2222, class senaite.core.catalog.client_catalog.ClientCatalog, serial this txn started with 0x03fb8ab538ce53bb 2024-09-25 11:33:13.313898, serial currently committed 0x03fb8e95eed3d666 2024-09-26 04:05:55.975193)
2024-09-26T04:06:10 (:8080) no current transaction: tpc_abort()
2024-09-26T04:06:29 Unexpected error while trying to resolve conflict on <ZODB.ConflictResolution.BadClass object at 0x7fe0a8a30690>
Traceback (most recent call last):
  File "/home/senaite/senaitelims/eggs/cp27mu/ZODB-5.8.0-py2.7.egg/ZODB/ConflictResolution.py", line 274, in tryToResolveConflict
    inst = klass.__new__(klass, *newargs)
TypeError: object.__new__(X): X is not a type object (BadClass)
2024-09-26T04:06:29 Bad request, 'vote'
Traceback (most recent call last):
  File "/home/senaite/senaitelims/eggs/cp27mu/ZEO-5.3.0-py2.7.egg/ZEO/asyncio/server.py", line 103, in message_received
    result = getattr(self.zeo_storage, name)(*args)
  File "/home/senaite/senaitelims/eggs/cp27mu/ZEO-5.3.0-py2.7.egg/ZEO/StorageServer.py", line 374, in vote
    return self.lock_manager.lock(self, self._vote)
  File "/home/senaite/senaitelims/eggs/cp27mu/ZEO-5.3.0-py2.7.egg/ZEO/StorageServer.py", line 1168, in lock
    result = func()
  File "/home/senaite/senaitelims/eggs/cp27mu/ZEO-5.3.0-py2.7.egg/ZEO/StorageServer.py", line 395, in _vote
    getattr(self, op)(*args)
  File "/home/senaite/senaitelims/eggs/cp27mu/ZEO-5.3.0-py2.7.egg/ZEO/StorageServer.py", line 529, in _store
    self.storage.store(oid, serial, data, '', self.transaction)
  File "/home/senaite/senaitelims/eggs/cp27mu/ZODB-5.8.0-py2.7.egg/ZODB/FileStorage/FileStorage.py", line 616, in store
    oldserial, data)
  File "/home/senaite/senaitelims/eggs/cp27mu/ZODB-5.8.0-py2.7.egg/ZODB/ConflictResolution.py", line 311, in tryToResolveConflict
    data=newpickle)
ConflictError: database conflict error (oid 0x2222, class senaite.core.catalog.client_catalog.ClientCatalog, serial this txn started with 0x03fb8ab538ce53bb 2024-09-25 11:33:13.313898, serial currently committed 0x03fb8e95eed3d666 2024-09-26 04:05:55.975193)
2024-09-26T04:06:29 (:8080) no current transaction: tpc_abort()
2024-09-26T04:06:59 Unexpected error while trying to resolve conflict on <ZODB.ConflictResolution.BadClass object at 0x7fe0a8a30450>
Traceback (most recent call last):
  File "/home/senaite/senaitelims/eggs/cp27mu/ZODB-5.8.0-py2.7.egg/ZODB/ConflictResolution.py", line 274, in tryToResolveConflict
    inst = klass.__new__(klass, *newargs)
TypeError: object.__new__(X): X is not a type object (BadClass)
2024-09-26T04:06:59 Bad request, 'vote'
Traceback (most recent call last):
  File "/home/senaite/senaitelims/eggs/cp27mu/ZEO-5.3.0-py2.7.egg/ZEO/asyncio/server.py", line 103, in message_received
    result = getattr(self.zeo_storage, name)(*args)
  File "/home/senaite/senaitelims/eggs/cp27mu/ZEO-5.3.0-py2.7.egg/ZEO/StorageServer.py", line 374, in vote
    return self.lock_manager.lock(self, self._vote)
  File "/home/senaite/senaitelims/eggs/cp27mu/ZEO-5.3.0-py2.7.egg/ZEO/StorageServer.py", line 1168, in lock
    result = func()
  File "/home/senaite/senaitelims/eggs/cp27mu/ZEO-5.3.0-py2.7.egg/ZEO/StorageServer.py", line 395, in _vote
    getattr(self, op)(*args)
  File "/home/senaite/senaitelims/eggs/cp27mu/ZEO-5.3.0-py2.7.egg/ZEO/StorageServer.py", line 529, in _store
    self.storage.store(oid, serial, data, '', self.transaction)
  File "/home/senaite/senaitelims/eggs/cp27mu/ZODB-5.8.0-py2.7.egg/ZODB/FileStorage/FileStorage.py", line 616, in store
    oldserial, data)
  File "/home/senaite/senaitelims/eggs/cp27mu/ZODB-5.8.0-py2.7.egg/ZODB/ConflictResolution.py", line 311, in tryToResolveConflict
    data=newpickle)
ConflictError: database conflict error (oid 0x2222, class senaite.core.catalog.client_catalog.ClientCatalog, serial this txn started with 0x03fb8ab538ce53bb 2024-09-25 11:33:13.313898, serial currently committed 0x03fb8e95eed3d666 2024-09-26 04:05:55.975193)
2024-09-26T04:06:59 (:8080) no current transaction: tpc_abort()
2024-09-26T04:20:24 Unexpected error while trying to resolve conflict on <ZODB.ConflictResolution.BadClass object at 0x7fe0a8a30450>
Traceback (most recent call last):
  File "/home/senaite/senaitelims/eggs/cp27mu/ZODB-5.8.0-py2.7.egg/ZODB/ConflictResolution.py", line 274, in tryToResolveConflict
    inst = klass.__new__(klass, *newargs)
TypeError: object.__new__(X): X is not a type object (BadClass)
2024-09-26T04:20:24 Bad request, 'vote'
Traceback (most recent call last):
  File "/home/senaite/senaitelims/eggs/cp27mu/ZEO-5.3.0-py2.7.egg/ZEO/asyncio/server.py", line 103, in message_received
    result = getattr(self.zeo_storage, name)(*args)
  File "/home/senaite/senaitelims/eggs/cp27mu/ZEO-5.3.0-py2.7.egg/ZEO/StorageServer.py", line 374, in vote
    return self.lock_manager.lock(self, self._vote)
  File "/home/senaite/senaitelims/eggs/cp27mu/ZEO-5.3.0-py2.7.egg/ZEO/StorageServer.py", line 1168, in lock
    result = func()
  File "/home/senaite/senaitelims/eggs/cp27mu/ZEO-5.3.0-py2.7.egg/ZEO/StorageServer.py", line 395, in _vote
    getattr(self, op)(*args)
  File "/home/senaite/senaitelims/eggs/cp27mu/ZEO-5.3.0-py2.7.egg/ZEO/StorageServer.py", line 529, in _store
    self.storage.store(oid, serial, data, '', self.transaction)
  File "/home/senaite/senaitelims/eggs/cp27mu/ZODB-5.8.0-py2.7.egg/ZODB/FileStorage/FileStorage.py", line 616, in store
    oldserial, data)
  File "/home/senaite/senaitelims/eggs/cp27mu/ZODB-5.8.0-py2.7.egg/ZODB/ConflictResolution.py", line 311, in tryToResolveConflict
    data=newpickle)
ConflictError: database conflict error (oid 0x2222, class senaite.core.catalog.client_catalog.ClientCatalog, serial this txn started with 0x03fb8e95eed3d666 2024-09-26 04:05:55.975193, serial currently committed 0x03fb8ea449879a44 2024-09-26 04:20:17.233523)
2024-09-26T04:20:24 (:8080) no current transaction: tpc_abort()
2024-09-26T04:20:38 Unexpected error while trying to resolve conflict on <ZODB.ConflictResolution.BadClass object at 0x7fe0a8a30610>
Traceback (most recent call last):
  File "/home/senaite/senaitelims/eggs/cp27mu/ZODB-5.8.0-py2.7.egg/ZODB/ConflictResolution.py", line 274, in tryToResolveConflict
    inst = klass.__new__(klass, *newargs)
TypeError: object.__new__(X): X is not a type object (BadClass)
2024-09-26T04:20:38 Bad request, 'vote'
Traceback (most recent call last):
  File "/home/senaite/senaitelims/eggs/cp27mu/ZEO-5.3.0-py2.7.egg/ZEO/asyncio/server.py", line 103, in message_received
    result = getattr(self.zeo_storage, name)(*args)
  File "/home/senaite/senaitelims/eggs/cp27mu/ZEO-5.3.0-py2.7.egg/ZEO/StorageServer.py", line 374, in vote
    return self.lock_manager.lock(self, self._vote)
  File "/home/senaite/senaitelims/eggs/cp27mu/ZEO-5.3.0-py2.7.egg/ZEO/StorageServer.py", line 1168, in lock
    result = func()
  File "/home/senaite/senaitelims/eggs/cp27mu/ZEO-5.3.0-py2.7.egg/ZEO/StorageServer.py", line 395, in _vote
    getattr(self, op)(*args)
  File "/home/senaite/senaitelims/eggs/cp27mu/ZEO-5.3.0-py2.7.egg/ZEO/StorageServer.py", line 529, in _store
    self.storage.store(oid, serial, data, '', self.transaction)
  File "/home/senaite/senaitelims/eggs/cp27mu/ZODB-5.8.0-py2.7.egg/ZODB/FileStorage/FileStorage.py", line 616, in store
    oldserial, data)
  File "/home/senaite/senaitelims/eggs/cp27mu/ZODB-5.8.0-py2.7.egg/ZODB/ConflictResolution.py", line 311, in tryToResolveConflict
    data=newpickle)
ConflictError: database conflict error (oid 0x2222, class senaite.core.catalog.client_catalog.ClientCatalog, serial this txn started with 0x03fb8e95eed3d666 2024-09-26 04:05:55.975193, serial currently committed 0x03fb8ea449879a44 2024-09-26 04:20:17.233523)
2024-09-26T04:20:38 (:8080) no current transaction: tpc_abort()
2024-09-26T04:30:30 Unexpected error while trying to resolve conflict on <ZODB.ConflictResolution.BadClass object at 0x7fe0a8a30610>
Traceback (most recent call last):
  File "/home/senaite/senaitelims/eggs/cp27mu/ZODB-5.8.0-py2.7.egg/ZODB/ConflictResolution.py", line 274, in tryToResolveConflict
    inst = klass.__new__(klass, *newargs)
TypeError: object.__new__(X): X is not a type object (BadClass)
2024-09-26T04:30:30 Bad request, 'vote'
Traceback (most recent call last):
  File "/home/senaite/senaitelims/eggs/cp27mu/ZEO-5.3.0-py2.7.egg/ZEO/asyncio/server.py", line 103, in message_received
    result = getattr(self.zeo_storage, name)(*args)
  File "/home/senaite/senaitelims/eggs/cp27mu/ZEO-5.3.0-py2.7.egg/ZEO/StorageServer.py", line 374, in vote
    return self.lock_manager.lock(self, self._vote)
  File "/home/senaite/senaitelims/eggs/cp27mu/ZEO-5.3.0-py2.7.egg/ZEO/StorageServer.py", line 1168, in lock
    result = func()
  File "/home/senaite/senaitelims/eggs/cp27mu/ZEO-5.3.0-py2.7.egg/ZEO/StorageServer.py", line 395, in _vote
    getattr(self, op)(*args)
  File "/home/senaite/senaitelims/eggs/cp27mu/ZEO-5.3.0-py2.7.egg/ZEO/StorageServer.py", line 529, in _store
    self.storage.store(oid, serial, data, '', self.transaction)
  File "/home/senaite/senaitelims/eggs/cp27mu/ZODB-5.8.0-py2.7.egg/ZODB/FileStorage/FileStorage.py", line 616, in store
    oldserial, data)
  File "/home/senaite/senaitelims/eggs/cp27mu/ZODB-5.8.0-py2.7.egg/ZODB/ConflictResolution.py", line 311, in tryToResolveConflict
    data=newpickle)
ConflictError: database conflict error (oid 0x2222, class senaite.core.catalog.client_catalog.ClientCatalog, serial this txn started with 0x03fb8ea449879a44 2024-09-26 04:20:17.233523, serial currently committed 0x03fb8eae5cea3544 2024-09-26 04:30:21.776924)
2024-09-26T04:30:30 (:8080) no current transaction: tpc_abort()
2024-09-26T07:49:16 (:8080) disconnected
2024-09-26T08:13:18 Connected server protocol
2024-09-26T08:13:18 received handshake 'Z5'
2024-09-26T10:32:21 (36) created PID file '/data/zeoserver/zeoserver.pid'
2024-09-26T10:32:21 (36) opening storage u'1' using FileStorage
2024-09-26T10:32:29 StorageServer created RW with storages: 1:RW:/data/filestorage/Data.fs
2024-09-26T10:32:31 listening on ('', 8080)
2024-09-26T10:32:38 Connected server protocol
2024-09-26T10:32:38 received handshake 'Z5'
2024-09-26T10:32:40 Connected server protocol
2024-09-26T10:32:40 received handshake 'Z5'
2024-09-26T11:08:05 Unexpected error while trying to resolve conflict on <ZODB.ConflictResolution.BadClass object at 0x7f3edf8d1610>
Traceback (most recent call last):
  File "/home/senaite/senaitelims/eggs/cp27mu/ZODB-5.8.0-py2.7.egg/ZODB/ConflictResolution.py", line 274, in tryToResolveConflict
    inst = klass.__new__(klass, *newargs)
TypeError: object.__new__(X): X is not a type object (BadClass)
2024-09-26T11:08:05 Bad request, 'vote'
Traceback (most recent call last):
  File "/home/senaite/senaitelims/eggs/cp27mu/ZEO-5.3.0-py2.7.egg/ZEO/asyncio/server.py", line 103, in message_received
    result = getattr(self.zeo_storage, name)(*args)
  File "/home/senaite/senaitelims/eggs/cp27mu/ZEO-5.3.0-py2.7.egg/ZEO/StorageServer.py", line 374, in vote
    return self.lock_manager.lock(self, self._vote)
  File "/home/senaite/senaitelims/eggs/cp27mu/ZEO-5.3.0-py2.7.egg/ZEO/StorageServer.py", line 1168, in lock
    result = func()
  File "/home/senaite/senaitelims/eggs/cp27mu/ZEO-5.3.0-py2.7.egg/ZEO/StorageServer.py", line 395, in _vote
    getattr(self, op)(*args)
  File "/home/senaite/senaitelims/eggs/cp27mu/ZEO-5.3.0-py2.7.egg/ZEO/StorageServer.py", line 529, in _store
    self.storage.store(oid, serial, data, '', self.transaction)
  File "/home/senaite/senaitelims/eggs/cp27mu/ZODB-5.8.0-py2.7.egg/ZODB/FileStorage/FileStorage.py", line 616, in store
    oldserial, data)
  File "/home/senaite/senaitelims/eggs/cp27mu/ZODB-5.8.0-py2.7.egg/ZODB/ConflictResolution.py", line 311, in tryToResolveConflict
    data=newpickle)
ConflictError: database conflict error (oid 0x2223, class senaite.core.catalog.sample_catalog.SampleCatalog, serial this txn started with 0x03f9df4812f9d033 2024-07-11 11:52:04.447461, serial currently committed 0x03fb903a6a3e21aa 2024-09-26 11:06:24.900633)
2024-09-26T11:08:07 (:8080) no current transaction: tpc_abort()
2024-09-26T11:11:01 (:8080) disconnected
2024-09-26T11:11:02 (:8080) disconnected
2024-09-26T11:11:53 (37) created PID file '/data/zeoserver/zeoserver.pid'
2024-09-26T11:11:53 (37) opening storage u'1' using FileStorage
2024-09-26T11:12:03 StorageServer created RW with storages: 1:RW:/data/filestorage/Data.fs
2024-09-26T11:12:09 listening on ('', 8080)
2024-09-26T11:12:20 Connected server protocol
2024-09-26T11:12:20 received handshake 'Z5'
2024-09-26T11:12:20 Connected server protocol
2024-09-26T11:12:20 received handshake 'Z5'
2024-09-26T11:26:33 (:8080) disconnected
2024-09-26T11:26:33 (:8080) disconnected
2024-09-26T11:27:20 (35) created PID file '/data/zeoserver/zeoserver.pid'
2024-09-26T11:27:20 (35) opening storage u'1' using FileStorage
2024-09-26T11:27:20 Ignoring index for /data/filestorage/Data.fs
2024-09-26T11:27:20 (35) Blob directory /data/blobstorage does not exist. Selected `bushy` layout. 
2024-09-26T11:27:20 (35) Blob directory '/data/blobstorage/' does not exist. Created new directory.
2024-09-26T11:27:20 (35) Blob temporary directory '/data/blobstorage/tmp' does not exist. Created new directory.
2024-09-26T11:27:20 StorageServer created RW with storages: 1:RW:/data/filestorage/Data.fs
2024-09-26T11:27:20 listening on ('', 8080)
2024-09-26T11:27:30 Connected server protocol
2024-09-26T11:27:30 received handshake 'Z5'
2024-09-26T11:27:30 Connected server protocol
2024-09-26T11:27:30 received handshake 'Z5'
2024-09-26T11:27:45 Unexpected error while trying to resolve conflict on <ZODB.ConflictResolution.BadClass object at 0x7f4f6439d250>
Traceback (most recent call last):
  File "/home/senaite/senaitelims/eggs/cp27mu/ZODB-5.8.0-py2.7.egg/ZODB/ConflictResolution.py", line 274, in tryToResolveConflict
    inst = klass.__new__(klass, *newargs)
TypeError: object.__new__(X): X is not a type object (BadClass)
2024-09-26T11:27:45 Bad request, 'vote'
Traceback (most recent call last):
  File "/home/senaite/senaitelims/eggs/cp27mu/ZEO-5.3.0-py2.7.egg/ZEO/asyncio/server.py", line 103, in message_received
    result = getattr(self.zeo_storage, name)(*args)
  File "/home/senaite/senaitelims/eggs/cp27mu/ZEO-5.3.0-py2.7.egg/ZEO/StorageServer.py", line 374, in vote
    return self.lock_manager.lock(self, self._vote)
  File "/home/senaite/senaitelims/eggs/cp27mu/ZEO-5.3.0-py2.7.egg/ZEO/StorageServer.py", line 1168, in lock
    result = func()
  File "/home/senaite/senaitelims/eggs/cp27mu/ZEO-5.3.0-py2.7.egg/ZEO/StorageServer.py", line 395, in _vote
    getattr(self, op)(*args)
  File "/home/senaite/senaitelims/eggs/cp27mu/ZEO-5.3.0-py2.7.egg/ZEO/StorageServer.py", line 529, in _store
    self.storage.store(oid, serial, data, '', self.transaction)
  File "/home/senaite/senaitelims/eggs/cp27mu/ZODB-5.8.0-py2.7.egg/ZODB/FileStorage/FileStorage.py", line 616, in store
    oldserial, data)
  File "/home/senaite/senaitelims/eggs/cp27mu/ZODB-5.8.0-py2.7.egg/ZODB/ConflictResolution.py", line 311, in tryToResolveConflict
    data=newpickle)
ConflictError: database conflict error (oid 0x01, class OFS.Application.Application, serial this txn started with 0x03fb904fc0f23e77 2024-09-26 11:27:45.221781, serial currently committed 0x03fb904fc1002b99 2024-09-26 11:27:45.234531)
2024-09-26T11:27:45 (:8080) no current transaction: tpc_abort()
2024-09-26T11:27:47 (:8080) disconnected
2024-09-26T11:30:26 Connected server protocol
2024-09-26T11:30:26 received handshake 'Z5'
2024-09-26T12:19:17 (:8080) disconnected
2024-09-27T04:39:57 (37) created PID file '/data/zeoserver/zeoserver.pid'
2024-09-27T04:39:57 (37) opening storage u'1' using FileStorage
2024-09-27T04:39:58 Ignoring index for /data/filestorage/Data.fs
2024-09-27T04:39:59 StorageServer created RW with storages: 1:RW:/data/filestorage/Data.fs
2024-09-27T04:39:59 listening on ('', 8080)
2024-09-27T04:40:10 Connected server protocol
2024-09-27T04:40:10 received handshake 'Z5'
2024-09-27T04:40:14 Connected server protocol
2024-09-27T04:40:14 received handshake 'Z5'
2024-09-27T08:05:35 (37) created PID file '/data/zeoserver/zeoserver.pid'
2024-09-27T08:05:35 (37) opening storage u'1' using FileStorage
2024-09-27T08:05:35 Ignoring index for /data/filestorage/Data.fs
2024-09-27T08:06:08 StorageServer created RW with storages: 1:RW:/data/filestorage/Data.fs
2024-09-27T08:06:09 listening on ('', 8080)
2024-09-27T08:06:10 Connected server protocol
2024-09-27T08:06:10 received handshake 'Z5'
2024-09-27T08:06:11 Connected server protocol
2024-09-27T08:06:11 received handshake 'Z5'
2024-09-27T10:00:10 Bad request, 'vote'
Traceback (most recent call last):
  File "/home/senaite/senaitelims/eggs/cp27mu/ZEO-5.3.0-py2.7.egg/ZEO/asyncio/server.py", line 103, in message_received
    result = getattr(self.zeo_storage, name)(*args)
  File "/home/senaite/senaitelims/eggs/cp27mu/ZEO-5.3.0-py2.7.egg/ZEO/StorageServer.py", line 374, in vote
    return self.lock_manager.lock(self, self._vote)
  File "/home/senaite/senaitelims/eggs/cp27mu/ZEO-5.3.0-py2.7.egg/ZEO/StorageServer.py", line 1168, in lock
    result = func()
  File "/home/senaite/senaitelims/eggs/cp27mu/ZEO-5.3.0-py2.7.egg/ZEO/StorageServer.py", line 395, in _vote
    getattr(self, op)(*args)
  File "/home/senaite/senaitelims/eggs/cp27mu/ZEO-5.3.0-py2.7.egg/ZEO/StorageServer.py", line 529, in _store
    self.storage.store(oid, serial, data, '', self.transaction)
  File "/home/senaite/senaitelims/eggs/cp27mu/ZODB-5.8.0-py2.7.egg/ZODB/FileStorage/FileStorage.py", line 616, in store
    oldserial, data)
  File "/home/senaite/senaitelims/eggs/cp27mu/ZODB-5.8.0-py2.7.egg/ZODB/ConflictResolution.py", line 311, in tryToResolveConflict
    data=newpickle)
ConflictError: database conflict error (oid 0x01413cf4, class BTrees.OOBTree.OOBTree, serial this txn started with 0x03fb90067c676377 2024-09-26 10:14:29.157155, serial currently committed 0x03fb959826eb6922 2024-09-27 10:00:09.121775)
2024-09-27T10:00:11 (:8080) no current transaction: tpc_abort()
2024-09-27T10:15:00 Bad request, 'vote'
Traceback (most recent call last):
  File "/home/senaite/senaitelims/eggs/cp27mu/ZEO-5.3.0-py2.7.egg/ZEO/asyncio/server.py", line 103, in message_received
    result = getattr(self.zeo_storage, name)(*args)
  File "/home/senaite/senaitelims/eggs/cp27mu/ZEO-5.3.0-py2.7.egg/ZEO/StorageServer.py", line 374, in vote
    return self.lock_manager.lock(self, self._vote)
  File "/home/senaite/senaitelims/eggs/cp27mu/ZEO-5.3.0-py2.7.egg/ZEO/StorageServer.py", line 1168, in lock
    result = func()
  File "/home/senaite/senaitelims/eggs/cp27mu/ZEO-5.3.0-py2.7.egg/ZEO/StorageServer.py", line 395, in _vote
    getattr(self, op)(*args)
  File "/home/senaite/senaitelims/eggs/cp27mu/ZEO-5.3.0-py2.7.egg/ZEO/StorageServer.py", line 529, in _store
    self.storage.store(oid, serial, data, '', self.transaction)
  File "/home/senaite/senaitelims/eggs/cp27mu/ZODB-5.8.0-py2.7.egg/ZODB/FileStorage/FileStorage.py", line 616, in store
    oldserial, data)
  File "/home/senaite/senaitelims/eggs/cp27mu/ZODB-5.8.0-py2.7.egg/ZODB/ConflictResolution.py", line 311, in tryToResolveConflict
    data=newpickle)
ConflictError: database conflict error (oid 0x01413cf4, class BTrees.OOBTree.OOBTree, serial this txn started with 0x03fb90067c676377 2024-09-26 10:14:29.157155, serial currently committed 0x03fb959826eb6922 2024-09-27 10:00:09.121775)
2024-09-27T10:15:00 (:8080) no current transaction: tpc_abort()
2024-09-27T10:20:58 (:8080) disconnected
2024-10-02T09:30:27 (54) created PID file '/data/zeoserver/zeoserver.pid'
2024-10-02T09:30:27 (54) opening storage u'1' using FileStorage
2024-10-02T09:30:28 StorageServer created RW with storages: 1:RW:/data/filestorage/Data.fs
2024-10-02T09:30:29 listening on ('', 8080)
2024-10-02T09:30:33 Connected server protocol
2024-10-02T09:30:33 Connected server protocol
2024-10-02T09:30:33 received handshake 'Z5'
2024-10-02T09:30:33 received handshake 'Z5'
2024-10-02T09:41:51 Unexpected error while trying to resolve conflict on <type 'BTrees.OIBTree.OIBucket'>
Traceback (most recent call last):
  File "/home/senaite/senaitelims/eggs/cp27mu/ZODB-5.8.0-py2.7.egg/ZODB/ConflictResolution.py", line 286, in tryToResolveConflict
    newstate = unpickler.load()
UnpicklingError: NEWOBJ class argument isn't a type object
2024-10-02T09:41:51 Bad request, 'vote'
Traceback (most recent call last):
  File "/home/senaite/senaitelims/eggs/cp27mu/ZEO-5.3.0-py2.7.egg/ZEO/asyncio/server.py", line 103, in message_received
    result = getattr(self.zeo_storage, name)(*args)
  File "/home/senaite/senaitelims/eggs/cp27mu/ZEO-5.3.0-py2.7.egg/ZEO/StorageServer.py", line 374, in vote
    return self.lock_manager.lock(self, self._vote)
  File "/home/senaite/senaitelims/eggs/cp27mu/ZEO-5.3.0-py2.7.egg/ZEO/StorageServer.py", line 1168, in lock
    result = func()
  File "/home/senaite/senaitelims/eggs/cp27mu/ZEO-5.3.0-py2.7.egg/ZEO/StorageServer.py", line 395, in _vote
    getattr(self, op)(*args)
  File "/home/senaite/senaitelims/eggs/cp27mu/ZEO-5.3.0-py2.7.egg/ZEO/StorageServer.py", line 529, in _store
    self.storage.store(oid, serial, data, '', self.transaction)
  File "/home/senaite/senaitelims/eggs/cp27mu/ZODB-5.8.0-py2.7.egg/ZODB/FileStorage/FileStorage.py", line 616, in store
    oldserial, data)
  File "/home/senaite/senaitelims/eggs/cp27mu/ZODB-5.8.0-py2.7.egg/ZODB/ConflictResolution.py", line 311, in tryToResolveConflict
    data=newpickle)
ConflictError: database conflict error (oid 0x01306015, class BTrees.OIBTree.OIBucket, serial this txn started with 0x03fbb745d8f3d822 2024-10-02 09:41:50.848246, serial currently committed 0x03fbb745dbc8d577 2024-10-02 09:41:51.511994)
2024-10-02T09:41:51 (:8080) no current transaction: tpc_abort()
2024-10-02T10:01:05 (53) created PID file '/data/zeoserver/zeoserver.pid'
2024-10-02T10:01:05 (53) opening storage u'1' using FileStorage
2024-10-02T10:01:05 StorageServer created RW with storages: 1:RW:/data/filestorage/Data.fs
2024-10-02T10:01:07 listening on ('', 8080)
2024-10-02T10:01:08 Connected server protocol
2024-10-02T10:01:08 received handshake 'Z5'
2024-10-02T10:01:08 Connected server protocol
2024-10-02T10:01:08 received handshake 'Z5'
2024-10-02T10:01:12 (:8080) disconnected
2024-10-02T10:01:12 (:8080) disconnected
2024-10-02T10:01:22 Connected server protocol
2024-10-02T10:01:22 received handshake 'Z5'
2024-10-02T10:01:22 Connected server protocol
2024-10-02T10:01:22 received handshake 'Z5'
2024-10-02T10:06:36 (:8080) disconnected
2024-10-02T10:06:44 Connected server protocol
2024-10-02T10:06:44 received handshake 'Z5'
2024-10-02T10:21:15 (:8080) disconnected
2024-10-02T10:21:24 Connected server protocol
2024-10-02T10:21:24 received handshake 'Z5'
2024-10-02T10:34:35 (:8080) disconnected
2024-10-02T10:34:43 Connected server protocol
2024-10-02T10:34:43 received handshake 'Z5'
2024-10-02T11:16:47 (:8080) disconnected
2024-10-02T11:16:56 Connected server protocol
2024-10-02T11:16:56 received handshake 'Z5'
2024-10-02T11:19:51 (:8080) disconnected
2024-10-02T11:20:00 Connected server protocol
2024-10-02T11:20:00 received handshake 'Z5'
2024-10-02T11:21:42 (54) created PID file '/data/zeoserver/zeoserver.pid'
2024-10-02T11:21:42 (54) opening storage u'1' using FileStorage
2024-10-02T11:21:43 StorageServer created RW with storages: 1:RW:/data/filestorage/Data.fs
2024-10-02T11:21:45 listening on ('', 8080)
2024-10-02T11:21:51 Connected server protocol
2024-10-02T11:21:51 Connected server protocol
2024-10-02T11:21:51 received handshake 'Z5'
2024-10-02T11:21:51 received handshake 'Z5'
2024-10-02T11:22:50 (:8080) disconnected
2024-10-02T11:22:58 Connected server protocol
2024-10-02T11:22:58 received handshake 'Z5'
2024-10-02T11:26:59 (:8080) disconnected
2024-10-02T11:27:07 Connected server protocol
2024-10-02T11:27:07 received handshake 'Z5'
2024-10-02T11:36:20 (:8080) disconnected
2024-10-02T11:36:28 Connected server protocol
2024-10-02T11:36:28 received handshake 'Z5'
2024-10-02T11:39:28 (:8080) disconnected
2024-10-02T11:39:35 Connected server protocol
2024-10-02T11:39:35 received handshake 'Z5'
2024-10-02T11:44:09 (:8080) disconnected
2024-10-02T11:44:17 Connected server protocol
2024-10-02T11:44:17 received handshake 'Z5'
2024-10-02T11:45:27 (:8080) disconnected
2024-10-02T11:45:35 Connected server protocol
2024-10-02T11:45:35 received handshake 'Z5'
2024-10-02T11:46:02 (:8080) disconnected
2024-10-02T11:46:12 Connected server protocol
2024-10-02T11:46:12 received handshake 'Z5'
2024-10-02T11:47:17 (:8080) disconnected
2024-10-02T11:47:25 Connected server protocol
2024-10-02T11:47:25 received handshake 'Z5'
2024-10-03T03:45:00 (37) created PID file '/data/zeoserver/zeoserver.pid'
2024-10-03T03:45:00 (37) opening storage u'1' using FileStorage
2024-10-03T03:45:01 StorageServer created RW with storages: 1:RW:/data/filestorage/Data.fs
2024-10-03T03:45:03 listening on ('', 8080)
2024-10-03T03:45:09 Connected server protocol
2024-10-03T03:45:09 Connected server protocol
2024-10-03T03:45:09 received handshake 'Z5'
2024-10-03T03:45:09 received handshake 'Z5'
2024-10-03T03:48:21 (54) created PID file '/data/zeoserver/zeoserver.pid'
2024-10-03T03:48:21 (54) opening storage u'1' using FileStorage
2024-10-03T03:48:22 StorageServer created RW with storages: 1:RW:/data/filestorage/Data.fs
2024-10-03T03:48:24 listening on ('', 8080)
2024-10-03T03:48:30 Connected server protocol
2024-10-03T03:48:30 Connected server protocol
2024-10-03T03:48:30 received handshake 'Z5'
2024-10-03T03:48:30 received handshake 'Z5'
2024-10-03T04:06:07 (:8080) disconnected
2024-10-03T04:06:07 (:8080) disconnected
2024-10-04T06:20:54 (36) created PID file '/data/zeoserver/zeoserver.pid'
2024-10-04T06:20:54 (36) opening storage u'1' using FileStorage
2024-10-04T06:20:58 StorageServer created RW with storages: 1:RW:/data/filestorage/Data.fs
2024-10-04T06:21:01 listening on ('', 8080)
2024-10-04T06:21:11 Connected server protocol
2024-10-04T06:21:11 received handshake 'Z5'
2024-10-04T06:21:11 Connected server protocol
2024-10-04T06:21:11 received handshake 'Z5'
2024-10-04T06:22:28 (:8080) disconnected
2024-10-04T06:22:39 Connected server protocol
2024-10-04T06:22:39 received handshake 'Z5'
2024-10-04T06:24:41 Unexpected error while trying to resolve conflict on <type 'BTrees.OIBTree.OIBucket'>
Traceback (most recent call last):
  File "/home/senaite/senaitelims/eggs/cp27mu/ZODB-5.8.0-py2.7.egg/ZODB/ConflictResolution.py", line 286, in tryToResolveConflict
    newstate = unpickler.load()
UnpicklingError: NEWOBJ class argument isn't a type object
2024-10-04T06:24:41 Bad request, 'vote'
Traceback (most recent call last):
  File "/home/senaite/senaitelims/eggs/cp27mu/ZEO-5.3.0-py2.7.egg/ZEO/asyncio/server.py", line 103, in message_received
    result = getattr(self.zeo_storage, name)(*args)
  File "/home/senaite/senaitelims/eggs/cp27mu/ZEO-5.3.0-py2.7.egg/ZEO/StorageServer.py", line 374, in vote
    return self.lock_manager.lock(self, self._vote)
  File "/home/senaite/senaitelims/eggs/cp27mu/ZEO-5.3.0-py2.7.egg/ZEO/StorageServer.py", line 1168, in lock
    result = func()
  File "/home/senaite/senaitelims/eggs/cp27mu/ZEO-5.3.0-py2.7.egg/ZEO/StorageServer.py", line 395, in _vote
    getattr(self, op)(*args)
  File "/home/senaite/senaitelims/eggs/cp27mu/ZEO-5.3.0-py2.7.egg/ZEO/StorageServer.py", line 529, in _store
    self.storage.store(oid, serial, data, '', self.transaction)
  File "/home/senaite/senaitelims/eggs/cp27mu/ZODB-5.8.0-py2.7.egg/ZODB/FileStorage/FileStorage.py", line 616, in store
    oldserial, data)
  File "/home/senaite/senaitelims/eggs/cp27mu/ZODB-5.8.0-py2.7.egg/ZODB/ConflictResolution.py", line 311, in tryToResolveConflict
    data=newpickle)
ConflictError: database conflict error (oid 0x01306015, class BTrees.OIBTree.OIBucket, serial this txn started with 0x03fbc1c0ab4bd222 2024-10-04 06:24:40.147541, serial currently committed 0x03fbc1c0aeee9eaa 2024-10-04 06:24:40.999713)
2024-10-04T06:24:41 (:8080) no current transaction: tpc_abort()
2024-10-04T06:26:55 (:8080) disconnected
2024-10-04T06:27:08 Connected server protocol
2024-10-04T06:27:08 received handshake 'Z5'
2024-10-04T06:46:02 (:8080) disconnected
2024-10-04T06:46:16 Connected server protocol
2024-10-04T06:46:16 received handshake 'Z5'
2024-10-04T08:22:30 (37) created PID file '/data/zeoserver/zeoserver.pid'
2024-10-04T08:22:30 (37) opening storage u'1' using FileStorage
2024-10-04T08:22:31 StorageServer created RW with storages: 1:RW:/data/filestorage/Data.fs
2024-10-04T08:22:33 listening on ('', 8080)
2024-10-04T08:22:41 Connected server protocol
2024-10-04T08:22:41 received handshake 'Z5'
2024-10-04T08:22:41 Connected server protocol
2024-10-04T08:22:41 received handshake 'Z5'
2024-10-04T10:24:29 (:8080) disconnected
2024-10-04T10:25:10 Connected server protocol
2024-10-04T10:25:10 received handshake 'Z5'
2024-10-04T10:26:25 Unexpected error while trying to resolve conflict on <ZODB.ConflictResolution.BadClass object at 0x7f7d2e69e910>
Traceback (most recent call last):
  File "/home/senaite/senaitelims/eggs/cp27mu/ZODB-5.8.0-py2.7.egg/ZODB/ConflictResolution.py", line 274, in tryToResolveConflict
    inst = klass.__new__(klass, *newargs)
TypeError: object.__new__(X): X is not a type object (BadClass)
2024-10-04T10:26:25 Bad request, 'vote'
Traceback (most recent call last):
  File "/home/senaite/senaitelims/eggs/cp27mu/ZEO-5.3.0-py2.7.egg/ZEO/asyncio/server.py", line 103, in message_received
    result = getattr(self.zeo_storage, name)(*args)
  File "/home/senaite/senaitelims/eggs/cp27mu/ZEO-5.3.0-py2.7.egg/ZEO/StorageServer.py", line 374, in vote
    return self.lock_manager.lock(self, self._vote)
  File "/home/senaite/senaitelims/eggs/cp27mu/ZEO-5.3.0-py2.7.egg/ZEO/StorageServer.py", line 1168, in lock
    result = func()
  File "/home/senaite/senaitelims/eggs/cp27mu/ZEO-5.3.0-py2.7.egg/ZEO/StorageServer.py", line 395, in _vote
    getattr(self, op)(*args)
  File "/home/senaite/senaitelims/eggs/cp27mu/ZEO-5.3.0-py2.7.egg/ZEO/StorageServer.py", line 529, in _store
    self.storage.store(oid, serial, data, '', self.transaction)
  File "/home/senaite/senaitelims/eggs/cp27mu/ZODB-5.8.0-py2.7.egg/ZODB/FileStorage/FileStorage.py", line 616, in store
    oldserial, data)
  File "/home/senaite/senaitelims/eggs/cp27mu/ZODB-5.8.0-py2.7.egg/ZODB/ConflictResolution.py", line 311, in tryToResolveConflict
    data=newpickle)
ConflictError: database conflict error (oid 0x012cb57c, class bika.lims.content.analysis.Analysis, serial this txn started with 0x03fbc1c0e6b516cc 2024-10-04 06:24:54.072042, serial currently committed 0x03fbc2b269be0155 2024-10-04 10:26:24.783330)
2024-10-04T10:26:25 (:8080) no current transaction: tpc_abort()
2024-10-04T10:26:27 Unexpected error while trying to resolve conflict on <ZODB.ConflictResolution.BadClass object at 0x7f7d2e69e910>
Traceback (most recent call last):
  File "/home/senaite/senaitelims/eggs/cp27mu/ZODB-5.8.0-py2.7.egg/ZODB/ConflictResolution.py", line 274, in tryToResolveConflict
    inst = klass.__new__(klass, *newargs)
TypeError: object.__new__(X): X is not a type object (BadClass)
2024-10-04T10:26:27 Bad request, 'vote'
Traceback (most recent call last):
  File "/home/senaite/senaitelims/eggs/cp27mu/ZEO-5.3.0-py2.7.egg/ZEO/asyncio/server.py", line 103, in message_received
    result = getattr(self.zeo_storage, name)(*args)
  File "/home/senaite/senaitelims/eggs/cp27mu/ZEO-5.3.0-py2.7.egg/ZEO/StorageServer.py", line 374, in vote
    return self.lock_manager.lock(self, self._vote)
  File "/home/senaite/senaitelims/eggs/cp27mu/ZEO-5.3.0-py2.7.egg/ZEO/StorageServer.py", line 1168, in lock
    result = func()
  File "/home/senaite/senaitelims/eggs/cp27mu/ZEO-5.3.0-py2.7.egg/ZEO/StorageServer.py", line 395, in _vote
    getattr(self, op)(*args)
  File "/home/senaite/senaitelims/eggs/cp27mu/ZEO-5.3.0-py2.7.egg/ZEO/StorageServer.py", line 529, in _store
    self.storage.store(oid, serial, data, '', self.transaction)
  File "/home/senaite/senaitelims/eggs/cp27mu/ZODB-5.8.0-py2.7.egg/ZODB/FileStorage/FileStorage.py", line 616, in store
    oldserial, data)
  File "/home/senaite/senaitelims/eggs/cp27mu/ZODB-5.8.0-py2.7.egg/ZODB/ConflictResolution.py", line 311, in tryToResolveConflict
    data=newpickle)
ConflictError: database conflict error (oid 0x012cb57c, class bika.lims.content.analysis.Analysis, serial this txn started with 0x03fbc2b269be0155 2024-10-04 10:26:24.783330, serial currently committed 0x03fbc2b272e9e677 2024-10-04 10:26:26.932892)
2024-10-04T10:26:27 (:8080) no current transaction: tpc_abort()
2024-10-04T11:08:42 (:8080) disconnected
2024-10-04T11:09:07 Connected server protocol
2024-10-04T11:09:07 received handshake 'Z5'
2024-10-04T11:10:25 Unexpected error while trying to resolve conflict on <type 'BTrees.OIBTree.OIBucket'>
Traceback (most recent call last):
  File "/home/senaite/senaitelims/eggs/cp27mu/ZODB-5.8.0-py2.7.egg/ZODB/ConflictResolution.py", line 286, in tryToResolveConflict
    newstate = unpickler.load()
UnpicklingError: NEWOBJ class argument isn't a type object
2024-10-04T11:10:25 Bad request, 'vote'
Traceback (most recent call last):
  File "/home/senaite/senaitelims/eggs/cp27mu/ZEO-5.3.0-py2.7.egg/ZEO/asyncio/server.py", line 103, in message_received
    result = getattr(self.zeo_storage, name)(*args)
  File "/home/senaite/senaitelims/eggs/cp27mu/ZEO-5.3.0-py2.7.egg/ZEO/StorageServer.py", line 374, in vote
    return self.lock_manager.lock(self, self._vote)
  File "/home/senaite/senaitelims/eggs/cp27mu/ZEO-5.3.0-py2.7.egg/ZEO/StorageServer.py", line 1168, in lock
    result = func()
  File "/home/senaite/senaitelims/eggs/cp27mu/ZEO-5.3.0-py2.7.egg/ZEO/StorageServer.py", line 395, in _vote
    getattr(self, op)(*args)
  File "/home/senaite/senaitelims/eggs/cp27mu/ZEO-5.3.0-py2.7.egg/ZEO/StorageServer.py", line 529, in _store
    self.storage.store(oid, serial, data, '', self.transaction)
  File "/home/senaite/senaitelims/eggs/cp27mu/ZODB-5.8.0-py2.7.egg/ZODB/FileStorage/FileStorage.py", line 616, in store
    oldserial, data)
  File "/home/senaite/senaitelims/eggs/cp27mu/ZODB-5.8.0-py2.7.egg/ZODB/ConflictResolution.py", line 311, in tryToResolveConflict
    data=newpickle)
ConflictError: database conflict error (oid 0x01445d9a, class BTrees.OIBTree.OIBucket, serial this txn started with 0x03fbc2de5cbefc77 2024-10-04 11:10:21.737353, serial currently committed 0x03fbc2de66aa89ee 2024-10-04 11:10:24.062383)
2024-10-04T11:10:25 (:8080) no current transaction: tpc_abort()
